{"stream":"ethusd@depth","data":{"e":"depthUpdate","E":1785649433879,"s":"ETHUSD","U":3656115049,"u":3656115107,"b":[["1873.79000000","0.00000000"],["1873.77000000","0.00000000"],["1873.76000000","0.00000000"],["1873.75000000","0.00000000"],["1873.74000000","0.00000000"],["1873.72000000","1.15040000"],["1873.68000000","0.00000000"],["1873.67000000","0.00000000"],["1873.66000000","0.00000000"],["1873.64000000","0.92180000"],["1873.62000000","0.00000000"],["1873.50000000","0.13840000"],["1873.45000000","0.00000000"],["1872.88000000","0.00000000"],["1872.87000000","0.00000000"],["1872.86000000","0.00000000"],["1872.85000000","0.10000000"]],"a":[["1874.11000000","0.00000000"],["1874.17000000","0.13870000"],["1874.19000000","0.00000000"],["1874.21000000","0.00000000"],["1874.23000000","0.00000000"],["1874.24000000","0.00000000"],["1874.25000000","4.67890000"],["1874.28000000","0.00000000"],["1874.29000000","1.12170000"],["1874.31000000","0.00000000"],["1874.32000000","0.00000000"],["1874.33000000","0.00000000"],["1874.34000000","0.00000000"],["1874.37000000","0.00000000"]]}}
{"stream":"ethusd@depth","data":{"e":"depthUpdate","E":1785649434879,"s":"ETHUSD","U":3656115108,"u":3656115109,"b":[["1873.64000000","0.02970000"],["1873.59000000","0.99710000"]],"a":[]}}
{"stream":"ethusd@depth","data":{"e":"depthUpdate","E":1785649437880,"s":"ETHUSD","U":3656115110,"u":3656115117,"b":[["1873.78000000","0.00000000"],["1873.72000000","0.00000000"],["1873.69000000","1.12680000"]],"a":[["1874.26000000","1.14990000"],["1874.29000000","0.00000000"],["1874.35000000","0.00000000"]]}}
{"stream":"ethusd@depth","data":{"e":"depthUpdate","E":1785649438880,"s":"ETHUSD","U":3656115118,"u":3656115139,"b":[["1873.78000000","0.00000000"],["1873.72000000","1.16100000"],["1873.70000000","0.00000000"],["1873.69000000","0.00000000"],["1873.58000000","0.00000000"],["1873.21000000","1.47330000"],["1873.15000000","0.00000000"],["1871.16000000","11.20810000"],["1871.11000000","0.00000000"]],"a":[["1874.09000000","0.05870000"],["1874.15000000","0.00000000"],["1874.26000000","0.02970000"],["1874.27000000","0.00000000"],["1874.30000000","1.14070000"],["1874.35000000","0.00000000"],["1875.75000000","0.00000000"],["1875.95000000","8.94560000"],["1875.96000000","0.00000000"],["1876.03000000","0.00000000"]]}}
{"stream":"btcusd@depth","data":{"e":"depthUpdate","E":1785649439880,"s":"BTCUSD","U":4527242713,"u":4527242728,"b":[["63342.00000000","0.00000000"],["63280.20000000","0.00000000"],["63178.56000000","0.00000000"],["63078.22000000","0.00000000"],["60253.20000000","0.01659000"],["60194.16000000","0.16612000"],["60097.27000000","0.83198000"],["60001.64000000","0.83331000"]],"a":[["63368.77000000","0.00000000"],["63430.66000000","0.00000000"],["63532.70000000","0.00000000"],["63633.76000000","0.00000000"],["66617.66000000","0.01501000"],["66682.96000000","0.14996000"],["66790.43000000","0.74861000"],["66896.84000000","0.74741000"]]}}
{"stream":"ethusd@depth","data":{"e":"depthUpdate","E":1785649439880,"s":"ETHUSD","U":3656115140,"u":3656115148,"b":[["1873.72000000","1.13380000"],["1873.65000000","0.00000000"]],"a":[["1874.22000000","0.00000000"],["1874.29000000","1.11480000"],["1874.30000000","0.00000000"],["1875.93000000","8.94540000"],["1875.95000000","0.00000000"]]}}
{"stream":"btcusd@depth","data":{"e":"depthUpdate","E":1785649440880,"s":"BTCUSD","U":4527242729,"u":4527242729,"b":[],"a":[["63532.94000000","0.00000000"]]}}
{"stream":"ethusd@depth","data":{"e":"depthUpdate","E":1785649440880,"s":"ETHUSD","U":3656115149,"u":3656115151,"b":[["1873.65000000","1.06730000"],["1873.59000000","0.00000000"],["1873.50000000","0.00000000"],["1873.47000000","0.13850000"]],"a":[]}}
{"stream":"btcusd@depth","data":{"e":"depthUpdate","E":1785649441880,"s":"BTCUSD","U":4527242730,"u":4527242743,"b":[["63342.74000000","0.01578000"],["63280.75000000","0.15802000"],["63178.95000000","0.79140000"],["60253.20000000","0.00000000"],["60194.16000000","0.00000000"],["60097.27000000","0.00000000"],["60001.64000000","0.00000000"]],"a":[["63368.95000000","0.01578000"],["63431.03000000","0.15765000"],["63533.23000000","0.78698000"],["66617.66000000","0.00000000"],["66682.96000000","0.00000000"],["66790.43000000","0.00000000"],["66896.84000000","0.00000000"]]}}
{"stream":"ethusd@depth","data":{"e":"depthUpdate","E":1785649441880,"s":"ETHUSD","U":3656115152,"u":3656115155,"b":[["1873.80000000","1.13850000"],["1873.72000000","0.00000000"]],"a":[["1874.29000000","0.00000000"],["1874.37000000","1.12030000"]]}}
{"stream":"ethusd@depth","data":{"e":"depthUpdate","E":1785649442880,"s":"ETHUSD","U":3656115156,"u":3656115159,"b":[["1873.80000000","0.00000000"],["1873.72000000","1.15120000"]],"a":[["1874.30000000","1.12880000"],["1874.37000000","0.00000000"]]}}
{"stream":"btcusd@depth","data":{"e":"depthUpdate","E":1785649443880,"s":"BTCUSD","U":4527242744,"u":4527242744,"b":[["63345.06000000","0.03150000"],["63345.00000000","0.00000000"]],"a":[]}}
{"stream":"ethusd@depth","data":{"e":"depthUpdate","E":1785649443880,"s":"ETHUSD","U":3656115160,"u":3656115167,"b":[["1873.79000000","0.00000000"],["1873.72000000","1.12790000"]],"a":[["1874.29000000","1.13500000"],["1874.30000000","0.00000000"],["1874.37000000","0.00000000"]]}}
{"stream":"btcusd@depth","data":{"e":"depthUpdate","E":1785649444880,"s":"BTCUSD","U":4527242745,"u":4527242746,"b":[["63078.48000000","0.79266000"]],"a":[["63634.43000000","0.78573000"]]}}
{"stream":"ethusd@depth","data":{"e":"depthUpdate","E":1785649444880,"s":"ETHUSD","U":3656115168,"u":3656115176,"b":[["1873.79000000","0.00000000"],["1873.72000000","1.15820000"]],"a":[["1874.13000000","0.13870000"],["1874.17000000","0.00000000"],["1874.29000000","1.13090000"],["1874.36000000","0.00000000"]]}}
{"stream":"ethusd@depth","data":{"e":"depthUpdate","E":1785649445880,"s":"ETHUSD","U":3656115177,"u":3656115188,"b":[["1873.79000000","0.00000000"],["1873.72000000","0.00000000"],["1873.71000000","1.15180000"]],"a":[["1874.07000000","0.05550000"],["1874.09000000","0.00000000"],["1874.16000000","0.00000000"],["1874.28000000","1.14800000"],["1874.29000000","0.00000000"],["1874.36000000","0.00000000"]]}}
{"stream":"ethusd@depth","data":{"e":"depthUpdate","E":1785649446880,"s":"ETHUSD","U":3656115189,"u":3656115194,"b":[["1873.78000000","1.13800000"],["1873.71000000","0.00000000"]],"a":[["1874.07000000","0.00000000"],["1874.16000000","0.05660000"],["1874.28000000","0.00000000"],["1874.35000000","1.08890000"]]}}
{"stream":"btcusd@depth","data":{"e":"depthUpdate","E":1785649447880,"s":"BTCUSD","U":4527242747,"u":4527242748,"b":[],"a":[["63535.19000000","0.00000000"],["63545.35000000","0.00000000"]]}}
{"stream":"ethusd@depth","data":{"e":"depthUpdate","E":1785649447880,"s":"ETHUSD","U":3656115195,"u":3656115212,"b":[["1873.78000000","0.00000000"],["1873.70000000","1.17300000"],["1873.58000000","0.00000000"],["1873.52000000","0.13810000"],["1873.47000000","0.00000000"]],"a":[["1873.98000000","0.00000000"],["1874.11000000","0.05920000"],["1874.13000000","0.00000000"],["1874.15000000","0.00000000"],["1874.16000000","0.00000000"],["1874.19000000","0.13870000"],["1874.27000000","1.16010000"],["1874.35000000","0.00000000"],["1874.41000000","0.00000000"],["1874.49000000","1.47240000"],["1875.90000000","8.94520000"],["1875.93000000","0.00000000"],["1882.45000000","7.07540000"],["1883.00000000","0.00000000"]]}}
{"stream":"btcusd@depth","data":{"e":"depthUpdate","E":1785649448880,"s":"BTCUSD","U":4527242749,"u":4527242749,"b":[["63345.17000000","0.03150000"],["63345.06000000","0.00000000"]],"a":[]}}
{"stream":"btcusd@depth","data":{"e":"depthUpdate","E":1785649449880,"s":"BTCUSD","U":4527242750,"u":4527242750,"b":[],"a":[["63544.00000000","0.00000000"]]}}
{"stream":"ethusd@depth","data":{"e":"depthUpdate","E":1785649449881,"s":"ETHUSD","U":3656115213,"u":3656115220,"b":[["1873.76000000","1.11520000"],["1873.70000000","0.00000000"],["1873.52000000","0.00000000"],["1873.45000000","0.13860000"]],"a":[["1874.10000000","0.05900000"],["1874.11000000","0.00000000"],["1874.12000000","0.13870000"],["1874.19000000","0.00000000"],["1874.27000000","0.00000000"],["1874.33000000","1.08820000"]]}}
{"stream":"ethusd@depth","data":{"e":"depthUpdate","E":1785649450881,"s":"ETHUSD","U":3656115221,"u":3656115227,"b":[["1873.76000000","0.00000000"],["1873.68000000","1.16930000"],["1873.65000000","0.00000000"],["1873.60000000","1.06730000"],["1873.48000000","0.13850000"],["1873.45000000","0.00000000"]],"a":[["1874.25000000","5.85850000"],["1874.33000000","0.00000000"]]}}
{"stream":"btcusd@depth","data":{"e":"depthUpdate","E":1785649451881,"s":"BTCUSD","U":4527242751,"u":4527242751,"b":[["63345.18000000","0.03150000"],["63345.17000000","0.00000000"]],"a":[]}}
{"stream":"ethusd@depth","data":{"e":"depthUpdate","E":1785649451881,"s":"ETHUSD","U":3656115228,"u":3656115232,"b":[["1873.76000000","1.14370000"],["1873.68000000","0.00000000"]],"a":[["1874.25000000","4.67890000"],["1874.33000000","1.08710000"],["1874.42000000","1.47240000"],["1874.49000000","0.00000000"]]}}
{"stream":"btcusd@depth","data":{"e":"depthUpdate","E":1785649452881,"s":"BTCUSD","U":4527242752,"u":4527242752,"b":[],"a":[["63645.63000000","0.00000000"]]}}
{"stream":"ethusd@depth","data":{"e":"depthUpdate","E":1785649452881,"s":"ETHUSD","U":3656115233,"u":3656115244,"b":[["1873.76000000","0.00000000"],["1873.73000000","1.09700000"],["1873.58000000","0.00000000"]],"a":[["1873.99000000","0.00000000"],["1874.10000000","0.00000000"],["1874.14000000","1.61610000"],["1874.15000000","0.00000000"],["1874.30000000","1.11230000"],["1874.33000000","0.00000000"]]}}
{"stream":"btcusd@depth","data":{"e":"depthUpdate","E":1785649453881,"s":"BTCUSD","U":4527242753,"u":4527242753,"b":[],"a":[["63563.85000000","0.00000000"]]}}
{"stream":"ethusd@depth","data":{"e":"depthUpdate","E":1785649453881,"s":"ETHUSD","U":3656115245,"u":3656115264,"b":[["1873.82000000","0.00000000"],["1873.76000000","1.16310000"],["1873.73000000","0.00000000"],["1873.60000000","1.20600000"],["1873.48000000","0.00000000"],["1873.30000000","1.47330000"],["1873.21000000","0.00000000"],["1872.25000000","9.18670000"],["1872.05000000","0.00000000"],["1871.17000000","11.20800000"],["1871.16000000","0.00000000"]],"a":[["1874.10000000","0.05710000"],["1874.12000000","0.00000000"],["1874.14000000","1.56050000"],["1874.15000000","0.00000000"],["1874.19000000","0.00000000"],["1874.26000000","0.16840000"],["1874.30000000","0.00000000"],["1874.33000000","1.12070000"],["1874.39000000","0.00000000"],["1874.42000000","0.00000000"],["1874.56000000","1.47210000"]]}}
{"stream":"ethusd@depth","data":{"e":"depthUpdate","E":1785649455881,"s":"ETHUSD","U":3656115265,"u":3656115268,"b":[["1873.60000000","1.06730000"],["1873.49000000","0.13870000"],["1873.30000000","0.00000000"],["1873.19000000","1.47340000"]],"a":[["1874.16000000","0.13870000"],["1874.26000000","0.02970000"],["1874.46000000","1.47240000"],["1874.56000000","0.00000000"]]}}
{"stream":"btcusd@depth","data":{"e":"depthUpdate","E":1785649458881,"s":"BTCUSD","U":4527242754,"u":4527242754,"b":[],"a":[["63550.00000000","0.00000000"]]}}
{"stream":"ethusd@depth","data":{"e":"depthUpdate","E":1785649459881,"s":"ETHUSD","U":3656115269,"u":3656115275,"b":[["1873.76000000","0.00000000"],["1873.70000000","1.10090000"],["1873.65000000","1.06730000"],["1873.60000000","0.00000000"],["1873.49000000","0.00000000"],["1873.46000000","0.13870000"]],"a":[["1874.27000000","1.17000000"],["1874.33000000","0.00000000"]]}}
{"stream":"ethusd@depth","data":{"e":"depthUpdate","E":1785649460881,"s":"ETHUSD","U":3656115276,"u":3656115277,"b":[["1872.52000000","2.13460000"],["1872.14000000","0.00000000"]],"a":[]}}
{"stream":"btcusd@depth","data":{"e":"depthUpdate","E":1785649461881,"s":"BTCUSD","U":4527242755,"u":4527242755,"b":[],"a":[["63572.72000000","0.00000000"]]}}
{"stream":"ethusd@depth","data":{"e":"depthUpdate","E":1785649461881,"s":"ETHUSD","U":3656115278,"u":3656115313,"b":[["1873.70000000","0.00000000"],["1873.65000000","0.00000000"],["1873.60000000","0.00000000"],["1873.52000000","1.15380000"],["1873.46000000","0.00000000"],["1873.41000000","1.06740000"],["1873.28000000","0.13870000"],["1873.27000000","1.56050000"],["1873.19000000","0.00000000"],["1873.12000000","0.53380000"],["1872.98000000","1.47350000"],["1872.93000000","1.60110000"],["1872.85000000","0.00000000"],["1872.83000000","0.10000000"],["1872.52000000","0.00000000"],["1872.25000000","0.00000000"],["1872.12000000","2.13490000"],["1871.93000000","9.18830000"],["1871.18000000","11.20890000"],["1871.17000000","0.00000000"]],"a":[["1873.86000000","0.53360000"],["1873.95000000","0.13870000"],["1874.01000000","0.00000000"],["1874.09000000","1.09400000"],["1874.10000000","0.00000000"],["1874.16000000","0.00000000"],["1874.17000000","0.00000000"],["1874.25000000","6.15140000"],["1874.27000000","0.00000000"],["1874.46000000","0.00000000"],["1875.16000000","0.00000000"],["1875.30000000","9.17190000"],["1875.58000000","0.00000000"],["1875.83000000","8.94470000"],["1875.84000000","0.00000000"],["1875.85000000","0.00000000"],["1875.86000000","0.00000000"],["1875.87000000","0.00000000"],["1875.88000000","0.00000000"],["1875.90000000","0.00000000"]]}}
{"stream":"ethusd@depth","data":{"e":"depthUpdate","E":1785649462881,"s":"ETHUSD","U":3656115314,"u":3656115323,"b":[["1873.59000000","0.00000000"],["1873.53000000","1.11060000"],["1873.52000000","0.00000000"],["1872.83000000","0.00000000"],["1872.64000000","0.10000000"]],"a":[["1874.09000000","0.00000000"],["1874.10000000","1.12200000"],["1874.16000000","0.00000000"],["1875.82000000","8.94460000"],["1875.83000000","0.00000000"]]}}
{"stream":"ethusd@depth","data":{"e":"depthUpdate","E":1785649463881,"s":"ETHUSD","U":3656115324,"u":3656115324,"b":[],"a":[["1875.81000000","8.94460000"],["1875.82000000","0.00000000"]]}}
{"stream":"ethusd@depth","data":{"e":"depthUpdate","E":1785649464881,"s":"ETHUSD","U":3656115325,"u":3656115330,"b":[["1873.60000000","1.16920000"],["1873.53000000","0.00000000"],["1873.46000000","1.01770000"],["1873.41000000","0.00000000"]],"a":[["1874.10000000","0.00000000"],["1874.17000000","1.12810000"]]}}
{"stream":"ethusd@depth","data":{"e":"depthUpdate","E":1785649465882,"s":"ETHUSD","U":3656115331,"u":3656115336,"b":[["1873.60000000","0.00000000"],["1873.53000000","1.10410000"],["1871.18000000","0.00000000"],["1870.93000000","11.20950000"]],"a":[["1874.10000000","1.11990000"],["1874.17000000","0.00000000"],["1875.80000000","8.94450000"],["1875.81000000","0.00000000"]]}}
{"stream":"btcusd@depth","data":{"e":"depthUpdate","E":1785649466882,"s":"BTCUSD","U":4527242756,"u":4527242781,"b":[["63342.74000000","0.00000000"],["63342.08000000","0.01578000"],["63280.75000000","0.00000000"],["63178.95000000","0.00000000"],["63078.48000000","0.00000000"],["60253.02000000","0.00000000"],["60193.14000000","0.00000000"],["60095.53000000","0.00000000"],["59999.31000000","0.00000000"]],"a":[["63368.95000000","0.00000000"],["63369.07000000","0.01578000"],["63431.03000000","0.00000000"],["63533.23000000","0.00000000"],["63634.43000000","0.00000000"],["66618.27000000","0.00000000"],["66684.51000000","0.00000000"],["66792.78000000","0.00000000"],["66899.85000000","0.00000000"]]}}
{"stream":"ethusd@depth","data":{"e":"depthUpdate","E":1785649466882,"s":"ETHUSD","U":3656115337,"u":3656115343,"b":[["1873.60000000","1.15740000"],["1873.53000000","0.00000000"],["1870.96000000","11.20930000"],["1870.94000000","0.00000000"],["1870.93000000","0.00000000"]],"a":[["1873.95000000","0.00000000"],["1873.98000000","0.13840000"],["1874.10000000","0.00000000"],["1874.17000000","1.14840000"]]}}
{"stream":"btcusd@depth","data":{"e":"depthUpdate","E":1785649467882,"s":"BTCUSD","U":4527242782,"u":4527242784,"b":[["63351.72000000","0.00000000"],["63279.26000000","0.15802000"],["63204.76000000","0.00000000"],["63062.23000000","0.00000000"]],"a":[["63370.74000000","0.00000000"],["63431.99000000","0.15764000"],["63521.60000000","0.00000000"],["63664.20000000","0.00000000"]]}}
{"stream":"btcusd@depth","data":{"e":"depthUpdate","E":1785649468882,"s":"BTCUSD","U":4527242785,"u":4527242786,"b":[["63176.76000000","0.79143000"]],"a":[["63534.90000000","0.78696000"]]}}
{"stream":"ethusd@depth","data":{"e":"depthUpdate","E":1785649468882,"s":"ETHUSD","U":3656115344,"u":3656115344,"b":[["1870.97000000","11.20920000"],["1870.96000000","0.00000000"]],"a":[]}}
{"stream":"btcusd@depth","data":{"e":"depthUpdate","E":1785649470882,"s":"BTCUSD","U":4527242787,"u":4527242788,"b":[["63075.69000000","0.79269000"]],"a":[["63636.70000000","0.78571000"]]}}
{"stream":"ethusd@depth","data":{"e":"depthUpdate","E":1785649472882,"s":"ETHUSD","U":3656115345,"u":3656115345,"b":[["1873.33000000","0.13850000"],["1873.28000000","0.00000000"]],"a":[]}}
{"stream":"btcusd@depth","data":{"e":"depthUpdate","E":1785649473882,"s":"BTCUSD","U":4527242789,"u":4527242810,"b":[["63353.44000000","0.03466000"],["63350.13000000","0.00000000"],["63346.86000000","0.04734000"],["63342.08000000","0.00000000"],["63337.16000000","0.01578000"],["63204.57000000","0.11812000"],["63062.01000000","0.17868000"]],"a":[["63367.23000000","0.00300000"],["63367.24000000","0.01578000"],["63367.76000000","0.00000000"],["63369.07000000","0.00000000"],["63372.48000000","0.03516000"],["63521.39000000","0.11428000"],["63527.88000000","0.00028000"],["63530.74000000","0.00038000"],["63545.00000000","0.00675000"],["63547.45000000","0.00649000"],["63550.75000000","0.00100000"],["63551.00000000","0.00620000"],["63559.20000000","0.00157000"],["63570.72000000","0.00056000"],["63645.46000000","0.00000000"],["63663.99000000","0.17942000"]]}}
{"stream":"ethusd@depth","data":{"e":"depthUpdate","E":1785649473882,"s":"ETHUSD","U":3656115346,"u":3656115346,"b":[],"a":[["1874.00000000","0.05600000"]]}}
{"stream":"ethusd@depth","data":{"e":"depthUpdate","E":1785649474882,"s":"ETHUSD","U":3656115347,"u":3656115355,"b":[["1873.60000000","0.00000000"],["1873.53000000","1.09620000"],["1870.99000000","11.20910000"],["1870.97000000","0.00000000"]],"a":[["1873.95000000","0.05490000"],["1873.98000000","0.00000000"],["1874.00000000","0.00000000"],["1874.01000000","0.13870000"],["1874.10000000","1.16730000"],["1874.17000000","0.00000000"],["1874.25000000","4.67890000"],["1874.31000000","1.47200000"]]}}
{"stream":"btcusd@depth","data":{"e":"depthUpdate","E":1785649476882,"s":"BTCUSD","U":4527242811,"u":4527242819,"b":[],"a":[["63366.05000000","0.00000000"],["63366.06000000","0.00000000"],["63366.07000000","0.00000000"],["63367.23000000","0.00000000"],["63367.24000000","0.00000000"],["63367.75000000","0.00000000"],["63367.76000000","0.00300000"]]}}
{"stream":"ethusd@depth","data":{"e":"depthUpdate","E":1785649476882,"s":"ETHUSD","U":3656115356,"u":3656115359,"b":[["1871.00000000","11.20950000"],["1870.99000000","0.00000000"]],"a":[["1873.95000000","0.19360000"],["1874.01000000","0.00000000"],["1874.25000000","6.15120000"],["1874.31000000","0.00000000"],["1875.79000000","8.94440000"],["1875.80000000","0.00000000"]]}}
{"stream":"btcusd@depth","data":{"e":"depthUpdate","E":1785649477882,"s":"BTCUSD","U":4527242820,"u":4527242832,"b":[],"a":[["63366.05000000","0.01578000"],["63367.73000000","0.00000000"],["63367.74000000","0.00000000"],["63367.75000000","0.00000000"],["63367.76000000","0.00300000"]]}}
{"stream":"ethusd@depth","data":{"e":"depthUpdate","E":1785649477882,"s":"ETHUSD","U":3656115360,"u":3656115360,"b":[],"a":[["1873.95000000","0.05490000"],["1873.98000000","0.13860000"]]}}
{"stream":"btcusd@depth","data":{"e":"depthUpdate","E":1785649478882,"s":"BTCUSD","U":4527242833,"u":4527242833,"b":[],"a":[["63625.16000000","0.00014000"]]}}
{"stream":"ethusd@depth","data":{"e":"depthUpdate","E":1785649479882,"s":"ETHUSD","U":3656115361,"u":3656115362,"b":[["1873.33000000","0.00000000"],["1873.28000000","0.13870000"]],"a":[["1873.95000000","0.19360000"],["1873.98000000","0.00000000"]]}}
{"stream":"btcusd@depth","data":{"e":"depthUpdate","E":1785649480882,"s":"BTCUSD","U":4527242834,"u":4527242843,"b":[["63350.29000000","0.04734000"],["63346.86000000","0.00000000"],["63346.31000000","0.00408000"],["63345.29000000","0.03150000"],["63345.18000000","0.00000000"],["63344.78000000","0.00000000"],["63341.98000000","0.01578000"],["63337.16000000","0.00000000"]],"a":[["63366.05000000","0.00000000"],["63367.76000000","0.00000000"],["63367.77000000","0.00000000"],["63368.49000000","0.00300000"],["63368.50000000","0.00410000"],["63370.91000000","0.01578000"]]}}
{"stream":"ethusd@depth","data":{"e":"depthUpdate","E":1785649480883,"s":"ETHUSD","U":3656115363,"u":3656115386,"b":[["1873.73000000","0.00000000"],["1873.66000000","1.19460000"],["1873.64000000","0.02970000"],["1873.53000000","1.06730000"],["1873.46000000","0.00000000"],["1873.43000000","0.13870000"],["1873.29000000","0.53380000"],["1873.28000000","0.00000000"],["1873.13000000","1.47260000"],["1873.12000000","0.00000000"],["1872.98000000","0.00000000"],["1871.01000000","11.20900000"],["1871.00000000","0.00000000"]],"a":[["1873.86000000","0.00000000"],["1873.95000000","0.00000000"],["1874.01000000","0.53360000"],["1874.10000000","0.13870000"],["1874.21000000","0.00000000"],["1874.24000000","1.09810000"],["1874.25000000","4.67890000"],["1874.30000000","0.00000000"],["1874.40000000","1.47150000"]]}}
{"stream":"ethusd@depth","data":{"e":"depthUpdate","E":1785649481883,"s":"ETHUSD","U":3656115387,"u":3656115391,"b":[["1873.72000000","1.14360000"],["1873.66000000","0.00000000"],["1871.02000000","11.20890000"],["1871.01000000","0.00000000"]],"a":[["1874.24000000","0.00000000"],["1874.29000000","1.17030000"]]}}
{"stream":"btcusd@depth","data":{"e":"depthUpdate","E":1785649482883,"s":"BTCUSD","U":4527242844,"u":4527242877,"b":[["63361.64000000","0.00000000"],["63357.91000000","0.00000000"],["63354.68000000","0.03264000"],["63353.95000000","0.04734000"],["63353.44000000","0.00000000"],["63352.60000000","0.00000000"],["63350.78000000","0.00410000"],["63350.29000000","0.00000000"],["63346.97000000","0.01578000"],["63346.43000000","0.03150000"],["63346.31000000","0.00000000"],["63346.16000000","0.00000000"],["63346.09000000","0.00000000"],["63345.65000000","0.00000000"],["63345.29000000","0.00000000"],["63341.98000000","0.00000000"],["63340.64000000","0.04353000"],["63335.44000000","0.00000000"],["63291.87000000","0.33140000"],["63288.58000000","0.00000000"],["63287.51000000","0.00000000"]],"a":[["63368.49000000","0.00000000"],["63368.50000000","0.00000000"],["63370.88000000","0.04696000"],["63370.90000000","0.00300000"],["63372.48000000","0.00000000"],["63372.64000000","0.00000000"],["63372.97000000","0.00410000"],["63373.70000000","0.03341000"],["63376.95000000","0.00000000"],["63377.10000000","0.00000000"],["63379.04000000","0.00000000"],["63380.67000000","0.00000000"],["63383.11000000","0.04352000"],["63413.62000000","0.00000000"],["63418.59000000","0.27121000"],["63663.70000000","0.00000000"]]}}
{"stream":"ethusd@depth","data":{"e":"depthUpdate","E":1785649482883,"s":"ETHUSD","U":3656115392,"u":3656115402,"b":[["1873.70000000","0.97210000"],["1873.59000000","0.00000000"],["1873.53000000","0.00000000"],["1873.14000000","1.45820000"],["1872.93000000","0.00000000"],["1872.85000000","0.10000000"],["1872.83000000","0.00000000"],["1872.64000000","0.00000000"],["1871.05000000","11.20880000"],["1871.02000000","0.00000000"]],"a":[["1874.01000000","0.00000000"],["1874.16000000","0.53350000"]]}}
{"stream":"btcusd@depth","data":{"e":"depthUpdate","E":1785649483883,"s":"BTCUSD","U":4527242878,"u":4527242885,"b":[["63350.78000000","0.00000000"],["63348.01000000","0.00410000"],["63340.64000000","0.00000000"],["63337.87000000","0.04355000"]],"a":[["63370.19000000","0.00300000"],["63370.20000000","0.00410000"],["63370.90000000","0.00000000"],["63372.97000000","0.00000000"],["63380.34000000","0.04354000"],["63383.11000000","0.00000000"],["63580.19000000","0.00000000"],["63587.53000000","0.00000000"],["63652.50000000","0.00018000"]]}}
{"stream":"ethusd@depth","data":{"e":"depthUpdate","E":1785649483883,"s":"ETHUSD","U":3656115403,"u":3656115407,"b":[["1873.70000000","0.00000000"],["1873.64000000","0.02970000"],["1873.58000000","0.99920000"],["1871.06000000","11.20870000"],["1871.05000000","0.00000000"]],"a":[]}}
{"stream":"btcusd@depth","data":{"e":"depthUpdate","E":1785649484883,"s":"BTCUSD","U":4527242886,"u":4527242887,"b":[],"a":[["63540.85000000","0.00038000"],["63586.14000000","0.00043000"]]}}
{"stream":"ethusd@depth","data":{"e":"depthUpdate","E":1785649484883,"s":"ETHUSD","U":3656115408,"u":3656115408,"b":[["1871.08000000","11.20860000"],["1871.06000000","0.00000000"]],"a":[]}}
{"stream":"btcusd@depth","data":{"e":"depthUpdate","E":1785649485883,"s":"BTCUSD","U":4527242888,"u":4527242907,"b":[["63357.67000000","0.03156000"],["63357.66000000","0.03340000"],["63354.68000000","0.00000000"],["63353.50000000","0.00000000"],["63351.31000000","0.00000000"],["63349.04000000","0.00410000"],["63348.01000000","0.00000000"],["63346.47000000","0.03150000"],["63346.43000000","0.00000000"],["63341.18000000","0.00000000"],["63338.90000000","0.04354000"],["63337.87000000","0.00000000"]],"a":[["63370.19000000","0.00000000"],["63370.20000000","0.00000000"],["63370.87000000","0.00300000"],["63370.91000000","0.00000000"],["63371.23000000","0.00410000"],["63373.50000000","0.00000000"],["63373.70000000","0.00000000"],["63375.77000000","0.00000000"],["63376.68000000","0.03480000"],["63380.34000000","0.00000000"],["63381.37000000","0.04354000"],["63383.64000000","0.00000000"]]}}
{"stream":"ethusd@depth","data":{"e":"depthUpdate","E":1785649485883,"s":"ETHUSD","U":3656115409,"u":3656115418,"b":[["1873.72000000","1.09210000"],["1873.61000000","0.00000000"],["1871.09000000","11.20850000"],["1871.08000000","0.00000000"]],"a":[["1874.18000000","0.00000000"],["1874.29000000","1.16300000"],["1875.30000000","0.00000000"],["1875.48000000","9.17090000"]]}}
{"stream":"btcusd@depth","data":{"e":"depthUpdate","E":1785649486883,"s":"BTCUSD","U":4527242908,"u":4527242909,"b":[],"a":[["63370.99000000","0.00000000"]]}}
{"stream":"btcusd@depth","data":{"e":"depthUpdate","E":1785649487883,"s":"BTCUSD","U":4527242910,"u":4527242934,"b":[["63359.94000000","0.00000000"],["63359.61000000","0.00000000"],["63357.66000000","0.00000000"],["63357.33000000","0.00000000"],["63357.29000000","0.03262000"],["63351.81000000","0.00410000"],["63350.53000000","0.03150000"],["63349.04000000","0.00000000"],["63348.26000000","0.00000000"],["63346.47000000","0.00000000"],["63341.67000000","0.04353000"],["63338.90000000","0.00000000"]],"a":[["63370.64000000","0.00300000"],["63370.65000000","0.01578000"],["63370.87000000","0.00000000"],["63371.23000000","0.00000000"],["63373.00000000","0.00410000"],["63374.00000000","0.00000000"],["63376.31000000","0.03301000"],["63376.36000000","0.00000000"],["63376.68000000","0.00000000"],["63378.63000000","0.00000000"],["63378.96000000","0.00000000"],["63381.37000000","0.00000000"],["63384.14000000","0.04353000"]]}}
{"stream":"ethusd@depth","data":{"e":"depthUpdate","E":1785649487883,"s":"ETHUSD","U":3656115419,"u":3656115420,"b":[["1873.64000000","1.09700000"],["1873.58000000","0.00000000"]],"a":[]}}
{"stream":"btcusd@depth","data":{"e":"depthUpdate","E":1785649488883,"s":"BTCUSD","U":4527242935,"u":4527242935,"b":[],"a":[["63582.14000000","0.00057000"]]}}
{"stream":"ethusd@depth","data":{"e":"depthUpdate","E":1785649488883,"s":"ETHUSD","U":3656115421,"u":3656115430,"b":[["1873.72000000","0.00000000"],["1873.71000000","1.19460000"],["1873.64000000","0.02970000"],["1873.62000000","0.00000000"],["1873.56000000","0.85980000"]],"a":[["1874.19000000","0.00000000"],["1874.28000000","1.12200000"],["1874.29000000","0.00000000"]]}}
{"stream":"btcusd@depth","data":{"e":"depthUpdate","E":1785649489883,"s":"BTCUSD","U":4527242936,"u":4527242967,"b":[["63360.56000000","0.03155000"],["63360.55000000","0.03506000"],["63357.67000000","0.00000000"],["63357.55000000","0.04733000"],["63357.29000000","0.00000000"],["63353.95000000","0.00000000"],["63350.72000000","0.03150000"],["63350.58000000","0.00000000"],["63350.57000000","0.00000000"],["63350.53000000","0.00000000"]],"a":[["63370.61000000","0.00300000"],["63370.62000000","0.00000000"],["63370.63000000","0.00000000"],["63370.64000000","0.00000000"],["63370.65000000","0.00000000"],["63370.88000000","0.00000000"],["63372.61000000","0.00000000"],["63372.62000000","0.00000000"],["63373.00000000","0.00000000"],["63373.86000000","0.00410000"],["63375.40000000","0.01577000"],["63376.31000000","0.00000000"],["63379.57000000","0.03483000"],["63393.32000000","0.04696000"]]}}
{"stream":"ethusd@depth","data":{"e":"depthUpdate","E":1785649489883,"s":"ETHUSD","U":3656115431,"u":3656115442,"b":[["1873.79000000","1.17420000"],["1873.71000000","0.00000000"],["1873.62000000","0.92130000"],["1873.56000000","0.00000000"],["1873.51000000","0.13870000"],["1873.43000000","0.00000000"],["1873.21000000","1.47330000"],["1873.13000000","0.00000000"],["1872.16000000","9.18720000"],["1871.93000000","0.00000000"],["1871.14000000","11.20820000"],["1871.09000000","0.00000000"]],"a":[["1874.10000000","0.00000000"],["1874.18000000","0.13870000"],["1874.28000000","0.00000000"],["1874.36000000","1.10390000"],["1874.40000000","0.00000000"],["1874.48000000","1.47220000"]]}}
{"stream":"btcusd@depth","data":{"e":"depthUpdate","E":1785649490883,"s":"BTCUSD","U":4527242968,"u":4527242985,"b":[["63364.18000000","0.00000000"],["63360.55000000","0.00000000"],["63359.16000000","0.03449000"],["63354.31000000","0.00410000"],["63352.57000000","0.03150000"],["63351.81000000","0.00000000"],["63350.75000000","0.00000000"],["63350.74000000","0.00000000"],["63350.72000000","0.00000000"],["63344.17000000","0.04357000"],["63341.67000000","0.00000000"],["63308.69000000","0.27167000"],["63300.20000000","0.00000000"],["63292.05000000","0.33140000"],["63291.87000000","0.00000000"]],"a":[["63370.61000000","0.00000000"],["63372.62000000","0.00300000"],["63373.86000000","0.00000000"],["63376.50000000","0.00410000"],["63378.20000000","0.03383000"],["63379.57000000","0.00000000"],["63383.20000000","0.00000000"],["63384.14000000","0.00000000"],["63386.64000000","0.04352000"]]}}
{"stream":"ethusd@depth","data":{"e":"depthUpdate","E":1785649490883,"s":"ETHUSD","U":3656115443,"u":3656115452,"b":[["1873.79000000","0.00000000"],["1873.75000000","1.14920000"],["1873.61000000","0.00000000"],["1873.51000000","0.00000000"],["1873.47000000","0.13870000"]],"a":[["1874.13000000","0.13870000"],["1874.18000000","0.00000000"],["1874.32000000","1.11100000"],["1874.36000000","0.00000000"]]}}
{"stream":"btcusd@depth","data":{"e":"depthUpdate","E":1785649491883,"s":"BTCUSD","U":4527242986,"u":4527242990,"b":[["63354.31000000","0.00000000"],["63352.53000000","0.00410000"],["63344.17000000","0.00000000"],["63341.60000000","0.04357000"]],"a":[["63373.90000000","0.00410000"],["63374.72000000","0.00000000"],["63376.50000000","0.00000000"],["63384.06000000","0.04353000"],["63386.64000000","0.00000000"]]}}
{"stream":"btcusd@depth","data":{"e":"depthUpdate","E":1785649492883,"s":"BTCUSD","U":4527242991,"u":4527243013,"b":[["63361.54000000","0.00000000"],["63359.16000000","0.03340000"],["63355.44000000","0.00000000"],["63352.81000000","0.00000000"],["63352.57000000","0.00000000"],["63352.53000000","0.00000000"],["63351.62000000","0.00410000"],["63350.85000000","0.03150000"],["63350.77000000","0.00000000"],["63345.30000000","0.00000000"],["63341.60000000","0.00000000"],["63341.48000000","0.04357000"],["63296.92000000","0.33140000"],["63292.07000000","0.00000000"],["63292.05000000","0.00000000"]],"a":[["63373.80000000","0.00410000"],["63373.90000000","0.00000000"],["63375.75000000","0.00000000"],["63377.63000000","0.00000000"],["63378.20000000","0.03424000"],["63380.56000000","0.00000000"],["63383.94000000","0.04354000"],["63384.06000000","0.00000000"],["63385.89000000","0.00000000"]]}}
{"stream":"ethusd@depth","data":{"e":"depthUpdate","E":1785649492883,"s":"ETHUSD","U":3656115453,"u":3656115460,"b":[["1873.76000000","1.11520000"],["1873.75000000","0.00000000"],["1873.61000000","0.00000000"]],"a":[["1874.18000000","0.00000000"],["1874.32000000","0.00000000"],["1874.33000000","1.06880000"]]}}
{"stream":"btcusd@depth","data":{"e":"depthUpdate","E":1785649493883,"s":"BTCUSD","U":4527243014,"u":4527243017,"b":[["63351.20000000","0.03150000"],["63350.89000000","0.00000000"],["63350.85000000","0.00000000"],["63321.71000000","0.00000000"],["63321.66000000","0.00000000"]],"a":[]}}
{"stream":"btcusd@depth","data":{"e":"depthUpdate","E":1785649495883,"s":"BTCUSD","U":4527243018,"u":4527243033,"b":[["63361.48000000","0.00000000"],["63360.69000000","0.03302000"],["63359.16000000","0.00000000"],["63354.03000000","0.00000000"],["63354.02000000","0.00000000"],["63352.61000000","0.00410000"],["63351.62000000","0.00000000"],["63351.29000000","0.03150000"],["63351.20000000","0.00000000"]],"a":[["63373.80000000","0.00000000"],["63374.80000000","0.00410000"],["63375.24000000","0.00000000"],["63376.21000000","0.00000000"],["63378.20000000","0.00000000"],["63380.52000000","0.03262000"],["63383.94000000","0.00000000"],["63386.35000000","0.04352000"]]}}
{"stream":"ethusd@depth","data":{"e":"depthUpdate","E":1785649495884,"s":"ETHUSD","U":3656115461,"u":3656115478,"b":[["1873.82000000","0.00000000"],["1873.81000000","1.19320000"],["1873.76000000","0.00000000"],["1873.58000000","0.13870000"],["1873.47000000","0.00000000"],["1873.29000000","2.00660000"],["1873.21000000","0.00000000"],["1871.23000000","11.20770000"],["1871.21000000","0.00000000"],["1871.16000000","0.00000000"],["1871.14000000","0.00000000"]],"a":[["1874.13000000","0.00000000"],["1874.25000000","4.81720000"],["1874.33000000","0.00000000"],["1874.38000000","0.00000000"],["1874.44000000","0.00000000"],["1874.48000000","0.00000000"],["1874.55000000","1.47220000"],["1875.79000000","0.00000000"],["1876.02000000","14.27650000"],["1876.04000000","0.00000000"]]}}
{"stream":"ethusd@depth","data":{"e":"depthUpdate","E":1785649496884,"s":"ETHUSD","U":3656115479,"u":3656115490,"b":[["1873.81000000","0.00000000"],["1873.74000000","1.10180000"],["1873.67000000","1.06730000"],["1873.62000000","0.00000000"]],"a":[["1874.33000000","1.11520000"],["1874.39000000","0.00000000"],["1875.96000000","8.94560000"],["1875.97000000","0.00000000"],["1875.99000000","0.00000000"],["1876.00000000","0.00000000"],["1876.01000000","0.00000000"],["1876.02000000","5.33040000"]]}}
{"stream":"btcusd@depth","data":{"e":"depthUpdate","E":1785649497884,"s":"BTCUSD","U":4527243034,"u":4527243051,"b":[["63355.31000000","0.00000000"],["63354.15000000","0.00410000"],["63353.36000000","0.03150000"],["63353.11000000","0.00000000"],["63352.61000000","0.00000000"],["63351.29000000","0.00000000"],["63345.18000000","0.04357000"],["63341.48000000","0.00000000"],["63296.92000000","0.00000000"],["63289.47000000","0.33140000"],["63289.39000000","0.00000000"]],"a":[["63373.75000000","0.00000000"],["63374.80000000","0.00000000"],["63376.18000000","0.00000000"],["63376.34000000","0.00408000"],["63377.50000000","0.00000000"],["63378.48000000","0.00000000"],["63380.52000000","0.00000000"],["63380.66000000","0.03427000"],["63383.89000000","0.00000000"],["63386.32000000","0.04353000"],["63386.35000000","0.00000000"]]}}
{"stream":"ethusd@depth","data":{"e":"depthUpdate","E":1785649497884,"s":"ETHUSD","U":3656115491,"u":3656115494,"b":[["1873.58000000","0.00000000"],["1873.45000000","0.13870000"],["1873.29000000","0.53380000"],["1873.15000000","1.47340000"]],"a":[["1874.12000000","0.13870000"],["1874.25000000","4.67890000"],["1874.42000000","1.47240000"],["1874.55000000","0.00000000"]]}}
{"stream":"btcusd@depth","data":{"e":"depthUpdate","E":1785649498884,"s":"BTCUSD","U":4527243052,"u":4527243054,"b":[["63353.36000000","0.00000000"],["63352.31000000","0.03150000"],["63351.46000000","0.00000000"],["63293.90000000","0.33140000"],["63289.47000000","0.00000000"]],"a":[]}}
{"stream":"ethusd@depth","data":{"e":"depthUpdate","E":1785649498884,"s":"ETHUSD","U":3656115495,"u":3656115502,"b":[["1873.81000000","0.00000000"],["1873.75000000","1.18940000"],["1873.74000000","0.00000000"],["1873.49000000","0.13870000"],["1873.45000000","0.00000000"]],"a":[["1874.10000000","0.00000000"],["1874.14000000","1.61750000"]]}}
{"stream":"btcusd@depth","data":{"e":"depthUpdate","E":1785649499884,"s":"BTCUSD","U":4527243055,"u":4527243066,"b":[["63363.00000000","0.00000000"],["63360.69000000","0.00000000"],["63360.23000000","0.03487000"],["63354.60000000","0.00410000"],["63354.15000000","0.00000000"],["63352.54000000","0.03150000"],["63352.50000000","0.00000000"],["63352.31000000","0.00000000"],["63345.18000000","0.00000000"],["63342.36000000","0.04357000"],["63294.24000000","0.33140000"],["63293.90000000","0.00000000"]],"a":[["63374.69000000","0.00000000"],["63376.34000000","0.00000000"],["63376.79000000","0.00408000"],["63380.66000000","0.00000000"]]}}
{"stream":"ethusd@depth","data":{"e":"depthUpdate","E":1785649499884,"s":"ETHUSD","U":3656115503,"u":3656115507,"b":[],"a":[["1874.08000000","0.00000000"],["1874.12000000","0.00000000"],["1874.14000000","1.56050000"],["1874.15000000","0.05820000"],["1874.16000000","0.67210000"]]}}
{"stream":"btcusd@depth","data":{"e":"depthUpdate","E":1785649500884,"s":"BTCUSD","U":4527243067,"u":4527243072,"b":[["63354.60000000","0.00000000"],["63352.49000000","0.00410000"]],"a":[["63373.64000000","0.00410000"],["63374.67000000","0.00000000"],["63376.79000000","0.00000000"],["63379.27000000","0.03359000"],["63383.78000000","0.04354000"],["63386.32000000","0.00000000"],["63588.87000000","0.00050000"]]}}
{"stream":"ethusd@depth","data":{"e":"depthUpdate","E":1785649500884,"s":"ETHUSD","U":3656115508,"u":3656115531,"b":[["1873.75000000","0.00000000"],["1873.67000000","1.18790000"],["1873.61000000","0.00000000"],["1873.56000000","1.06730000"]],"a":[["1873.94000000","0.00000000"],["1874.03000000","0.53360000"],["1874.08000000","0.05510000"],["1874.09000000","0.00000000"],["1874.14000000","1.56050000"],["1874.15000000","0.00000000"],["1874.16000000","0.13860000"],["1874.24000000","1.14620000"],["1874.27000000","0.00000000"],["1874.33000000","0.00000000"],["1875.90000000","8.94520000"],["1875.95000000","0.00000000"],["1875.96000000","0.00000000"]]}}
{"stream":"btcusd@depth","data":{"e":"depthUpdate","E":1785649501884,"s":"BTCUSD","U":4527243073,"u":4527243074,"b":[["63357.55000000","0.00000000"],["63354.34000000","0.04734000"]],"a":[]}}
{"stream":"ethusd@depth","data":{"e":"depthUpdate","E":1785649502884,"s":"ETHUSD","U":3656115532,"u":3656115545,"b":[["1873.67000000","0.00000000"],["1873.63000000","1.09340000"],["1873.57000000","0.00000000"],["1873.49000000","0.00000000"],["1873.35000000","0.13870000"],["1873.15000000","0.00000000"],["1873.05000000","1.47350000"],["1872.16000000","0.00000000"],["1872.00000000","9.18800000"]],"a":[["1874.01000000","0.13870000"],["1874.08000000","0.00000000"],["1874.15000000","0.00000000"],["1874.16000000","0.00000000"],["1874.21000000","1.09540000"],["1874.24000000","0.00000000"],["1874.31000000","1.47250000"],["1874.42000000","0.00000000"]]}}
{"stream":"btcusd@depth","data":{"e":"depthUpdate","E":1785649503884,"s":"BTCUSD","U":4527243075,"u":4527243080,"b":[["63357.82000000","0.04733000"],["63354.34000000","0.00000000"],["63353.85000000","0.03150000"],["63352.54000000","0.00000000"],["63318.40000000","0.07889000"],["63307.11000000","0.00000000"],["63294.76000000","0.33140000"],["63294.24000000","0.00000000"]],"a":[]}}
{"stream":"ethusd@depth","data":{"e":"depthUpdate","E":1785649503884,"s":"ETHUSD","U":3656115546,"u":3656115553,"b":[["1873.65000000","1.18190000"],["1873.63000000","0.00000000"],["1873.56000000","1.06730000"]],"a":[["1874.14000000","1.56050000"],["1874.21000000","0.00000000"],["1874.22000000","1.08050000"]]}}
{"stream":"ethusd@depth","data":{"e":"depthUpdate","E":1785649504884,"s":"ETHUSD","U":3656115554,"u":3656115554,"b":[],"a":[["1874.06000000","0.05810000"]]}}
{"stream":"ethusd@depth","data":{"e":"depthUpdate","E":1785649505884,"s":"ETHUSD","U":3656115555,"u":3656115566,"b":[["1873.65000000","0.00000000"],["1873.63000000","1.13790000"],["1873.57000000","0.00000000"],["1871.83000000","0.00000000"],["1871.77000000","2.66840000"]],"a":[["1874.05000000","0.05750000"],["1874.06000000","0.00000000"],["1874.15000000","0.00000000"],["1874.21000000","1.12110000"],["1874.22000000","0.00000000"]]}}
{"stream":"ethusd@depth","data":{"e":"depthUpdate","E":1785649506884,"s":"ETHUSD","U":3656115567,"u":3656115579,"b":[["1873.64000000","1.20140000"],["1873.63000000","0.00000000"],["1873.57000000","0.00000000"]],"a":[["1873.98000000","0.00000000"],["1874.01000000","0.00000000"],["1874.04000000","0.13870000"],["1874.05000000","0.05850000"],["1874.14000000","1.56050000"],["1874.21000000","1.12680000"]]}}
{"stream":"ethusd@depth","data":{"e":"depthUpdate","E":1785649508884,"s":"ETHUSD","U":3656115580,"u":3656115611,"b":[["1873.64000000","1.20750000"],["1873.62000000","0.00000000"],["1873.57000000","0.00000000"]],"a":[["1873.98000000","0.00000000"],["1874.04000000","0.13870000"],["1874.05000000","0.00000000"],["1874.06000000","0.05870000"],["1874.14000000","1.56050000"],["1874.20000000","0.00000000"],["1874.21000000","1.10230000"],["1874.22000000","0.00000000"]]}}
{"stream":"ethusd@depth","data":{"e":"depthUpdate","E":1785649509884,"s":"ETHUSD","U":3656115612,"u":3656115613,"b":[["1871.67000000","0.00000000"],["1871.65000000","3.73580000"]],"a":[]}}
{"stream":"ethusd@depth","data":{"e":"depthUpdate","E":1785649510884,"s":"ETHUSD","U":3656115614,"u":3656115637,"b":[["1873.65000000","0.00000000"],["1873.64000000","1.18480000"],["1873.58000000","0.00000000"],["1873.57000000","0.00000000"]],"a":[["1873.98000000","0.00000000"],["1874.05000000","0.05540000"],["1874.06000000","0.00000000"],["1874.14000000","1.56050000"],["1874.15000000","0.00000000"],["1874.21000000","1.15930000"],["1874.22000000","0.00000000"]]}}
{"stream":"ethusd@depth","data":{"e":"depthUpdate","E":1785649511885,"s":"ETHUSD","U":3656115638,"u":3656115641,"b":[["1873.62000000","0.00000000"],["1873.57000000","1.06730000"],["1873.56000000","0.00000000"]],"a":[]}}
{"stream":"ethusd@depth","data":{"e":"depthUpdate","E":1785649516885,"s":"ETHUSD","U":3656115642,"u":3656115643,"b":[["1873.77000000","1.02100000"]],"a":[["1874.19000000","0.96540000"]]}}
{"stream":"ethusd@depth","data":{"e":"depthUpdate","E":1785649517885,"s":"ETHUSD","U":3656115644,"u":3656115652,"b":[["1873.65000000","1.19310000"],["1873.64000000","0.02970000"],["1873.57000000","1.06730000"]],"a":[["1874.05000000","0.00000000"],["1874.14000000","1.56050000"],["1874.21000000","0.00000000"],["1874.22000000","1.12180000"]]}}
{"stream":"btcusd@depth","data":{"e":"depthUpdate","E":1785649518885,"s":"BTCUSD","U":4527243081,"u":4527243082,"b":[["63352.49000000","0.00000000"],["63351.05000000","0.00410000"],["63332.38000000","0.02925000"]],"a":[]}}
{"stream":"btcusd@depth","data":{"e":"depthUpdate","E":1785649520885,"s":"BTCUSD","U":4527243083,"u":4527243084,"b":[["63357.82000000","0.21259000"],["63353.49000000","0.00000000"]],"a":[]}}
{"stream":"btcusd@depth","data":{"e":"depthUpdate","E":1785649522885,"s":"BTCUSD","U":4527243085,"u":4527243086,"b":[["63334.47000000","0.06311000"],["63324.22000000","0.00000000"]],"a":[]}}
{"stream":"ethusd@depth","data":{"e":"depthUpdate","E":1785649523885,"s":"ETHUSD","U":3656115653,"u":3656115655,"b":[["1873.41000000","0.13820000"],["1873.35000000","0.00000000"]],"a":[["1874.04000000","0.00000000"],["1874.07000000","0.13870000"],["1874.31000000","0.00000000"],["1874.37000000","1.47240000"]]}}
{"stream":"btcusd@depth","data":{"e":"depthUpdate","E":1785649524885,"s":"BTCUSD","U":4527243087,"u":4527243094,"b":[["63360.23000000","0.00000000"],["63357.82000000","0.16526000"],["63357.65000000","0.03337000"],["63353.99000000","0.04734000"]],"a":[["63372.29000000","0.00300000"],["63372.30000000","0.00410000"],["63372.62000000","0.00000000"],["63373.64000000","0.00000000"],["63376.67000000","0.03250000"],["63379.27000000","0.00000000"]]}}
{"stream":"btcusd@depth","data":{"e":"depthUpdate","E":1785649525885,"s":"BTCUSD","U":4527243095,"u":4527243096,"b":[["63308.48000000","0.11046000"],["63304.50000000","0.00000000"]],"a":[]}}
{"stream":"btcusd@depth","data":{"e":"depthUpdate","E":1785649527886,"s":"BTCUSD","U":4527243097,"u":4527243098,"b":[["63357.63000000","0.04733000"],["63353.99000000","0.00000000"]],"a":[]}}
{"stream":"ethusd@depth","data":{"e":"depthUpdate","E":1785649528886,"s":"ETHUSD","U":3656115656,"u":3656115657,"b":[["1872.50000000","2.13470000"],["1872.12000000","0.00000000"]],"a":[]}}
{"stream":"btcusd@depth","data":{"e":"depthUpdate","E":1785649533886,"s":"BTCUSD","U":4527243099,"u":4527243100,"b":[],"a":[["63589.28000000","0.00000000"],["63599.47000000","0.00000000"]]}}
{"stream":"ethusd@depth","data":{"e":"depthUpdate","E":1785649533886,"s":"ETHUSD","U":3656115658,"u":3656115658,"b":[],"a":[["1874.03000000","0.59260000"]]}}
{"stream":"ethusd@trade","data":{"e":"trade","E":1785649534887,"s":"ETHUSD","t":51376012,"p":"1873.77000000","q":"0.01330000","b":1909997059,"a":1909997070,"T":1785649534887,"m":true,"M":true}}
{"stream":"ethusd@depth","data":{"e":"depthUpdate","E":1785649535886,"s":"ETHUSD","U":3656115659,"u":3656115659,"b":[["1873.77000000","1.00770000"]],"a":[]}}
{"stream":"ethusd@depth","data":{"e":"depthUpdate","E":1785649538886,"s":"ETHUSD","U":3656115660,"u":3656115662,"b":[["1873.62000000","1.06730000"],["1873.57000000","0.00000000"],["1873.13000000","1.47340000"],["1873.05000000","0.00000000"]],"a":[]}}
{"stream":"ethusd@depth","data":{"e":"depthUpdate","E":1785649540886,"s":"ETHUSD","U":3656115663,"u":3656115666,"b":[["1873.72000000","1.12470000"],["1873.65000000","0.00000000"]],"a":[["1874.22000000","0.00000000"],["1874.29000000","1.10390000"]]}}
{"stream":"ethusd@depth","data":{"e":"depthUpdate","E":1785649541887,"s":"ETHUSD","U":3656115667,"u":3656115669,"b":[["1873.69000000","1.06730000"],["1873.62000000","0.00000000"]],"a":[["1874.03000000","0.53360000"]]}}
{"stream":"ethusd@depth","data":{"e":"depthUpdate","E":1785649542887,"s":"ETHUSD","U":3656115670,"u":3656115675,"b":[["1873.79000000","1.11860000"],["1873.72000000","0.00000000"],["1873.69000000","0.00000000"],["1873.64000000","1.09700000"]],"a":[["1874.29000000","0.00000000"],["1874.36000000","1.14120000"]]}}
{"stream":"ethusd@depth","data":{"e":"depthUpdate","E":1785649543887,"s":"ETHUSD","U":3656115676,"u":3656115686,"b":[["1873.79000000","0.00000000"],["1873.75000000","1.11410000"],["1873.64000000","1.09700000"],["1873.49000000","0.13790000"],["1873.41000000","0.00000000"]],"a":[["1874.07000000","0.00000000"],["1874.16000000","0.13870000"],["1874.22000000","0.00000000"],["1874.32000000","1.14880000"],["1874.36000000","0.00000000"],["1874.37000000","0.00000000"],["1874.46000000","1.47230000"]]}}
{"stream":"btcusd@depth","data":{"e":"depthUpdate","E":1785649544887,"s":"BTCUSD","U":4527243101,"u":4527243116,"b":[["63346.97000000","0.00000000"],["63279.26000000","0.00000000"],["63176.76000000","0.00000000"],["63075.69000000","0.00000000"],["60260.37000000","0.01659000"],["60201.31000000","0.16610000"],["60104.38000000","0.83188000"],["60008.73000000","0.83321000"]],"a":[["63375.40000000","0.00000000"],["63431.99000000","0.00000000"],["63534.90000000","0.00000000"],["63636.70000000","0.00000000"],["66623.87000000","0.01500000"],["66689.20000000","0.14994000"],["66796.70000000","0.74854000"],["66903.13000000","0.74734000"]]}}
{"stream":"btcusd@depth","data":{"e":"depthUpdate","E":1785649545887,"s":"BTCUSD","U":4527243117,"u":4527243128,"b":[["63350.43000000","0.01578000"],["63288.41000000","0.15800000"],["60260.37000000","0.00000000"],["60201.31000000","0.00000000"],["60104.38000000","0.00000000"],["60008.73000000","0.00000000"]],"a":[["63375.03000000","0.01577000"],["63437.14000000","0.15763000"],["66623.87000000","0.00000000"],["66689.20000000","0.00000000"],["66796.70000000","0.00000000"],["66903.13000000","0.00000000"]]}}
{"stream":"btcusd@depth","data":{"e":"depthUpdate","E":1785649546887,"s":"BTCUSD","U":4527243129,"u":4527243130,"b":[["63186.58000000","0.79130000"]],"a":[["63539.36000000","0.78691000"]]}}
{"stream":"ethusd@depth","data":{"e":"depthUpdate","E":1785649546887,"s":"ETHUSD","U":3656115687,"u":3656115688,"b":[["1873.49000000","0.00000000"],["1873.45000000","0.13810000"]],"a":[["1874.12000000","0.13870000"],["1874.16000000","0.00000000"]]}}
{"stream":"btcusd@depth","data":{"e":"depthUpdate","E":1785649547887,"s":"BTCUSD","U":4527243131,"u":4527243131,"b":[],"a":[["63372.30000000","0.00000000"],["63372.89000000","0.00410000"]]}}
{"stream":"btcusd@depth","data":{"e":"depthUpdate","E":1785649548887,"s":"BTCUSD","U":4527243132,"u":4527243151,"b":[["63086.08000000","0.79256000"]],"a":[["63372.28000000","0.00000000"],["63372.29000000","0.00000000"],["63372.59000000","0.00000000"],["63372.60000000","0.00000000"],["63372.61000000","0.00000000"],["63372.62000000","0.00300000"],["63580.19000000","0.00072000"],["63640.59000000","0.78566000"]]}}
{"stream":"btcusd@depth","data":{"e":"depthUpdate","E":1785649549887,"s":"BTCUSD","U":4527243152,"u":4527243155,"b":[],"a":[["63372.60000000","0.00000000"],["63372.61000000","0.00000000"],["63372.62000000","0.00300000"]]}}
{"stream":"ethusd@depth","data":{"e":"depthUpdate","E":1785649553887,"s":"ETHUSD","U":3656115689,"u":3656115703,"b":[["1873.81000000","0.00000000"],["1873.75000000","1.10410000"],["1873.70000000","1.06720000"],["1873.64000000","0.02970000"],["1873.45000000","0.13960000"],["1873.43000000","0.53370000"],["1873.29000000","0.00000000"]],"a":[["1874.03000000","0.00000000"],["1874.18000000","0.53350000"],["1874.32000000","1.12900000"],["1874.38000000","0.00000000"]]}}
{"stream":"ethusd@depth","data":{"e":"depthUpdate","E":1785649555888,"s":"ETHUSD","U":3656115704,"u":3656115705,"b":[],"a":[["1875.33000000","0.00000000"],["1875.40000000","2.66820000"]]}}
{"stream":"ethusd@depth","data":{"e":"depthUpdate","E":1785649556888,"s":"ETHUSD","U":3656115706,"u":3656115707,"b":[],"a":[["1873.82000000","1.06730000"],["1873.83000000","0.00000000"]]}}
{"stream":"btcusd@depth","data":{"e":"depthUpdate","E":1785649558888,"s":"BTCUSD","U":4527243156,"u":4527243156,"b":[["63352.45000000","0.00000000"]],"a":[]}}
{"stream":"ethusd@depth","data":{"e":"depthUpdate","E":1785649558888,"s":"ETHUSD","U":3656115708,"u":3656115710,"b":[],"a":[["1874.12000000","0.19480000"],["1881.03000000","0.00160000"],["1882.07000000","0.00000000"]]}}
{"stream":"btcusd@depth","data":{"e":"depthUpdate","E":1785649559888,"s":"BTCUSD","U":4527243157,"u":4527243157,"b":[["63353.73000000","0.00079000"]],"a":[]}}
{"stream":"ethusd@depth","data":{"e":"depthUpdate","E":1785649559888,"s":"ETHUSD","U":3656115711,"u":3656115716,"b":[["1873.70000000","0.00000000"],["1873.65000000","1.06730000"],["1873.50000000","0.13870000"],["1873.45000000","0.00150000"],["1873.20000000","1.47260000"],["1873.13000000","0.00000000"]],"a":[["1874.12000000","0.05610000"],["1874.16000000","0.13870000"],["1874.26000000","0.00000000"]]}}
{"stream":"btcusd@depth","data":{"e":"depthUpdate","E":1785649560888,"s":"BTCUSD","U":4527243158,"u":4527243191,"b":[["63362.05000000","0.04190000"],["63362.04000000","0.03534000"],["63360.08000000","0.00000000"],["63357.86000000","0.03150000"],["63357.81000000","0.00000000"],["63357.65000000","0.00000000"],["63357.63000000","0.00000000"],["63357.26000000","0.00000000"],["63356.36000000","0.01578000"],["63355.29000000","0.00000000"],["63354.89000000","0.00000000"],["63354.59000000","0.00000000"],["63354.53000000","0.00000000"],["63353.85000000","0.00000000"],["63350.43000000","0.00000000"],["63297.12000000","0.33140000"],["63297.07000000","0.00000000"],["63296.52000000","0.00000000"],["63294.76000000","0.00000000"],["63090.80000000","0.00347000"],["63082.34000000","0.00000000"]],"a":[["63372.62000000","0.00300000"],["63372.89000000","0.00000000"],["63373.55000000","0.00000000"],["63374.46000000","0.00408000"],["63375.03000000","0.00000000"],["63376.67000000","0.00000000"],["63377.15000000","0.00000000"],["63378.58000000","0.00000000"],["63379.11000000","0.00000000"],["63380.36000000","0.01577000"],["63381.07000000","0.03250000"],["63384.23000000","0.11800000"],["63385.62000000","0.00335000"]]}}
{"stream":"ethusd@depth","data":{"e":"depthUpdate","E":1785649560888,"s":"ETHUSD","U":3656115717,"u":3656115778,"b":[["1873.88000000","1.06710000"],["1873.87000000","1.11280000"],["1873.81000000","0.00000000"],["1873.75000000","0.00000000"],["1873.71000000","0.00000000"],["1873.66000000","1.56050000"],["1873.65000000","0.00000000"],["1873.64000000","0.16840000"],["1873.58000000","0.53370000"],["1873.56000000","0.00000000"],["1873.50000000","0.00000000"],["1873.43000000","0.00000000"],["1873.34000000","3.07370000"],["1873.27000000","1.66050000"],["1873.26000000","0.00000000"],["1873.21000000","0.00000000"],["1873.20000000","0.00000000"],["1873.14000000","0.00000000"],["1872.91000000","2.67000000"],["1872.85000000","0.00000000"],["1872.82000000","0.00000000"],["1872.63000000","0.00000000"],["1872.21000000","9.18680000"],["1872.00000000","0.00000000"],["1871.39000000","11.20670000"],["1871.38000000","0.00000000"],["1871.36000000","0.00000000"],["1871.31000000","0.00000000"],["1871.30000000","0.00000000"],["1871.29000000","5.34380000"],["1871.27000000","0.00000000"],["1871.23000000","0.00000000"],["1870.86000000","0.28820000"],["1870.56000000","0.00000000"],["1865.11000000","0.00000000"]],"a":[["1873.82000000","0.00000000"],["1873.88000000","0.00000000"],["1874.12000000","0.00000000"],["1874.14000000","0.00000000"],["1874.16000000","0.00000000"],["1874.18000000","0.00000000"],["1874.22000000","0.00000000"],["1874.25000000","0.02980000"],["1874.31000000","0.13870000"],["1874.32000000","0.00000000"],["1874.33000000","0.53350000"],["1874.39000000","0.00000000"],["1874.45000000","0.00000000"],["1874.46000000","0.00000000"],["1874.47000000","1.15310000"],["1874.52000000","0.00000000"],["1874.56000000","4.16360000"],["1874.61000000","1.47230000"],["1874.80000000","1.56050000"],["1874.81000000","2.66700000"],["1875.00000000","0.00000000"],["1875.21000000","0.00000000"],["1875.48000000","0.00000000"],["1875.51000000","0.23180000"],["1875.66000000","9.17000000"],["1875.90000000","0.00000000"],["1876.17000000","8.94710000"],["1881.43000000","0.00000000"],["1882.26000000","8.57730000"]]}}
{"stream":"btcusd@depth","data":{"e":"depthUpdate","E":1785649561888,"s":"BTCUSD","U":4527243192,"u":4527243225,"b":[["63360.56000000","0.03232000"],["63357.90000000","0.03150000"],["63357.86000000","0.00000000"],["63354.52000000","0.00410000"],["63353.73000000","0.00000000"],["63351.05000000","0.00000000"],["63318.29000000","0.20337000"],["63297.16000000","0.33140000"],["63297.12000000","0.00000000"],["63108.11000000","0.00000000"]],"a":[["63372.59000000","0.00000000"],["63372.60000000","0.00000000"],["63372.61000000","0.00000000"],["63372.62000000","0.00300000"],["63374.46000000","0.00000000"],["63376.53000000","0.00000000"],["63376.71000000","0.00410000"],["63382.10000000","0.00079000"],["63383.78000000","0.00000000"],["63386.85000000","0.04352000"],["63425.50000000","0.00000000"],["63428.40000000","0.00000000"],["63533.52000000","0.26094000"],["63542.85000000","0.25973000"],["63590.30000000","0.00055000"]]}}
{"stream":"ethusd@depth","data":{"e":"depthUpdate","E":1785649561888,"s":"ETHUSD","U":3656115779,"u":3656115794,"b":[["1873.89000000","0.00000000"],["1873.64000000","0.13870000"],["1873.27000000","1.56050000"],["1872.92000000","0.10000000"],["1871.40000000","11.20670000"],["1871.39000000","0.00000000"],["1866.74000000","7.09050000"],["1866.49000000","7.05260000"],["1865.16000000","0.00000000"]],"a":[["1874.25000000","0.00000000"],["1874.44000000","0.02940000"],["1881.51000000","0.00000000"],["1881.58000000","0.00000000"],["1881.65000000","0.00000000"],["1882.19000000","8.42230000"],["1882.34000000","8.53110000"],["1883.41000000","0.00000000"]]}}
{"stream":"btcusd@depth","data":{"e":"depthUpdate","E":1785649562888,"s":"BTCUSD","U":4527243226,"u":4527243240,"b":[["63364.02000000","0.01985000"],["63364.01000000","0.03496000"],["63362.04000000","0.00000000"],["63360.56000000","0.00077000"],["63357.09000000","0.00408000"],["63354.52000000","0.00000000"],["63345.01000000","0.04357000"],["63342.36000000","0.00000000"],["63332.38000000","0.00000000"],["63330.20000000","0.07900000"],["63325.03000000","0.00000000"]],"a":[["63376.37000000","0.02907000"],["63376.71000000","0.00000000"],["63379.28000000","0.00410000"],["63381.07000000","0.00000000"],["63383.03000000","0.03224000"],["63386.85000000","0.00000000"],["63389.41000000","0.04354000"],["63418.59000000","0.00000000"],["63424.90000000","0.27117000"]]}}
{"stream":"ethusd@depth","data":{"e":"depthUpdate","E":1785649562888,"s":"ETHUSD","U":3656115795,"u":3656115806,"b":[["1873.99000000","1.10930000"],["1873.95000000","0.88750000"],["1873.94000000","0.02970000"],["1873.88000000","0.00000000"],["1873.87000000","0.00000000"]],"a":[["1874.19000000","0.00000000"],["1874.31000000","0.00000000"],["1874.33000000","0.53350000"],["1874.35000000","0.13840000"],["1874.47000000","0.00000000"],["1874.56000000","5.30960000"],["1882.55000000","8.59940000"],["1882.65000000","8.64940000"]]}}
{"stream":"ethusd@depth","data":{"e":"depthUpdate","E":1785649563888,"s":"ETHUSD","U":3656115807,"u":3656115809,"b":[["1873.70000000","0.13830000"],["1873.64000000","0.00000000"]],"a":[["1874.35000000","0.00000000"],["1874.37000000","0.13870000"],["1874.61000000","0.00000000"],["1874.67000000","1.47190000"]]}}
{"stream":"btcusd@depth","data":{"e":"depthUpdate","E":1785649564888,"s":"BTCUSD","U":4527243241,"u":4527243243,"b":[],"a":[["63372.62000000","0.00000000"],["63372.63000000","0.00000000"],["63376.35000000","0.00300000"],["63376.36000000","0.36224000"]]}}
{"stream":"ethusd@depth","data":{"e":"depthUpdate","E":1785649564888,"s":"ETHUSD","U":3656115810,"u":3656115810,"b":[["1871.43000000","11.20650000"],["1871.40000000","0.00000000"]],"a":[]}}
{"stream":"btcusd@depth","data":{"e":"depthUpdate","E":1785649565888,"s":"BTCUSD","U":4527243244,"u":4527243257,"b":[["63365.98000000","0.02484000"],["63365.97000000","0.03328000"],["63364.02000000","0.00000000"],["63364.01000000","0.00000000"],["63358.10000000","0.03150000"],["63357.90000000","0.00000000"],["63320.10000000","0.20641000"],["63297.36000000","0.33140000"],["63297.16000000","0.00000000"],["63115.29000000","0.00000000"]],"a":[["63376.35000000","0.00000000"],["63376.36000000","0.00000000"],["63382.09000000","0.36224000"],["63383.03000000","0.00000000"],["63384.99000000","0.03465000"],["63433.50000000","0.00000000"]]}}
{"stream":"ethusd@depth","data":{"e":"depthUpdate","E":1785649565888,"s":"ETHUSD","U":3656115811,"u":3656115812,"b":[["1874.00000000","1.06710000"],["1873.95000000","0.00000000"]],"a":[]}}
{"stream":"btcusd@depth","data":{"e":"depthUpdate","E":1785649566888,"s":"BTCUSD","U":4527243258,"u":4527243273,"b":[["63363.17000000","0.00077000"],["63360.56000000","0.00000000"],["63358.81000000","0.00410000"],["63358.15000000","0.03150000"],["63358.14000000","0.00000000"],["63358.13000000","0.00000000"],["63358.11000000","0.00000000"],["63358.10000000","0.00000000"],["63357.09000000","0.00000000"],["63348.67000000","0.04354000"],["63345.01000000","0.00000000"],["63297.41000000","0.33140000"],["63297.40000000","0.00000000"],["63297.39000000","0.00000000"],["63297.37000000","0.00000000"],["63297.36000000","0.00000000"]],"a":[["63379.28000000","0.00000000"],["63381.01000000","0.00408000"],["63382.10000000","0.00000000"],["63384.71000000","0.00077000"],["63434.95000000","0.20476000"]]}}
{"stream":"ethusd@depth","data":{"e":"depthUpdate","E":1785649566888,"s":"ETHUSD","U":3656115813,"u":3656115815,"b":[["1873.75000000","0.13870000"],["1873.70000000","0.00000000"],["1873.45000000","1.47390000"],["1873.34000000","1.60080000"]],"a":[["1874.37000000","0.00000000"],["1874.42000000","0.13860000"]]}}
{"stream":"btcusd@depth","data":{"e":"depthUpdate","E":1785649567888,"s":"BTCUSD","U":4527243274,"u":4527243283,"b":[["63358.27000000","0.03150000"],["63358.25000000","0.00000000"],["63358.23000000","0.00000000"],["63358.20000000","0.00000000"],["63358.19000000","0.00000000"],["63358.15000000","0.00000000"],["63297.53000000","0.33140000"],["63297.51000000","0.00000000"],["63297.49000000","0.00000000"],["63297.46000000","0.00000000"],["63297.45000000","0.00000000"],["63297.41000000","0.00000000"]],"a":[]}}
{"stream":"ethusd@depth","data":{"e":"depthUpdate","E":1785649567888,"s":"ETHUSD","U":3656115816,"u":3656115830,"b":[["1874.06000000","1.06700000"],["1874.05000000","1.13770000"],["1874.00000000","0.00000000"],["1873.99000000","0.00000000"],["1873.72000000","0.53360000"],["1873.58000000","0.00000000"],["1873.54000000","1.60060000"],["1873.34000000","0.00000000"],["1871.45000000","16.40810000"],["1871.44000000","0.00000000"],["1871.43000000","0.00000000"]],"a":[["1874.33000000","0.00000000"],["1874.50000000","0.53340000"],["1874.56000000","4.16360000"],["1874.62000000","1.12580000"],["1874.67000000","0.00000000"],["1874.72000000","1.47180000"]]}}
{"stream":"btcusd@depth","data":{"e":"depthUpdate","E":1785649568888,"s":"BTCUSD","U":4527243284,"u":4527243286,"b":[["63358.35000000","0.03150000"],["63358.27000000","0.00000000"],["63297.61000000","0.33140000"],["63297.53000000","0.00000000"]],"a":[["63389.41000000","0.00000000"],["63391.37000000","0.04353000"]]}}
{"stream":"ethusd@depth","data":{"e":"depthUpdate","E":1785649568888,"s":"ETHUSD","U":3656115831,"u":3656115837,"b":[["1874.06000000","0.00000000"],["1874.00000000","1.06710000"],["1873.45000000","1.47240000"],["1872.42000000","9.18590000"],["1872.21000000","0.00000000"]],"a":[["1874.42000000","0.00000000"],["1874.43000000","0.53340000"],["1874.44000000","0.16800000"],["1874.50000000","0.00000000"]]}}
{"stream":"ethusd@depth","data":{"e":"depthUpdate","E":1785649569888,"s":"ETHUSD","U":3656115838,"u":3656115839,"b":[["1874.00000000","0.00000000"],["1873.94000000","1.09680000"]],"a":[]}}
{"stream":"btcusd@depth","data":{"e":"depthUpdate","E":1785649570888,"s":"BTCUSD","U":4527243287,"u":4527243291,"b":[["63358.72000000","0.03150000"],["63358.35000000","0.00000000"],["63297.98000000","0.33130000"],["63297.61000000","0.00000000"]],"a":[["63376.36000000","0.00300000"],["63382.47000000","0.00000000"],["63389.57000000","0.00626000"]]}}
{"stream":"btcusd@depth","data":{"e":"depthUpdate","E":1785649571889,"s":"BTCUSD","U":4527243292,"u":4527243293,"b":[["63358.98000000","0.03150000"],["63358.72000000","0.00000000"],["63298.24000000","0.33130000"],["63297.98000000","0.00000000"]],"a":[]}}
{"stream":"btcusd@depth","data":{"e":"depthUpdate","E":1785649572889,"s":"BTCUSD","U":4527243294,"u":4527243295,"b":[["63359.09000000","0.03150000"],["63358.98000000","0.00000000"],["63298.35000000","0.33130000"],["63298.24000000","0.00000000"]],"a":[]}}
{"stream":"btcusd@depth","data":{"e":"depthUpdate","E":1785649574889,"s":"BTCUSD","U":4527243296,"u":4527243301,"b":[["63321.90000000","0.20445000"],["63122.61000000","0.00000000"]],"a":[["63434.95000000","0.00000000"],["63435.95000000","0.20518000"],["63540.72000000","0.26146000"],["63542.85000000","0.00000000"]]}}
{"stream":"btcusd@depth","data":{"e":"depthUpdate","E":1785649577889,"s":"BTCUSD","U":4527243302,"u":4527243303,"b":[],"a":[["63376.34000000","0.00300000"],["63376.35000000","0.03155000"],["63376.36000000","0.00000000"]]}}
{"stream":"btcusd@depth","data":{"e":"depthUpdate","E":1785649578889,"s":"BTCUSD","U":4527243304,"u":4527243305,"b":[["63365.98000000","0.07217000"],["63362.05000000","0.00000000"]],"a":[]}}
{"stream":"ethusd@depth","data":{"e":"depthUpdate","E":1785649578889,"s":"ETHUSD","U":3656115840,"u":3656115840,"b":[["1873.77000000","0.00000000"]],"a":[]}}
{"stream":"ethusd@depth","data":{"e":"depthUpdate","E":1785649584889,"s":"ETHUSD","U":3656115841,"u":3656115841,"b":[["1873.28000000","0.10000000"],["1872.92000000","0.00000000"]],"a":[]}}
{"stream":"btcusd@depth","data":{"e":"depthUpdate","E":1785649585890,"s":"BTCUSD","U":4527243306,"u":4527243310,"b":[["63365.98000000","0.02484000"],["63362.78000000","0.00000000"],["63359.58000000","0.00300000"],["63359.57000000","0.04733000"]],"a":[]}}
{"stream":"ethusd@depth","data":{"e":"depthUpdate","E":1785649585890,"s":"ETHUSD","U":3656115842,"u":3656115876,"b":[["1874.05000000","0.00000000"],["1873.94000000","0.02970000"],["1873.86000000","0.00000000"],["1873.85000000","1.17340000"],["1873.77000000","0.00000000"],["1873.75000000","0.00000000"],["1873.72000000","0.00000000"],["1873.67000000","0.71240000"],["1873.63000000","0.13870000"],["1873.56000000","0.00000000"],["1873.54000000","0.00000000"],["1873.45000000","0.00000000"],["1873.33000000","1.47330000"],["1873.28000000","0.00000000"],["1873.11000000","1.34760000"],["1872.92000000","0.10000000"],["1872.91000000","8.11270000"],["1872.84000000","0.00000000"],["1870.86000000","0.00000000"],["1870.67000000","0.22420000"]],"a":[["1874.28000000","0.00000000"],["1874.30000000","0.13870000"],["1874.40000000","0.00000000"],["1874.42000000","1.11060000"],["1874.43000000","0.00000000"],["1874.44000000","0.02940000"],["1874.60000000","1.47230000"],["1874.62000000","0.00000000"],["1874.72000000","0.00000000"],["1876.15000000","8.94700000"],["1876.16000000","0.00000000"],["1876.17000000","0.00000000"]]}}
{"stream":"btcusd@depth","data":{"e":"depthUpdate","E":1785649586890,"s":"BTCUSD","U":4527243311,"u":4527243313,"b":[["63362.86000000","0.04733000"],["63359.58000000","0.00000000"],["63359.57000000","0.00000000"]],"a":[]}}
{"stream":"ethusd@depth","data":{"e":"depthUpdate","E":1785649586890,"s":"ETHUSD","U":3656115877,"u":3656115889,"b":[["1873.68000000","0.67750000"],["1873.67000000","0.00000000"],["1873.62000000","0.00000000"],["1873.41000000","0.53370000"],["1873.12000000","0.10000000"],["1872.92000000","0.00000000"]],"a":[["1874.19000000","0.67750000"],["1874.20000000","0.53350000"],["1874.29000000","0.00000000"],["1875.51000000","0.00000000"],["1876.12000000","8.94680000"],["1876.13000000","0.00000000"],["1876.15000000","0.00000000"]]}}
{"stream":"ethusd@depth","data":{"e":"depthUpdate","E":1785649589890,"s":"ETHUSD","U":3656115890,"u":3656115902,"b":[["1874.00000000","0.00000000"],["1873.94000000","1.20760000"],["1873.85000000","0.00000000"],["1873.80000000","0.73580000"],["1873.74000000","0.00000000"],["1873.68000000","0.00000000"]],"a":[["1874.42000000","0.00000000"],["1874.51000000","1.12120000"],["1874.57000000","1.56050000"],["1875.29000000","0.21610000"]]}}
{"stream":"ethusd@depth","data":{"e":"depthUpdate","E":1785649590890,"s":"ETHUSD","U":3656115903,"u":3656115927,"b":[["1874.05000000","0.00000000"],["1873.97000000","0.75850000"],["1873.94000000","0.02970000"],["1873.85000000","0.00000000"],["1873.80000000","0.00000000"],["1873.56000000","0.53370000"],["1873.41000000","0.00000000"],["1873.30000000","1.13650000"],["1873.13000000","0.00000000"],["1873.12000000","0.00000000"],["1873.11000000","0.00000000"],["1872.93000000","0.10000000"],["1872.92000000","0.00000000"],["1870.86000000","0.23330000"],["1870.67000000","0.00000000"],["1869.27000000","0.00000000"],["1865.05000000","0.00000000"]],"a":[["1874.20000000","0.00000000"],["1874.37000000","0.53350000"],["1874.51000000","0.00000000"],["1874.56000000","0.00000000"],["1874.62000000","0.00000000"],["1874.76000000","4.16360000"],["1875.29000000","0.00000000"],["1875.50000000","0.28670000"],["1878.64000000","0.00000000"],["1882.86000000","0.00000000"]]}}
{"stream":"ethusd@depth","data":{"e":"depthUpdate","E":1785649591890,"s":"ETHUSD","U":3656115928,"u":3656115942,"b":[["1873.97000000","0.00000000"],["1873.91000000","0.60230000"],["1872.95000000","0.00000000"],["1872.94000000","0.00000000"],["1872.93000000","0.00000000"],["1872.92000000","0.10000000"]],"a":[]}}
{"stream":"ethusd@depth","data":{"e":"depthUpdate","E":1785649592890,"s":"ETHUSD","U":3656115943,"u":3656115944,"b":[["1873.68000000","0.13870000"],["1873.63000000","0.00000000"]],"a":[["1874.30000000","0.00000000"],["1874.35000000","0.13840000"]]}}
{"stream":"btcusd@depth","data":{"e":"depthUpdate","E":1785649593890,"s":"BTCUSD","U":4527243314,"u":4527243314,"b":[],"a":[["63376.37000000","0.00000000"]]}}
{"stream":"btcusd@depth","data":{"e":"depthUpdate","E":1785649595890,"s":"BTCUSD","U":4527243315,"u":4527243316,"b":[],"a":[["63380.36000000","0.00000000"],["63385.35000000","0.01577000"]]}}
{"stream":"ethusd@depth","data":{"e":"depthUpdate","E":1785649595890,"s":"ETHUSD","U":3656115945,"u":3656115952,"b":[["1874.00000000","1.10300000"],["1873.91000000","0.00000000"],["1873.84000000","0.77440000"],["1869.60000000","3.81720000"],["1865.38000000","15.00030000"]],"a":[["1874.57000000","2.75380000"],["1878.98000000","4.17000000"],["1883.20000000","6.51010000"]]}}
{"stream":"btcusd@depth","data":{"e":"depthUpdate","E":1785649600890,"s":"BTCUSD","U":4527243317,"u":4527243320,"b":[["63360.80000000","0.03150000"],["63359.63000000","0.00000000"],["63359.09000000","0.00000000"],["63300.05000000","0.33130000"],["63298.89000000","0.00000000"],["63298.35000000","0.00000000"]],"a":[]}}
{"stream":"ethusd@depth","data":{"e":"depthUpdate","E":1785649605891,"s":"ETHUSD","U":3656115953,"u":3656115954,"b":[["1873.90000000","1.06710000"],["1873.84000000","0.00000000"]],"a":[]}}
{"stream":"ethusd@depth","data":{"e":"depthUpdate","E":1785649607891,"s":"ETHUSD","U":3656115955,"u":3656116003,"b":[["1874.00000000","0.00000000"],["1873.96000000","1.13790000"],["1873.90000000","0.00000000"],["1873.88000000","1.06710000"],["1873.85000000","0.00000000"],["1873.81000000","0.00000000"],["1873.74000000","0.00000000"],["1873.68000000","0.00000000"],["1873.67000000","0.00000000"],["1873.60000000","0.13870000"],["1873.59000000","0.53370000"],["1873.56000000","0.00000000"],["1873.40000000","1.11080000"],["1873.30000000","0.00000000"],["1873.29000000","1.60080000"],["1873.08000000","0.00000000"],["1873.07000000","0.00000000"],["1872.92000000","0.10000000"],["1872.91000000","5.44270000"],["1872.76000000","2.67000000"],["1872.42000000","0.00000000"],["1872.25000000","9.18670000"],["1871.45000000","5.20170000"],["1871.28000000","11.20740000"],["1871.27000000","0.00000000"],["1871.19000000","0.00000000"],["1871.18000000","0.00000000"],["1870.86000000","0.00000000"],["1870.60000000","0.25610000"]],"a":[["1874.14000000","1.06730000"],["1874.15000000","0.00000000"],["1874.19000000","0.00000000"],["1874.27000000","0.13870000"],["1874.30000000","0.53350000"],["1874.35000000","0.00000000"],["1874.37000000","0.00000000"],["1874.47000000","0.00000000"],["1874.53000000","0.08780000"],["1874.57000000","1.56050000"],["1875.33000000","0.30420000"],["1875.50000000","0.00000000"],["1876.05000000","8.94630000"],["1876.08000000","0.00000000"],["1876.12000000","0.00000000"]]}}
{"stream":"ethusd@depth","data":{"e":"depthUpdate","E":1785649608891,"s":"ETHUSD","U":3656116004,"u":3656116020,"b":[["1873.95000000","1.06710000"],["1873.88000000","0.00000000"],["1873.09000000","0.00000000"],["1872.97000000","0.10000000"],["1872.96000000","2.67000000"],["1872.94000000","0.00000000"],["1872.93000000","0.00000000"],["1872.92000000","0.00000000"],["1872.76000000","0.00000000"],["1871.38000000","11.20680000"],["1871.33000000","0.00000000"],["1871.28000000","0.00000000"],["1870.80000000","0.26400000"],["1870.60000000","0.00000000"]],"a":[]}}
{"stream":"ethusd@depth","data":{"e":"depthUpdate","E":1785649609891,"s":"ETHUSD","U":3656116021,"u":3656116034,"b":[["1874.13000000","1.10550000"],["1874.06000000","0.00000000"],["1873.96000000","0.00000000"],["1873.75000000","0.13870000"],["1873.70000000","0.00000000"],["1873.60000000","0.00000000"],["1873.45000000","1.47250000"],["1873.33000000","0.00000000"]],"a":[["1874.27000000","0.00000000"],["1874.36000000","0.00000000"],["1874.41000000","0.13860000"],["1874.53000000","0.00000000"],["1874.60000000","0.00000000"],["1874.63000000","0.00000000"],["1874.66000000","1.47190000"],["1874.70000000","0.10990000"]]}}
{"stream":"ethusd@depth","data":{"e":"depthUpdate","E":1785649610891,"s":"ETHUSD","U":3656116035,"u":3656116035,"b":[["1871.40000000","11.20670000"],["1871.38000000","0.00000000"]],"a":[]}}
{"stream":"ethusd@depth","data":{"e":"depthUpdate","E":1785649611891,"s":"ETHUSD","U":3656116036,"u":3656116037,"b":[["1871.43000000","11.20650000"],["1871.40000000","0.00000000"]],"a":[["1876.05000000","0.00000000"],["1876.30000000","8.94800000"]]}}
{"stream":"ethusd@depth","data":{"e":"depthUpdate","E":1785649612891,"s":"ETHUSD","U":3656116038,"u":3656116043,"b":[["1874.01000000","1.06710000"],["1873.95000000","0.00000000"],["1873.48000000","1.60060000"],["1873.29000000","0.00000000"]],"a":[["1876.25000000","8.94770000"],["1876.26000000","0.00000000"],["1876.30000000","0.00000000"]]}}
{"stream":"ethusd@depth","data":{"e":"depthUpdate","E":1785649613891,"s":"ETHUSD","U":3656116044,"u":3656116044,"b":[],"a":[["1876.23000000","8.94750000"],["1876.25000000","0.00000000"]]}}
{"stream":"btcusd@depth","data":{"e":"depthUpdate","E":1785649614891,"s":"BTCUSD","U":4527243321,"u":4527243336,"b":[["63356.36000000","0.00000000"],["63288.41000000","0.00000000"],["63186.58000000","0.00000000"],["63086.08000000","0.00000000"],["60269.46000000","0.01659000"],["60210.58000000","0.16608000"],["60113.79000000","0.83175000"],["60018.25000000","0.83307000"]],"a":[["63385.35000000","0.00000000"],["63437.14000000","0.00000000"],["63539.36000000","0.00000000"],["63640.59000000","0.00000000"],["66633.46000000","0.01500000"],["66698.60000000","0.14992000"],["66805.94000000","0.74843000"],["66912.24000000","0.74724000"]]}}
{"stream":"ethusd@depth","data":{"e":"depthUpdate","E":1785649614891,"s":"ETHUSD","U":3656116045,"u":3656116046,"b":[["1874.01000000","0.00000000"],["1873.96000000","1.06710000"]],"a":[]}}
{"stream":"btcusd@depth","data":{"e":"depthUpdate","E":1785649615891,"s":"BTCUSD","U":4527243337,"u":4527243346,"b":[["63360.05000000","0.01578000"],["60269.46000000","0.00000000"],["60210.58000000","0.00000000"],["60113.79000000","0.00000000"],["60018.25000000","0.00000000"]],"a":[["63384.86000000","0.01577000"],["66633.46000000","0.00000000"],["66698.60000000","0.00000000"],["66805.94000000","0.00000000"],["66912.24000000","0.00000000"]]}}
{"stream":"ethusd@depth","data":{"e":"depthUpdate","E":1785649615892,"s":"ETHUSD","U":3656116047,"u":3656116104,"b":[["1874.14000000","1.06700000"],["1874.08000000","0.00000000"],["1874.02000000","0.00000000"],["1873.96000000","0.00000000"],["1873.94000000","0.00000000"],["1873.73000000","0.53360000"],["1873.68000000","1.60050000"],["1873.59000000","0.00000000"],["1873.48000000","0.00000000"],["1873.41000000","0.10000000"],["1873.28000000","0.00000000"],["1873.07000000","2.66900000"],["1872.97000000","0.00000000"],["1872.96000000","0.00000000"],["1872.89000000","2.13410000"],["1872.50000000","0.00000000"],["1871.94000000","5.34200000"],["1871.58000000","11.20560000"],["1871.55000000","0.00000000"],["1871.54000000","0.00000000"],["1871.51000000","0.00000000"],["1871.50000000","0.00000000"],["1871.47000000","0.00000000"],["1871.44000000","0.00000000"],["1871.43000000","0.00000000"],["1871.29000000","0.00000000"],["1867.05000000","7.06420000"],["1866.85000000","7.00560000"],["1865.26000000","0.00000000"],["1865.21000000","0.00000000"]],"a":[["1874.14000000","0.00000000"],["1874.20000000","0.00000000"],["1874.25000000","0.00000000"],["1874.30000000","0.00000000"],["1874.32000000","1.06700000"],["1874.46000000","0.53340000"],["1874.66000000","0.00000000"],["1874.71000000","1.47180000"],["1874.81000000","0.00000000"],["1875.12000000","2.66600000"],["1875.33000000","0.00000000"],["1875.40000000","0.00000000"],["1875.55000000","0.31950000"],["1876.17000000","2.66740000"],["1881.72000000","0.00000000"],["1881.74000000","0.00000000"],["1881.79000000","0.00000000"],["1881.84000000","0.00000000"],["1881.93000000","0.00000000"],["1882.02000000","0.00000000"],["1882.03000000","7.02590000"],["1882.50000000","8.56510000"],["1882.60000000","8.61740000"],["1882.70000000","8.69670000"],["1882.75000000","8.53000000"],["1882.80000000","8.67040000"],["1883.35000000","0.00000000"]]}}
{"stream":"btcusd@depth","data":{"e":"depthUpdate","E":1785649616892,"s":"BTCUSD","U":4527243347,"u":4527243348,"b":[["63297.93000000","0.15798000"]],"a":[["63447.06000000","0.15761000"]]}}
{"stream":"ethusd@depth","data":{"e":"depthUpdate","E":1785649616892,"s":"ETHUSD","U":3656116105,"u":3656116107,"b":[["1874.28000000","0.02940000"],["1871.59000000","16.40720000"],["1871.58000000","0.00000000"]],"a":[["1883.34000000","9.04320000"]]}}
{"stream":"btcusd@depth","data":{"e":"depthUpdate","E":1785649617892,"s":"BTCUSD","U":4527243349,"u":4527243350,"b":[["63196.02000000","0.79118000"]],"a":[["63549.38000000","0.78678000"]]}}
{"stream":"btcusd@depth","data":{"e":"depthUpdate","E":1785649619892,"s":"BTCUSD","U":4527243351,"u":4527243352,"b":[["63095.43000000","0.79245000"]],"a":[["63650.68000000","0.78553000"]]}}
{"stream":"ethusd@depth","data":{"e":"depthUpdate","E":1785649620892,"s":"ETHUSD","U":3656116108,"u":3656116109,"b":[["1870.80000000","0.00000000"]],"a":[["1874.48000000","0.05730000"]]}}
{"stream":"ethusd@depth","data":{"e":"depthUpdate","E":1785649621892,"s":"ETHUSD","U":3656116110,"u":3656116111,"b":[["1874.21000000","1.06700000"],["1874.14000000","0.00000000"]],"a":[]}}
{"stream":"ethusd@depth","data":{"e":"depthUpdate","E":1785649622892,"s":"ETHUSD","U":3656116112,"u":3656116117,"b":[["1873.81000000","0.13870000"],["1873.75000000","0.00000000"],["1872.46000000","9.18570000"],["1872.25000000","0.00000000"],["1871.60000000","11.20550000"],["1871.59000000","5.20170000"]],"a":[["1874.41000000","0.00000000"],["1874.47000000","0.13870000"],["1874.71000000","0.00000000"],["1874.77000000","3.03260000"],["1875.66000000","0.00000000"],["1875.82000000","9.16930000"]]}}
{"stream":"ethusd@depth","data":{"e":"depthUpdate","E":1785649625892,"s":"ETHUSD","U":3656116118,"u":3656116118,"b":[["1870.99000000","0.30350000"]],"a":[]}}
{"stream":"btcusd@depth","data":{"e":"depthUpdate","E":1785649628892,"s":"BTCUSD","U":4527243353,"u":4527243368,"b":[["63360.05000000","0.00000000"],["63297.93000000","0.00000000"],["63196.02000000","0.00000000"],["63095.43000000","0.00000000"],["60269.15000000","0.01659000"],["60210.36000000","0.16608000"],["60113.65000000","0.83175000"],["60018.16000000","0.83308000"]],"a":[["63384.86000000","0.00000000"],["63447.06000000","0.00000000"],["63549.38000000","0.00000000"],["63650.68000000","0.00000000"],["66633.04000000","0.01500000"],["66698.08000000","0.14992000"],["66805.34000000","0.74844000"],["66911.58000000","0.74725000"]]}}
{"stream":"btcusd@depth","data":{"e":"depthUpdate","E":1785649629893,"s":"BTCUSD","U":4527243369,"u":4527243389,"b":[["63367.08000000","0.03401000"],["63366.47000000","0.04733000"],["63365.97000000","0.00000000"],["63362.86000000","0.00000000"],["63360.98000000","0.01578000"],["63299.09000000","0.15798000"],["60269.15000000","0.00000000"],["60210.36000000","0.00000000"],["60113.65000000","0.00000000"],["60018.16000000","0.00000000"]],"a":[["63376.33000000","0.00000000"],["63376.34000000","0.00300000"],["63384.99000000","0.00000000"],["63385.95000000","0.01577000"],["63386.13000000","0.03428000"],["63447.92000000","0.15760000"],["66633.04000000","0.00000000"],["66698.08000000","0.00000000"],["66805.34000000","0.00000000"],["66911.58000000","0.00000000"]]}}
{"stream":"ethusd@depth","data":{"e":"depthUpdate","E":1785649629893,"s":"ETHUSD","U":3656116119,"u":3656116191,"b":[["1874.31000000","1.09910000"],["1874.28000000","1.06690000"],["1874.21000000","0.00000000"],["1874.20000000","0.00000000"],["1874.13000000","0.00000000"],["1874.04000000","1.56050000"],["1874.01000000","0.53360000"],["1873.90000000","1.60030000"],["1873.88000000","0.13870000"],["1873.87000000","0.00000000"],["1873.81000000","0.00000000"],["1873.73000000","0.00000000"],["1873.68000000","0.00000000"],["1873.58000000","1.47260000"],["1873.46000000","6.60150000"],["1873.45000000","0.00000000"],["1873.41000000","0.00000000"],["1873.40000000","3.77980000"],["1873.29000000","2.13380000"],["1873.27000000","0.00000000"],["1873.20000000","0.00000000"],["1873.07000000","0.00000000"],["1872.91000000","0.00000000"],["1872.89000000","0.00000000"],["1872.54000000","2.66750000"],["1872.40000000","3.73440000"],["1871.78000000","11.20440000"],["1871.77000000","0.00000000"],["1871.65000000","0.00000000"],["1871.63000000","0.00000000"],["1871.60000000","0.00000000"],["1871.24000000","0.29470000"],["1870.99000000","0.00000000"],["1867.13000000","7.00480000"],["1865.32000000","0.00000000"]],"a":[["1874.32000000","0.00000000"],["1874.38000000","0.00000000"],["1874.46000000","0.00000000"],["1874.47000000","1.06690000"],["1874.48000000","0.00000000"],["1874.51000000","0.00000000"],["1874.52000000","0.00000000"],["1874.54000000","0.00000000"],["1874.55000000","0.13840000"],["1874.57000000","0.00000000"],["1874.66000000","0.00000000"],["1874.70000000","0.05780000"],["1874.76000000","0.00000000"],["1874.77000000","1.56050000"],["1874.81000000","2.00530000"],["1874.88000000","0.09520000"],["1875.11000000","3.64830000"],["1875.12000000","0.00000000"],["1875.22000000","1.56050000"],["1875.48000000","2.66600000"],["1875.55000000","0.00000000"],["1875.88000000","0.30230000"],["1876.23000000","0.00000000"],["1876.47000000","8.95050000"],["1876.51000000","0.00000000"],["1882.03000000","0.00000000"],["1882.07000000","0.00000000"],["1883.34000000","0.00000000"],["1883.35000000","9.00330000"],["1883.40000000","9.07540000"]]}}
{"stream":"btcusd@depth","data":{"e":"depthUpdate","E":1785649630893,"s":"BTCUSD","U":4527243390,"u":4527243391,"b":[["63197.38000000","0.79117000"]],"a":[["63550.03000000","0.78678000"]]}}
{"stream":"ethusd@depth","data":{"e":"depthUpdate","E":1785649630893,"s":"ETHUSD","U":3656116192,"u":3656116193,"b":[["1874.36000000","0.02960000"],["1871.79000000","11.20440000"],["1871.78000000","0.00000000"]],"a":[]}}
{"stream":"ethusd@depth","data":{"e":"depthUpdate","E":1785649631893,"s":"ETHUSD","U":3656116194,"u":3656116231,"b":[["1874.28000000","0.00000000"],["1874.22000000","0.00000000"],["1874.14000000","0.00000000"],["1874.10000000","0.39450000"],["1874.09000000","0.00000000"],["1874.03000000","0.00000000"],["1874.01000000","0.00000000"],["1873.96000000","0.13840000"],["1873.90000000","0.00000000"],["1873.88000000","0.00000000"],["1873.85000000","0.53360000"],["1873.70000000","0.00000000"],["1873.50000000","1.03360000"],["1873.47000000","0.00000000"],["1873.41000000","0.10000000"],["1873.29000000","0.00000000"],["1872.90000000","0.00000000"],["1872.49000000","0.80580000"],["1872.40000000","0.00000000"],["1871.64000000","1.29800000"],["1871.24000000","0.00000000"],["1871.03000000","0.21910000"]],"a":[["1874.52000000","0.53340000"],["1874.55000000","0.00000000"],["1874.63000000","0.13860000"],["1874.66000000","0.00000000"],["1874.81000000","0.00000000"],["1874.92000000","1.47200000"],["1875.32000000","2.66600000"],["1875.48000000","0.00000000"],["1875.82000000","0.00000000"],["1875.88000000","0.00000000"],["1875.97000000","9.16850000"],["1876.46000000","8.94910000"],["1876.47000000","0.00000000"]]}}
{"stream":"btcusd@depth","data":{"e":"depthUpdate","E":1785649632893,"s":"BTCUSD","U":4527243392,"u":4527243393,"b":[["63096.96000000","0.79243000"]],"a":[["63651.17000000","0.78553000"]]}}
{"stream":"ethusd@depth","data":{"e":"depthUpdate","E":1785649632893,"s":"ETHUSD","U":3656116232,"u":3656116232,"b":[],"a":[["1876.45000000","8.94910000"],["1876.46000000","0.00000000"]]}}
{"stream":"ethusd@depth","data":{"e":"depthUpdate","E":1785649633893,"s":"ETHUSD","U":3656116233,"u":3656116234,"b":[["1874.15000000","0.50080000"],["1874.10000000","0.00000000"]],"a":[]}}
{"stream":"ethusd@depth","data":{"e":"depthUpdate","E":1785649635893,"s":"ETHUSD","U":3656116235,"u":3656116235,"b":[],"a":[["1875.67000000","0.30480000"]]}}
{"stream":"ethusd@depth","data":{"e":"depthUpdate","E":1785649636893,"s":"ETHUSD","U":3656116236,"u":3656116243,"b":[["1874.22000000","0.68500000"],["1874.15000000","0.00000000"],["1873.99000000","0.53360000"],["1873.85000000","0.00000000"],["1872.87000000","1.37680000"],["1872.49000000","0.00000000"]],"a":[["1874.52000000","0.00000000"],["1874.67000000","0.53340000"]]}}
{"stream":"ethusd@depth","data":{"e":"depthUpdate","E":1785649637893,"s":"ETHUSD","U":3656116244,"u":3656116247,"b":[["1874.27000000","0.68870000"],["1874.22000000","0.00000000"],["1873.70000000","1.14950000"],["1873.50000000","0.00000000"]],"a":[]}}
{"stream":"btcusd@depth","data":{"e":"depthUpdate","E":1785649640893,"s":"BTCUSD","U":4527243394,"u":4527243406,"b":[["63363.17000000","0.00000000"],["63362.07000000","0.03150000"],["63361.09000000","0.00000000"],["63360.80000000","0.00000000"],["63347.91000000","0.06310000"],["63334.55000000","0.07900000"],["63334.47000000","0.00000000"],["63330.20000000","0.00000000"],["63300.35000000","0.33130000"],["63300.05000000","0.00000000"]],"a":[["63384.71000000","0.00000000"],["63435.95000000","0.00000000"],["63436.85000000","0.20470000"],["63540.72000000","0.00000000"],["63542.03000000","0.26411000"]]}}
{"stream":"ethusd@depth","data":{"e":"depthUpdate","E":1785649640893,"s":"ETHUSD","U":3656116248,"u":3656116267,"b":[["1874.33000000","0.96090000"],["1874.27000000","0.00000000"],["1874.13000000","0.53350000"],["1873.99000000","0.00000000"],["1873.59000000","0.10000000"],["1873.47000000","0.00000000"],["1873.41000000","0.00000000"],["1867.16000000","7.09580000"],["1865.38000000","6.02070000"]],"a":[["1874.47000000","0.00000000"],["1874.52000000","0.99950000"],["1874.67000000","0.00000000"],["1874.85000000","0.53330000"],["1876.02000000","0.00000000"],["1876.70000000","5.32850000"],["1882.11000000","0.00000000"],["1882.12000000","0.00000000"],["1882.14000000","7.03030000"],["1883.40000000","0.00000000"],["1883.41000000","8.96340000"]]}}
{"stream":"btcusd@depth","data":{"e":"depthUpdate","E":1785649641893,"s":"BTCUSD","U":4527243407,"u":4527243412,"b":[["63365.17000000","0.00077000"],["63362.10000000","0.03150000"],["63362.08000000","0.00000000"],["63362.07000000","0.00000000"],["63301.36000000","0.33130000"],["63301.34000000","0.00000000"],["63300.35000000","0.00000000"]],"a":[["63385.87000000","0.00077000"]]}}
{"stream":"ethusd@depth","data":{"e":"depthUpdate","E":1785649641893,"s":"ETHUSD","U":3656116268,"u":3656116268,"b":[["1871.80000000","11.20430000"],["1871.79000000","0.00000000"]],"a":[]}}
{"stream":"ethusd@depth","data":{"e":"depthUpdate","E":1785649642893,"s":"ETHUSD","U":3656116269,"u":3656116282,"b":[["1874.33000000","0.00000000"],["1874.28000000","1.06690000"],["1874.16000000","1.56050000"],["1874.13000000","0.00000000"],["1873.95000000","0.53360000"],["1873.40000000","2.66900000"]],"a":[["1874.45000000","1.06690000"],["1874.52000000","0.00000000"],["1874.71000000","0.53340000"],["1874.77000000","0.00000000"],["1874.80000000","0.00000000"],["1874.85000000","0.00000000"],["1875.19000000","1.56050000"],["1875.47000000","1.56050000"]]}}
{"stream":"btcusd@depth","data":{"e":"depthUpdate","E":1785649643893,"s":"BTCUSD","U":4527243413,"u":4527243414,"b":[["63362.12000000","0.03150000"],["63362.10000000","0.00000000"],["63301.38000000","0.33130000"],["63301.36000000","0.00000000"]],"a":[]}}
{"stream":"ethusd@depth","data":{"e":"depthUpdate","E":1785649643893,"s":"ETHUSD","U":3656116283,"u":3656116283,"b":[["1873.59000000","0.00000000"],["1873.47000000","0.10000000"]],"a":[]}}
{"stream":"ethusd@depth","data":{"e":"depthUpdate","E":1785649644893,"s":"ETHUSD","U":3656116284,"u":3656116284,"b":[["1873.68000000","1.47230000"],["1873.58000000","0.00000000"]],"a":[]}}
{"stream":"btcusd@depth","data":{"e":"depthUpdate","E":1785649645894,"s":"BTCUSD","U":4527243415,"u":4527243415,"b":[["63090.80000000","0.00000000"]],"a":[]}}
{"stream":"btcusd@depth","data":{"e":"depthUpdate","E":1785649647894,"s":"BTCUSD","U":4527243416,"u":4527243436,"b":[["63363.68000000","0.03150000"],["63362.26000000","0.00000000"],["63362.12000000","0.00000000"],["63323.69000000","0.20389000"],["63302.94000000","0.33130000"],["63301.51000000","0.00000000"],["63301.38000000","0.00000000"],["63130.75000000","0.00000000"],["63097.57000000","0.00608000"]],"a":[["63376.33000000","0.00000000"],["63376.34000000","0.00300000"],["63381.00000000","0.00000000"],["63384.23000000","0.00000000"],["63392.68000000","0.11800000"],["63436.85000000","0.00000000"],["63437.75000000","0.20474000"],["63542.03000000","0.00000000"],["63543.54000000","0.26281000"]]}}
{"stream":"ethusd@depth","data":{"e":"depthUpdate","E":1785649647894,"s":"ETHUSD","U":3656116285,"u":3656116286,"b":[["1874.34000000","1.06690000"],["1874.28000000","0.00000000"]],"a":[]}}
{"stream":"btcusd@depth","data":{"e":"depthUpdate","E":1785649648894,"s":"BTCUSD","U":4527243437,"u":4527243454,"b":[["63363.73000000","0.03150000"],["63363.72000000","0.00000000"],["63363.68000000","0.00000000"],["63302.98000000","0.33130000"],["63302.97000000","0.00000000"],["63302.94000000","0.00000000"]],"a":[["63376.31000000","0.00000000"],["63376.32000000","0.00000000"],["63376.33000000","0.00000000"],["63376.34000000","0.00300000"],["63625.16000000","0.00000000"],["63652.50000000","0.00000000"]]}}
{"stream":"ethusd@depth","data":{"e":"depthUpdate","E":1785649648894,"s":"ETHUSD","U":3656116287,"u":3656116287,"b":[],"a":[["1881.03000000","0.00000000"]]}}
{"stream":"btcusd@depth","data":{"e":"depthUpdate","E":1785649649894,"s":"BTCUSD","U":4527243455,"u":4527243455,"b":[],"a":[["63381.01000000","0.00000000"],["63382.03000000","0.00410000"]]}}
{"stream":"ethusd@depth","data":{"e":"depthUpdate","E":1785649649894,"s":"ETHUSD","U":3656116288,"u":3656116289,"b":[["1872.39000000","3.73430000"],["1871.64000000","0.00000000"]],"a":[]}}
{"stream":"btcusd@depth","data":{"e":"depthUpdate","E":1785649650894,"s":"BTCUSD","U":4527243456,"u":4527243456,"b":[],"a":[["63385.62000000","0.00000000"]]}}
{"stream":"ethusd@depth","data":{"e":"depthUpdate","E":1785649650894,"s":"ETHUSD","U":3656116290,"u":3656116293,"b":[["1873.69000000","6.59630000"],["1873.48000000","0.10000000"],["1873.47000000","0.00000000"],["1873.46000000","0.00000000"],["1873.41000000","0.00000000"]],"a":[]}}
{"stream":"btcusd@depth","data":{"e":"depthUpdate","E":1785649651894,"s":"BTCUSD","U":4527243457,"u":4527243458,"b":[],"a":[["63612.06000000","0.00014000"],["63639.78000000","0.00018000"]]}}
{"stream":"ethusd@depth","data":{"e":"depthUpdate","E":1785649651894,"s":"ETHUSD","U":3656116294,"u":3656116322,"b":[["1874.11000000","0.53350000"],["1873.95000000","0.00000000"],["1873.93000000","1.60030000"],["1873.70000000","0.00000000"],["1873.48000000","0.00000000"],["1873.44000000","0.00000000"],["1873.43000000","0.00000000"],["1873.42000000","0.00000000"],["1873.41000000","0.10000000"],["1873.29000000","2.13370000"],["1872.87000000","0.00000000"]],"a":[["1874.45000000","0.00000000"],["1874.53000000","1.06680000"],["1874.71000000","0.00000000"],["1874.90000000","0.53330000"]]}}
{"stream":"btcusd@depth","data":{"e":"depthUpdate","E":1785649654894,"s":"BTCUSD","U":4527243459,"u":4527243473,"b":[["63365.17000000","0.00000000"],["63364.11000000","0.03150000"],["63363.73000000","0.00000000"],["63326.85000000","0.20533000"],["63303.37000000","0.33130000"],["63303.36000000","0.00000000"],["63302.98000000","0.00000000"],["63138.21000000","0.00000000"]],"a":[["63376.34000000","0.00000000"],["63385.87000000","0.00000000"],["63392.43000000","0.00530000"],["63437.75000000","0.00000000"],["63438.65000000","0.00000000"],["63541.12000000","0.26377000"],["63543.54000000","0.00000000"],["63548.58000000","0.26179000"]]}}
{"stream":"ethusd@depth","data":{"e":"depthUpdate","E":1785649654894,"s":"ETHUSD","U":3656116323,"u":3656116370,"b":[["1874.43000000","1.06680000"],["1874.42000000","1.17990000"],["1874.36000000","0.00000000"],["1874.34000000","0.00000000"],["1874.31000000","0.00000000"],["1874.25000000","0.53350000"],["1874.11000000","0.00000000"],["1874.03000000","0.13870000"],["1873.96000000","0.00000000"],["1873.60000000","2.66900000"],["1873.40000000","0.00000000"],["1872.68000000","9.18450000"],["1872.46000000","0.00000000"],["1871.98000000","11.20320000"],["1871.95000000","0.00000000"],["1871.94000000","5.34200000"],["1871.93000000","0.00000000"],["1871.85000000","0.00000000"],["1871.83000000","0.00000000"],["1871.80000000","0.00000000"],["1871.31000000","0.31250000"],["1871.03000000","0.00000000"],["1867.35000000","7.08640000"],["1865.45000000","0.00000000"]],"a":[["1874.53000000","0.00000000"],["1874.60000000","0.00000000"],["1874.63000000","0.00000000"],["1874.67000000","1.06680000"],["1874.69000000","0.13860000"],["1874.70000000","0.00000000"],["1874.88000000","0.00000000"],["1874.92000000","0.00000000"],["1874.99000000","2.58450000"],["1875.14000000","1.60020000"],["1875.32000000","0.00000000"],["1875.54000000","2.66600000"],["1875.67000000","0.00000000"],["1875.91000000","2.13360000"],["1875.92000000","0.28250000"],["1876.45000000","0.00000000"],["1876.70000000","14.27940000"],["1878.94000000","4.43940000"],["1881.03000000","0.00160000"],["1882.14000000","0.00000000"],["1882.19000000","0.00000000"],["1882.20000000","0.00000000"],["1882.26000000","0.00000000"],["1882.82000000","26.55600000"],["1883.41000000","0.00000000"],["1883.42000000","8.94000000"],["1883.47000000","9.02820000"]]}}
{"stream":"btcusd@depth","data":{"e":"depthUpdate","E":1785649655894,"s":"BTCUSD","U":4527243474,"u":4527243478,"b":[["63369.24000000","0.03155000"],["63369.23000000","0.00077000"],["63365.98000000","0.00000000"],["63364.12000000","0.03150000"],["63364.11000000","0.00000000"]],"a":[["63389.93000000","0.00077000"]]}}
{"stream":"ethusd@depth","data":{"e":"depthUpdate","E":1785649655894,"s":"ETHUSD","U":3656116371,"u":3656116373,"b":[["1874.43000000","1.09620000"]],"a":[["1883.53000000","9.00960000"],["1883.59000000","9.10630000"]]}}
{"stream":"btcusd@depth","data":{"e":"depthUpdate","E":1785649656894,"s":"BTCUSD","U":4527243479,"u":4527243482,"b":[["63369.09000000","0.03375000"],["63367.08000000","0.00000000"]],"a":[["63386.13000000","0.00000000"],["63388.13000000","0.03389000"]]}}
{"stream":"ethusd@depth","data":{"e":"depthUpdate","E":1785649656894,"s":"ETHUSD","U":3656116374,"u":3656116377,"b":[["1874.09000000","0.13870000"],["1874.03000000","0.00000000"],["1873.79000000","1.47260000"],["1873.68000000","0.00000000"]],"a":[["1874.69000000","0.00000000"],["1874.76000000","0.13860000"],["1874.99000000","1.11280000"],["1875.06000000","1.47120000"]]}}
{"stream":"btcusd@depth","data":{"e":"depthUpdate","E":1785649657894,"s":"BTCUSD","U":4527243483,"u":4527243484,"b":[["63360.67000000","0.00409000"],["63358.81000000","0.00000000"]],"a":[["63382.02000000","0.00300000"]]}}
{"stream":"btcusd@depth","data":{"e":"depthUpdate","E":1785649659894,"s":"BTCUSD","U":4527243485,"u":4527243493,"b":[["63351.59000000","0.04356000"],["63348.67000000","0.00000000"],["63315.55000000","0.27164000"],["63308.69000000","0.00000000"]],"a":[["63382.01000000","0.00000000"],["63382.02000000","0.00000000"],["63382.03000000","0.00000000"],["63382.07000000","0.00000000"],["63382.08000000","0.00300000"],["63383.37000000","0.00410000"],["63391.37000000","0.00000000"],["63393.51000000","0.04352000"]]}}
{"stream":"ethusd@depth","data":{"e":"depthUpdate","E":1785649659894,"s":"ETHUSD","U":3656116378,"u":3656116393,"b":[["1874.43000000","2.18760000"],["1874.42000000","0.00000000"],["1874.29000000","0.13870000"],["1874.14000000","0.00000000"],["1874.09000000","0.00000000"],["1873.99000000","1.47270000"],["1873.79000000","0.00000000"],["1872.94000000","9.18320000"],["1872.68000000","0.00000000"],["1872.02000000","11.20300000"],["1872.01000000","0.00000000"],["1871.98000000","0.00000000"]],"a":[["1874.76000000","0.00000000"],["1874.81000000","0.00000000"],["1874.96000000","0.13860000"],["1874.99000000","0.00000000"],["1875.06000000","0.00000000"],["1875.12000000","0.00000000"],["1875.22000000","2.68940000"],["1875.26000000","1.47100000"],["1875.97000000","0.00000000"],["1876.16000000","9.16770000"]]}}
{"stream":"btcusd@depth","data":{"e":"depthUpdate","E":1785649660894,"s":"BTCUSD","U":4527243494,"u":4527243507,"b":[],"a":[["63382.05000000","0.00000000"],["63382.06000000","0.00000000"],["63382.07000000","0.00000000"],["63382.08000000","0.00300000"]]}}
{"stream":"ethusd@depth","data":{"e":"depthUpdate","E":1785649660895,"s":"ETHUSD","U":3656116394,"u":3656116477,"b":[["1874.43000000","0.02940000"],["1874.37000000","0.00000000"],["1874.35000000","1.17560000"],["1874.31000000","0.00000000"],["1874.29000000","0.00000000"],["1874.25000000","0.00000000"],["1874.19000000","0.00000000"],["1874.14000000","1.06700000"],["1874.09000000","0.00000000"],["1874.00000000","0.13870000"],["1873.99000000","0.00000000"],["1873.94000000","0.53360000"],["1873.93000000","0.00000000"],["1873.92000000","0.00000000"],["1873.89000000","0.00000000"],["1873.72000000","1.60040000"],["1873.70000000","1.47300000"],["1873.60000000","0.00000000"],["1873.41000000","0.00000000"],["1873.35000000","2.66900000"],["1873.29000000","0.00000000"],["1872.94000000","0.00000000"],["1872.90000000","2.13400000"],["1872.65000000","9.18470000"],["1872.11000000","0.00000000"],["1872.08000000","0.00000000"],["1872.02000000","0.00000000"],["1871.84000000","11.20400000"],["1871.31000000","0.00000000"],["1867.35000000","0.00000000"],["1867.20000000","0.00000000"],["1866.95000000","8.04140000"],["1865.57000000","0.00000000"],["1865.52000000","0.00000000"]],"a":[["1874.66000000","0.13860000"],["1874.67000000","0.00000000"],["1874.72000000","0.53340000"],["1874.86000000","0.00000000"],["1874.90000000","0.00000000"],["1874.92000000","0.08820000"],["1874.95000000","1.60040000"],["1874.96000000","1.47200000"],["1875.01000000","0.00000000"],["1875.06000000","0.00000000"],["1875.07000000","0.00000000"],["1875.11000000","0.00000000"],["1875.14000000","0.00000000"],["1875.16000000","0.00000000"],["1875.22000000","1.56050000"],["1875.26000000","0.00000000"],["1875.46000000","3.64830000"],["1875.49000000","2.66600000"],["1875.54000000","0.00000000"],["1875.76000000","0.26670000"],["1875.81000000","0.00000000"],["1875.92000000","0.00000000"],["1876.13000000","0.00000000"],["1876.56000000","8.94990000"],["1876.57000000","0.00000000"],["1876.58000000","0.00000000"],["1876.61000000","0.00000000"],["1876.67000000","0.00000000"],["1876.70000000","5.32850000"],["1876.81000000","0.00000000"],["1876.83000000","0.00000000"],["1876.88000000","0.00000000"],["1876.90000000","0.00000000"],["1876.91000000","0.00000000"],["1876.95000000","0.00000000"],["1882.26000000","7.12130000"],["1883.59000000","0.00000000"]]}}
{"stream":"ethusd@depth","data":{"e":"depthUpdate","E":1785649661895,"s":"ETHUSD","U":3656116478,"u":3656116486,"b":[["1874.20000000","0.81070000"],["1874.14000000","0.00000000"],["1871.12000000","0.28450000"],["1867.19000000","7.04980000"],["1867.00000000","8.01170000"]],"a":[["1875.37000000","2.66600000"],["1875.49000000","0.00000000"],["1882.17000000","7.04290000"],["1883.53000000","0.00000000"]]}}
{"stream":"btcusd@depth","data":{"e":"depthUpdate","E":1785649662895,"s":"BTCUSD","U":4527243508,"u":4527243509,"b":[],"a":[["63530.74000000","0.00000000"],["63540.85000000","0.00000000"]]}}
{"stream":"ethusd@depth","data":{"e":"depthUpdate","E":1785649662895,"s":"ETHUSD","U":3656116487,"u":3656116489,"b":[["1874.26000000","0.90540000"],["1874.20000000","0.00000000"]],"a":[["1876.55000000","8.94980000"],["1876.56000000","0.00000000"]]}}
{"stream":"ethusd@depth","data":{"e":"depthUpdate","E":1785649663895,"s":"ETHUSD","U":3656116490,"u":3656116490,"b":[],"a":[["1876.54000000","8.94970000"],["1876.55000000","0.00000000"]]}}
{"stream":"btcusd@depth","data":{"e":"depthUpdate","E":1785649664895,"s":"BTCUSD","U":4527243510,"u":4527243510,"b":[],"a":[["63545.00000000","0.00000000"]]}}
{"stream":"ethusd@depth","data":{"e":"depthUpdate","E":1785649667895,"s":"ETHUSD","U":3656116491,"u":3656116496,"b":[["1874.43000000","1.14570000"],["1874.35000000","0.00000000"],["1874.32000000","1.06690000"],["1874.26000000","0.00000000"]],"a":[["1874.92000000","0.00000000"],["1875.01000000","1.14850000"]]}}
{"stream":"ethusd@depth","data":{"e":"depthUpdate","E":1785649670895,"s":"ETHUSD","U":3656116497,"u":3656116500,"b":[["1874.08000000","0.13870000"],["1874.00000000","0.00000000"],["1873.78000000","1.47260000"],["1873.70000000","0.00000000"]],"a":[["1874.66000000","0.00000000"],["1874.74000000","0.13860000"],["1874.96000000","0.00000000"],["1875.04000000","1.47190000"]]}}
{"stream":"btcusd@depth","data":{"e":"depthUpdate","E":1785649674895,"s":"BTCUSD","U":4527243511,"u":4527243527,"b":[["63360.98000000","0.00000000"],["63299.09000000","0.00000000"],["63197.38000000","0.00000000"],["63096.96000000","0.00000000"],["60272.04000000","0.01659000"],["60212.83000000","0.16607000"],["60115.76000000","0.83172000"],["60019.98000000","0.83305000"]],"a":[["63385.95000000","0.00000000"],["63447.92000000","0.00000000"],["63547.45000000","0.00000000"],["63550.03000000","0.00000000"],["63651.17000000","0.00000000"],["66636.20000000","0.01500000"],["66701.71000000","0.14992000"],["66809.36000000","0.74839000"],["66915.93000000","0.74720000"]]}}
{"stream":"ethusd@depth","data":{"e":"depthUpdate","E":1785649674895,"s":"ETHUSD","U":3656116501,"u":3656116503,"b":[["1874.32000000","0.00000000"],["1874.26000000","1.06700000"]],"a":[["1875.91000000","0.00000000"]]}}
{"stream":"btcusd@depth","data":{"e":"depthUpdate","E":1785649675895,"s":"BTCUSD","U":4527243528,"u":4527243539,"b":[["63369.10000000","0.16080000"],["63362.59000000","0.01578000"],["63357.82000000","0.00000000"],["60272.04000000","0.00000000"],["60212.83000000","0.00000000"],["60115.76000000","0.00000000"],["60019.98000000","0.00000000"]],"a":[["63386.61000000","0.01577000"],["66636.20000000","0.00000000"],["66701.71000000","0.00000000"],["66809.36000000","0.00000000"],["66915.93000000","0.00000000"]]}}
{"stream":"btcusd@depth","data":{"e":"depthUpdate","E":1785649676896,"s":"BTCUSD","U":4527243540,"u":4527243543,"b":[["63300.43000000","0.15797000"]],"a":[["63448.86000000","0.15760000"],["63570.72000000","0.00000000"],["63586.14000000","0.00000000"]]}}
{"stream":"ethusd@depth","data":{"e":"depthUpdate","E":1785649676896,"s":"ETHUSD","U":3656116504,"u":3656116505,"b":[["1874.32000000","1.06690000"],["1874.26000000","0.00000000"]],"a":[]}}
{"stream":"btcusd@depth","data":{"e":"depthUpdate","E":1785649677896,"s":"BTCUSD","U":4527243544,"u":4527243547,"b":[["63335.78000000","0.07888000"],["63318.40000000","0.00000000"],["63198.48000000","0.79115000"]],"a":[["63551.22000000","0.78676000"]]}}
{"stream":"btcusd@depth","data":{"e":"depthUpdate","E":1785649679896,"s":"BTCUSD","U":4527243548,"u":4527243549,"b":[["63097.86000000","0.79241000"]],"a":[["63652.56000000","0.78551000"]]}}
{"stream":"ethusd@depth","data":{"e":"depthUpdate","E":1785649680896,"s":"ETHUSD","U":3656116506,"u":3656116507,"b":[],"a":[["1875.00000000","3.64830000"],["1875.46000000","0.00000000"]]}}
{"stream":"ethusd@depth","data":{"e":"depthUpdate","E":1785649682896,"s":"ETHUSD","U":3656116508,"u":3656116510,"b":[["1874.32000000","0.00000000"],["1874.07000000","0.53350000"],["1873.94000000","0.00000000"]],"a":[]}}
{"stream":"ethusd@depth","data":{"e":"depthUpdate","E":1785649685896,"s":"ETHUSD","U":3656116511,"u":3656116514,"b":[["1873.91000000","1.60030000"],["1873.72000000","0.00000000"],["1873.28000000","2.13380000"],["1872.90000000","0.00000000"]],"a":[]}}
{"stream":"btcusd@depth","data":{"e":"depthUpdate","E":1785649692897,"s":"BTCUSD","U":4527243550,"u":4527243565,"b":[["63362.59000000","0.00000000"],["63300.43000000","0.00000000"],["63198.48000000","0.00000000"],["63097.86000000","0.00000000"],["60272.77000000","0.01659000"],["60214.08000000","0.16607000"],["60117.45000000","0.83170000"],["60022.04000000","0.83302000"]],"a":[["63386.61000000","0.00000000"],["63448.86000000","0.00000000"],["63551.22000000","0.00000000"],["63652.56000000","0.00000000"],["66636.64000000","0.01500000"],["66701.57000000","0.14992000"],["66808.73000000","0.74840000"],["66914.89000000","0.74721000"]]}}
{"stream":"ethusd@depth","data":{"e":"depthUpdate","E":1785649693897,"s":"ETHUSD","U":3656116515,"u":3656116530,"b":[["1873.67000000","0.10000000"],["1873.36000000","0.00000000"],["1871.88000000","11.20380000"],["1871.87000000","0.00000000"],["1871.84000000","0.00000000"]],"a":[["1874.72000000","0.00000000"],["1874.89000000","0.53330000"],["1875.00000000","0.00000000"],["1875.01000000","0.00000000"],["1875.06000000","0.00000000"],["1875.08000000","0.00000000"],["1875.12000000","1.12010000"],["1875.14000000","0.00000000"],["1875.18000000","3.13300000"]]}}
{"stream":"ethusd@depth","data":{"e":"depthUpdate","E":1785649694897,"s":"ETHUSD","U":3656116531,"u":3656116533,"b":[["1873.67000000","0.00000000"],["1873.36000000","0.10000000"],["1871.91000000","11.20360000"],["1871.90000000","0.00000000"],["1871.88000000","0.00000000"]],"a":[]}}
{"stream":"btcusd@depth","data":{"e":"depthUpdate","E":1785649695897,"s":"BTCUSD","U":4527243566,"u":4527243579,"b":[["63363.64000000","0.01578000"],["63301.85000000","0.15797000"],["63200.21000000","0.79113000"],["60272.77000000","0.00000000"],["60214.08000000","0.00000000"],["60117.45000000","0.00000000"],["60022.04000000","0.00000000"]],"a":[["63387.39000000","0.01577000"],["63449.27000000","0.15760000"],["63551.30000000","0.78676000"],["66636.64000000","0.00000000"],["66701.57000000","0.00000000"],["66808.73000000","0.00000000"],["66914.89000000","0.00000000"]]}}
{"stream":"ethusd@depth","data":{"e":"depthUpdate","E":1785649695897,"s":"ETHUSD","U":3656116534,"u":3656116535,"b":[["1874.12000000","0.13850000"],["1874.08000000","0.00000000"]],"a":[["1874.74000000","0.00000000"],["1874.78000000","0.13860000"]]}}
{"stream":"btcusd@depth","data":{"e":"depthUpdate","E":1785649696897,"s":"BTCUSD","U":4527243580,"u":4527243581,"b":[["63099.85000000","0.79239000"]],"a":[["63652.37000000","0.78551000"]]}}
{"stream":"ethusd@depth","data":{"e":"depthUpdate","E":1785649698897,"s":"ETHUSD","U":3656116536,"u":3656116537,"b":[],"a":[["1874.75000000","0.53340000"],["1874.89000000","0.00000000"]]}}
{"stream":"ethusd@depth","data":{"e":"depthUpdate","E":1785649699897,"s":"ETHUSD","U":3656116538,"u":3656116548,"b":[["1874.27000000","1.06700000"],["1874.12000000","0.00000000"],["1874.07000000","0.00000000"],["1874.04000000","1.69920000"],["1873.93000000","0.53360000"],["1873.91000000","0.00000000"],["1873.71000000","1.60050000"]],"a":[["1874.70000000","0.13860000"],["1874.78000000","0.00000000"],["1874.99000000","0.03700000"],["1875.05000000","0.00000000"],["1875.12000000","0.00000000"]]}}
{"stream":"btcusd@depth","data":{"e":"depthUpdate","E":1785649702897,"s":"BTCUSD","U":4527243582,"u":4527243583,"b":[["63316.35000000","0.11044000"],["63308.48000000","0.00000000"]],"a":[]}}
{"stream":"ethusd@depth","data":{"e":"depthUpdate","E":1785649702897,"s":"ETHUSD","U":3656116549,"u":3656116549,"b":[],"a":[["1969.99000000","0.00000000"]]}}
{"stream":"ethusd@depth","data":{"e":"depthUpdate","E":1785649706898,"s":"ETHUSD","U":3656116550,"u":3656116550,"b":[],"a":[["1874.97000000","0.97300000"]]}}
{"stream":"btcusd@depth","data":{"e":"depthUpdate","E":1785649707898,"s":"BTCUSD","U":4527243584,"u":4527243586,"b":[["63367.92000000","0.03117000"]],"a":[["63382.05000000","0.00300000"],["63382.06000000","0.03087000"],["63382.08000000","0.00000000"]]}}
{"stream":"ethusd@depth","data":{"e":"depthUpdate","E":1785649707898,"s":"ETHUSD","U":3656116551,"u":3656116551,"b":[],"a":[["1969.99000000","0.00560000"]]}}
{"stream":"ethusd@depth","data":{"e":"depthUpdate","E":1785649713898,"s":"ETHUSD","U":3656116552,"u":3656116553,"b":[],"a":[["1874.96000000","3.13300000"],["1875.18000000","0.00000000"]]}}
{"stream":"ethusd@depth","data":{"e":"depthUpdate","E":1785649714898,"s":"ETHUSD","U":3656116554,"u":3656116554,"b":[],"a":[["1874.74000000","0.05730000"]]}}
{"stream":"btcusd@depth","data":{"e":"depthUpdate","E":1785649715898,"s":"BTCUSD","U":4527243587,"u":4527243587,"b":[["63369.09000000","0.00000000"],["63204.57000000","0.00000000"],["63062.01000000","0.00000000"]],"a":[["63388.13000000","0.00000000"],["63521.39000000","0.00000000"],["63663.99000000","0.00000000"]]}}
{"stream":"btcusd@depth","data":{"e":"depthUpdate","E":1785649716898,"s":"BTCUSD","U":4527243588,"u":4527243588,"b":[],"a":[["63551.00000000","0.00000000"]]}}
{"stream":"btcusd@depth","data":{"e":"depthUpdate","E":1785649721899,"s":"BTCUSD","U":4527243589,"u":4527243592,"b":[["63360.67000000","0.00000000"],["63359.42000000","0.00410000"],["63351.59000000","0.00000000"],["63349.28000000","0.04356000"]],"a":[["63381.61000000","0.00300000"],["63381.62000000","0.00410000"],["63382.05000000","0.00000000"],["63383.37000000","0.00000000"]]}}
{"stream":"ethusd@depth","data":{"e":"depthUpdate","E":1785649721899,"s":"ETHUSD","U":3656116555,"u":3656116556,"b":[["1874.33000000","1.06690000"],["1874.27000000","0.00000000"]],"a":[]}}
{"stream":"btcusd@depth","data":{"e":"depthUpdate","E":1785649728899,"s":"BTCUSD","U":4527243593,"u":4527243598,"b":[],"a":[["63376.34000000","0.00300000"],["63381.61000000","0.00000000"],["63513.21000000","0.00038000"],["63545.00000000","0.00675000"],["63547.45000000","0.00649000"],["63552.00000000","0.00620000"],["63564.52000000","0.00056000"]]}}
{"stream":"ethusd@depth","data":{"e":"depthUpdate","E":1785649728899,"s":"ETHUSD","U":3656116557,"u":3656116668,"b":[["1874.43000000","0.99470000"],["1874.33000000","0.00000000"],["1874.25000000","0.00000000"],["1874.16000000","0.00000000"],["1874.04000000","0.00000000"],["1873.99000000","0.00000000"],["1873.93000000","0.00000000"],["1873.90000000","0.02940000"],["1873.85000000","0.00000000"],["1873.80000000","0.00000000"],["1873.78000000","0.00000000"],["1873.75000000","1.06720000"],["1873.71000000","0.13870000"],["1873.69000000","0.00000000"],["1873.66000000","0.00000000"],["1873.60000000","0.00000000"],["1873.52000000","0.00000000"],["1873.49000000","1.56050000"],["1873.45000000","0.53370000"],["1873.41000000","1.47320000"],["1873.37000000","0.00000000"],["1873.36000000","0.00000000"],["1873.35000000","0.00000000"],["1873.34000000","1.56050000"],["1873.31000000","1.60080000"],["1873.28000000","0.00000000"],["1873.18000000","0.00000000"],["1872.94000000","1.56050000"],["1872.93000000","6.69890000"],["1872.92000000","2.67000000"],["1872.90000000","0.00000000"],["1872.66000000","0.00000000"],["1872.65000000","0.00000000"],["1872.51000000","2.13450000"],["1872.36000000","9.18610000"],["1871.91000000","0.00000000"],["1871.76000000","0.00000000"],["1871.65000000","0.00000000"],["1871.49000000","0.00000000"],["1871.27000000","11.20760000"],["1871.24000000","0.00000000"],["1871.12000000","0.00000000"],["1870.79000000","0.21870000"],["1869.60000000","0.00000000"],["1867.19000000","0.00000000"],["1867.18000000","0.00000000"],["1867.16000000","0.00000000"],["1867.13000000","0.00000000"],["1867.05000000","0.00000000"],["1867.00000000","0.00000000"],["1866.95000000","0.00000000"],["1866.90000000","0.00000000"],["1866.85000000","0.00000000"],["1866.74000000","0.00000000"],["1866.67000000","7.05870000"],["1866.58000000","7.75200000"],["1865.68000000","0.00000000"],["1865.63000000","0.00000000"],["1865.38000000","0.00000000"]],"a":[["1874.44000000","0.16810000"],["1874.45000000","2.09390000"],["1874.57000000","0.00000000"],["1874.61000000","0.00000000"],["1874.63000000","1.47220000"],["1874.68000000","0.00000000"],["1874.70000000","0.00000000"],["1874.71000000","1.56050000"],["1874.74000000","0.00000000"],["1874.75000000","0.00000000"],["1874.76000000","0.00000000"],["1874.87000000","0.00000000"],["1874.94000000","0.44960000"],["1874.95000000","0.00000000"],["1874.99000000","0.00000000"],["1875.02000000","2.66700000"],["1875.04000000","0.00000000"],["1875.13000000","2.13430000"],["1875.17000000","0.00000000"],["1875.22000000","0.00000000"],["1875.37000000","0.00000000"],["1875.43000000","0.23000000"],["1875.47000000","0.00000000"],["1875.73000000","9.16960000"],["1875.76000000","0.00000000"],["1875.92000000","0.00000000"],["1876.02000000","5.33040000"],["1876.12000000","8.94670000"],["1876.14000000","0.00000000"],["1876.16000000","0.00000000"],["1876.23000000","0.00000000"],["1876.24000000","0.00000000"],["1876.32000000","0.00000000"],["1876.34000000","0.00000000"],["1876.44000000","0.00000000"],["1876.49000000","0.00000000"],["1876.51000000","0.00000000"],["1876.52000000","0.00000000"],["1876.54000000","0.00000000"],["1876.70000000","0.00000000"],["1878.98000000","0.00000000"],["1881.65000000","7.08640000"],["1883.20000000","0.00000000"],["1883.47000000","0.00000000"]]}}
{"stream":"ethusd@trade","data":{"e":"trade","E":1785649729010,"s":"ETHUSD","t":51376013,"p":"1874.43000000","q":"0.13870000","b":1909997672,"a":1909997721,"T":1785649729010,"m":true,"M":true}}
{"stream":"ethusd@trade","data":{"e":"trade","E":1785649729110,"s":"ETHUSD","t":51376014,"p":"1874.43000000","q":"0.13870000","b":1909997672,"a":1909997723,"T":1785649729110,"m":true,"M":true}}
{"stream":"ethusd@trade","data":{"e":"trade","E":1785649729210,"s":"ETHUSD","t":51376015,"p":"1874.43000000","q":"0.13870000","b":1909997672,"a":1909997724,"T":1785649729210,"m":true,"M":true}}
{"stream":"ethusd@trade","data":{"e":"trade","E":1785649729311,"s":"ETHUSD","t":51376016,"p":"1874.43000000","q":"0.13870000","b":1909997672,"a":1909997729,"T":1785649729311,"m":true,"M":true}}
{"stream":"ethusd@trade","data":{"e":"trade","E":1785649729410,"s":"ETHUSD","t":51376017,"p":"1874.43000000","q":"0.13870000","b":1909997672,"a":1909997731,"T":1785649729410,"m":true,"M":true}}
{"stream":"ethusd@trade","data":{"e":"trade","E":1785649729442,"s":"ETHUSD","t":51376018,"p":"1874.43000000","q":"0.30120000","b":1909997672,"a":1909997733,"T":1785649729441,"m":true,"M":true}}
{"stream":"ethusd@depth","data":{"e":"depthUpdate","E":1785649729899,"s":"ETHUSD","U":3656116669,"u":3656116703,"b":[["1874.43000000","0.00000000"],["1873.71000000","0.00000000"],["1873.55000000","0.13870000"],["1873.41000000","0.00000000"],["1873.25000000","1.47330000"],["1872.54000000","0.00000000"],["1872.39000000","0.00000000"],["1871.74000000","1.73550000"],["1871.54000000","2.42970000"],["1866.63000000","7.68590000"],["1866.54000000","7.98390000"],["1865.68000000","8.94820000"],["1865.62000000","8.91680000"],["1865.56000000","8.99980000"],["1865.50000000","9.01110000"],["1865.45000000","8.92690000"]],"a":[["1874.23000000","0.13870000"],["1874.25000000","1.56050000"],["1874.29000000","0.00000000"],["1874.42000000","0.00000000"],["1874.44000000","0.02940000"],["1874.45000000","1.56050000"],["1874.52000000","0.00000000"],["1874.53000000","1.47230000"],["1874.63000000","0.00000000"],["1874.94000000","0.00000000"],["1875.19000000","0.00000000"],["1875.57000000","9.17050000"],["1875.73000000","0.00000000"],["1876.11000000","0.00000000"],["1876.12000000","8.94680000"],["1876.13000000","0.00000000"]]}}
{"stream":"ethusd@depth","data":{"e":"depthUpdate","E":1785649730899,"s":"ETHUSD","U":3656116704,"u":3656116709,"b":[["1865.39000000","9.09790000"]],"a":[["1874.20000000","0.53350000"],["1874.87000000","2.66700000"],["1875.02000000","0.00000000"],["1876.11000000","8.94660000"],["1876.12000000","0.00000000"],["1882.54000000","0.01500000"]]}}
{"stream":"btcusd@depth","data":{"e":"depthUpdate","E":1785649731899,"s":"BTCUSD","U":4527243599,"u":4527243604,"b":[["63369.30000000","0.03240000"],["63220.37000000","0.11594000"],["63077.80000000","0.18151000"]],"a":[["63388.32000000","0.03378000"],["63537.28000000","0.11811000"],["63679.92000000","0.19296000"]]}}
{"stream":"ethusd@depth","data":{"e":"depthUpdate","E":1785649731899,"s":"ETHUSD","U":3656116710,"u":3656116714,"b":[["1871.28000000","11.20740000"],["1871.27000000","0.00000000"]],"a":[["1874.25000000","0.00000000"],["1874.45000000","0.00000000"],["1875.00000000","1.56050000"],["1875.28000000","1.56050000"]]}}
{"stream":"ethusd@depth","data":{"e":"depthUpdate","E":1785649732899,"s":"ETHUSD","U":3656116715,"u":3656116719,"b":[],"a":[["1874.25000000","1.56050000"],["1874.53000000","3.03280000"],["1875.00000000","0.00000000"],["1875.28000000","0.00000000"],["1876.09000000","8.94650000"],["1876.11000000","0.00000000"]]}}
{"stream":"ethusd@depth","data":{"e":"depthUpdate","E":1785649733899,"s":"ETHUSD","U":3656116720,"u":3656116721,"b":[],"a":[["1874.43000000","2.52080000"],["1874.96000000","0.00000000"]]}}
{"stream":"ethusd@depth","data":{"e":"depthUpdate","E":1785649734899,"s":"ETHUSD","U":3656116722,"u":3656116727,"b":[["1873.90000000","1.11790000"],["1869.50000000","3.91600000"],["1865.28000000","6.56280000"]],"a":[["1874.47000000","1.11340000"],["1878.88000000","3.81720000"],["1883.09000000","6.46290000"]]}}
{"stream":"ethusd@depth","data":{"e":"depthUpdate","E":1785649737900,"s":"ETHUSD","U":3656116728,"u":3656116760,"b":[["1874.09000000","1.12940000"],["1874.03000000","0.00000000"],["1874.02000000","0.00000000"],["1873.97000000","0.89170000"],["1873.91000000","0.00000000"],["1873.90000000","0.02940000"],["1873.81000000","0.00000000"],["1873.75000000","0.00000000"],["1873.59000000","0.53370000"],["1873.45000000","0.00000000"],["1872.93000000","6.59890000"],["1872.36000000","0.00000000"],["1872.17000000","9.18700000"],["1871.43000000","11.20650000"],["1871.37000000","0.00000000"],["1871.36000000","0.00000000"],["1871.31000000","0.00000000"],["1871.29000000","0.00000000"],["1871.28000000","0.00000000"]],"a":[["1874.18000000","0.00000000"],["1874.20000000","0.00000000"],["1874.23000000","0.00000000"],["1874.24000000","0.13870000"],["1874.25000000","0.00000000"],["1874.36000000","0.00000000"],["1874.47000000","0.00000000"],["1874.48000000","0.00000000"],["1874.53000000","1.56050000"],["1874.54000000","1.47220000"],["1874.60000000","0.00000000"],["1874.66000000","1.19400000"]]}}
{"stream":"ethusd@depth","data":{"e":"depthUpdate","E":1785649738900,"s":"ETHUSD","U":3656116761,"u":3656116775,"b":[["1873.97000000","0.00000000"],["1873.91000000","0.67970000"],["1873.68000000","0.13870000"],["1873.55000000","0.00000000"],["1873.38000000","1.47250000"],["1873.25000000","0.00000000"],["1871.44000000","11.20640000"],["1871.43000000","0.00000000"]],"a":[["1874.24000000","0.00000000"],["1874.34000000","0.13870000"],["1874.37000000","0.53350000"],["1874.53000000","0.00000000"],["1874.54000000","0.00000000"],["1874.64000000","1.47150000"],["1874.71000000","1.56050000"],["1874.90000000","1.56050000"],["1875.18000000","1.56050000"],["1875.46000000","0.00000000"]]}}
{"stream":"ethusd@depth","data":{"e":"depthUpdate","E":1785649739900,"s":"ETHUSD","U":3656116776,"u":3656116776,"b":[["1871.45000000","16.40810000"],["1871.44000000","0.00000000"]],"a":[]}}
{"stream":"ethusd@depth","data":{"e":"depthUpdate","E":1785649740900,"s":"ETHUSD","U":3656116777,"u":3656116810,"b":[["1874.08000000","0.81420000"],["1873.96000000","0.00000000"],["1873.91000000","0.00000000"],["1873.90000000","0.00000000"],["1873.73000000","2.09410000"],["1873.59000000","0.00000000"],["1873.50000000","1.22130000"],["1873.31000000","0.00000000"],["1872.95000000","0.10000000"],["1872.94000000","0.00000000"],["1871.58000000","11.20560000"],["1871.57000000","0.00000000"],["1871.52000000","0.00000000"],["1871.45000000","5.20170000"],["1866.71000000","7.12230000"],["1865.39000000","0.00000000"]],"a":[["1874.37000000","0.00000000"],["1874.43000000","0.00000000"],["1874.52000000","0.53340000"],["1874.71000000","0.00000000"],["1874.86000000","2.52080000"],["1874.87000000","0.00000000"],["1874.90000000","0.00000000"],["1875.13000000","0.00000000"],["1875.19000000","2.66600000"],["1875.46000000","1.56050000"],["1875.51000000","1.62510000"],["1875.61000000","1.56050000"],["1876.09000000","0.00000000"],["1876.34000000","8.94830000"],["1881.65000000","0.00000000"],["1881.73000000","0.00000000"],["1883.42000000","0.00000000"]]}}
{"stream":"btcusd@depth","data":{"e":"depthUpdate","E":1785649741900,"s":"BTCUSD","U":4527243605,"u":4527243606,"b":[],"a":[["63391.43000000","0.04353000"],["63393.51000000","0.00000000"],["63527.88000000","0.00000000"]]}}
{"stream":"ethusd@depth","data":{"e":"depthUpdate","E":1785649741900,"s":"ETHUSD","U":3656116811,"u":3656116847,"b":[["1874.08000000","0.00000000"],["1874.04000000","0.02960000"],["1874.03000000","0.82250000"],["1873.76000000","0.13870000"],["1873.68000000","0.00000000"],["1872.97000000","0.00000000"],["1872.96000000","0.00000000"],["1872.95000000","0.00000000"],["1872.94000000","0.10000000"],["1872.41000000","9.18600000"],["1872.17000000","0.00000000"],["1871.59000000","16.40730000"],["1871.58000000","0.00000000"],["1866.81000000","7.09830000"],["1865.45000000","0.00000000"]],"a":[["1874.34000000","0.00000000"],["1874.41000000","0.84860000"],["1874.42000000","0.13870000"],["1874.64000000","1.56050000"],["1874.72000000","1.47220000"],["1874.91000000","1.56050000"],["1875.46000000","0.00000000"],["1875.57000000","0.00000000"],["1875.61000000","0.00000000"],["1875.77000000","9.16940000"],["1881.79000000","7.07040000"],["1881.98000000","7.67590000"]]}}
{"stream":"btcusd@depth","data":{"e":"depthUpdate","E":1785649742900,"s":"BTCUSD","U":4527243607,"u":4527243608,"b":[],"a":[["63612.06000000","0.00000000"],["63639.78000000","0.00000000"]]}}
{"stream":"ethusd@depth","data":{"e":"depthUpdate","E":1785649742900,"s":"ETHUSD","U":3656116848,"u":3656116850,"b":[["1873.12000000","2.66900000"],["1872.92000000","0.00000000"],["1871.60000000","11.20550000"],["1871.59000000","5.20170000"]],"a":[]}}
{"stream":"btcusd@depth","data":{"e":"depthUpdate","E":1785649743900,"s":"BTCUSD","U":4527243609,"u":4527243624,"b":[["63363.64000000","0.00000000"],["63301.85000000","0.00000000"],["63200.21000000","0.00000000"],["63099.85000000","0.00000000"],["60273.36000000","0.01659000"],["60214.23000000","0.16607000"],["60117.25000000","0.83170000"],["60021.53000000","0.83303000"]],"a":[["63387.39000000","0.00000000"],["63449.27000000","0.00000000"],["63551.30000000","0.00000000"],["63652.37000000","0.00000000"],["66637.47000000","0.01500000"],["66702.87000000","0.14991000"],["66810.44000000","0.74838000"],["66916.94000000","0.74719000"]]}}
{"stream":"ethusd@depth","data":{"e":"depthUpdate","E":1785649744900,"s":"ETHUSD","U":3656116851,"u":3656116867,"b":[["1874.03000000","0.00000000"],["1873.95000000","0.00000000"],["1873.90000000","1.01720000"],["1873.73000000","1.56050000"],["1873.57000000","0.53370000"],["1873.50000000","0.00000000"],["1873.31000000","1.52690000"]],"a":[["1874.36000000","1.01440000"],["1874.37000000","0.00000000"],["1874.41000000","0.00000000"],["1874.52000000","0.00000000"],["1875.05000000","2.66700000"],["1875.19000000","0.00000000"],["1876.33000000","8.94820000"],["1876.34000000","0.00000000"],["1881.03000000","0.00000000"]]}}
{"stream":"btcusd@depth","data":{"e":"depthUpdate","E":1785649745900,"s":"BTCUSD","U":4527243625,"u":4527243638,"b":[["63363.81000000","0.01578000"],["63301.74000000","0.15797000"],["63199.87000000","0.79114000"],["60273.36000000","0.00000000"],["60214.23000000","0.00000000"],["60117.25000000","0.00000000"],["60021.53000000","0.00000000"]],"a":[["63387.68000000","0.01577000"],["63449.83000000","0.15760000"],["63552.11000000","0.78675000"],["66637.47000000","0.00000000"],["66702.87000000","0.00000000"],["66810.44000000","0.00000000"],["66916.94000000","0.00000000"]]}}
{"stream":"ethusd@depth","data":{"e":"depthUpdate","E":1785649745900,"s":"ETHUSD","U":3656116868,"u":3656116872,"b":[],"a":[["1874.35000000","0.53350000"],["1874.64000000","0.00000000"],["1874.91000000","0.00000000"],["1875.34000000","1.56050000"],["1875.62000000","1.56050000"]]}}
{"stream":"ethusd@depth","data":{"e":"depthUpdate","E":1785649746900,"s":"ETHUSD","U":3656116873,"u":3656116876,"b":[],"a":[["1874.58000000","1.56050000"],["1874.86000000","4.08130000"],["1875.34000000","0.00000000"],["1875.62000000","0.00000000"]]}}
{"stream":"btcusd@depth","data":{"e":"depthUpdate","E":1785649747900,"s":"BTCUSD","U":4527243639,"u":4527243640,"b":[],"a":[["63376.34000000","0.00300000"],["63381.61000000","0.00000000"]]}}
{"stream":"ethusd@depth","data":{"e":"depthUpdate","E":1785649747900,"s":"ETHUSD","U":3656116877,"u":3656116904,"b":[["1874.09000000","0.00000000"],["1873.98000000","1.17610000"],["1873.91000000","0.00000000"],["1873.90000000","0.00000000"],["1873.85000000","1.06720000"],["1873.76000000","0.00000000"],["1873.65000000","0.00000000"],["1873.55000000","0.13870000"],["1873.38000000","0.00000000"],["1873.25000000","1.47330000"],["1872.41000000","0.00000000"],["1872.20000000","9.18690000"]],"a":[["1874.21000000","0.13870000"],["1874.28000000","0.53350000"],["1874.30000000","1.06720000"],["1874.31000000","0.00000000"],["1874.35000000","0.00000000"],["1874.36000000","0.00000000"],["1874.42000000","0.00000000"],["1874.49000000","0.00000000"],["1874.51000000","1.47230000"],["1874.55000000","1.17090000"],["1874.61000000","0.00000000"],["1874.66000000","0.00000000"],["1874.72000000","0.00000000"],["1875.56000000","9.17060000"],["1875.77000000","0.00000000"],["1876.24000000","8.94760000"],["1876.26000000","0.00000000"],["1876.27000000","0.00000000"],["1876.28000000","0.00000000"],["1876.29000000","0.00000000"],["1876.33000000","0.00000000"]]}}
{"stream":"btcusd@depth","data":{"e":"depthUpdate","E":1785649748900,"s":"BTCUSD","U":4527243641,"u":4527243668,"b":[["63367.92000000","0.00000000"],["63337.46000000","0.07900000"],["63334.55000000","0.00000000"],["63099.31000000","0.79240000"]],"a":[["63376.31000000","0.00000000"],["63376.32000000","0.00000000"],["63376.33000000","0.00300000"],["63376.34000000","0.00000000"],["63382.06000000","0.00000000"],["63519.63000000","0.00028000"],["63523.51000000","0.00038000"],["63580.25000000","0.00043000"],["63604.71000000","0.00014000"],["63632.43000000","0.00018000"],["63653.38000000","0.78550000"]]}}
{"stream":"ethusd@depth","data":{"e":"depthUpdate","E":1785649748900,"s":"ETHUSD","U":3656116905,"u":3656116919,"b":[["1873.92000000","0.00000000"],["1873.86000000","1.06720000"],["1873.85000000","0.00000000"],["1873.26000000","6.59780000"],["1872.93000000","0.00000000"]],"a":[["1874.20000000","1.06710000"],["1874.21000000","0.00000000"],["1874.22000000","0.13860000"],["1874.30000000","0.00000000"],["1874.58000000","0.00000000"],["1874.69000000","1.56050000"],["1874.97000000","0.00000000"],["1875.46000000","0.00000000"],["1881.03000000","0.00160000"]]}}
{"stream":"btcusd@depth","data":{"e":"depthUpdate","E":1785649749901,"s":"BTCUSD","U":4527243669,"u":4527243669,"b":[],"a":[["63376.33000000","0.00000000"],["63376.34000000","0.00300000"]]}}
{"stream":"ethusd@depth","data":{"e":"depthUpdate","E":1785649749901,"s":"ETHUSD","U":3656116920,"u":3656116940,"b":[["1873.98000000","0.00000000"],["1873.92000000","1.16890000"],["1873.86000000","0.00000000"],["1873.80000000","0.00000000"],["1873.74000000","1.06720000"],["1873.12000000","0.00000000"],["1872.94000000","0.00000000"],["1872.81000000","2.67000000"],["1872.52000000","0.10000000"],["1871.60000000","0.00000000"],["1871.34000000","11.20740000"],["1871.28000000","0.00000000"]],"a":[["1874.22000000","0.00000000"],["1874.25000000","0.13870000"],["1874.42000000","1.56050000"],["1874.49000000","0.39810000"],["1874.51000000","0.00000000"],["1874.55000000","1.47210000"],["1875.13000000","2.13450000"],["1875.18000000","0.00000000"],["1875.51000000","0.00000000"],["1876.15000000","8.94700000"],["1876.23000000","0.00000000"],["1876.24000000","0.00000000"]]}}
{"stream":"btcusd@depth","data":{"e":"depthUpdate","E":1785649750901,"s":"BTCUSD","U":4527243670,"u":4527243670,"b":[],"a":[["63559.20000000","0.00000000"]]}}
{"stream":"ethusd@depth","data":{"e":"depthUpdate","E":1785649750901,"s":"ETHUSD","U":3656116941,"u":3656116973,"b":[["1874.10000000","0.00000000"],["1874.09000000","0.00000000"],["1874.07000000","0.00000000"],["1874.04000000","1.12450000"],["1874.00000000","1.06710000"],["1873.98000000","0.00000000"],["1873.92000000","0.00000000"],["1873.81000000","0.00000000"],["1873.74000000","0.00000000"],["1873.71000000","0.53360000"],["1873.57000000","0.00000000"],["1873.51000000","1.60060000"],["1873.31000000","0.00000000"],["1871.41000000","11.20660000"],["1871.36000000","0.00000000"],["1871.34000000","0.00000000"]],"a":[["1874.21000000","0.13870000"],["1874.25000000","0.00000000"],["1874.28000000","0.00000000"],["1874.43000000","0.00000000"],["1874.45000000","0.53340000"],["1874.49000000","0.00000000"],["1874.55000000","1.47210000"],["1874.61000000","1.12360000"],["1874.66000000","0.00000000"],["1874.67000000","0.00000000"]]}}
{"stream":"ethusd@depth","data":{"e":"depthUpdate","E":1785649751901,"s":"ETHUSD","U":3656116974,"u":3656116980,"b":[["1873.66000000","0.13870000"],["1873.55000000","0.00000000"],["1873.36000000","1.47280000"],["1873.25000000","0.00000000"],["1872.94000000","2.67000000"],["1872.82000000","0.10000000"],["1872.81000000","0.00000000"],["1872.52000000","0.00000000"]],"a":[["1874.21000000","0.00000000"],["1874.32000000","0.13870000"],["1874.55000000","0.00000000"],["1874.62000000","1.47170000"]]}}
{"stream":"ethusd@depth","data":{"e":"depthUpdate","E":1785649752901,"s":"ETHUSD","U":3656116981,"u":3656116987,"b":[["1872.95000000","0.10000000"],["1872.82000000","0.00000000"],["1872.53000000","0.00000000"],["1872.52000000","0.00000000"]],"a":[["1874.42000000","0.00000000"],["1874.69000000","0.00000000"],["1875.18000000","1.56050000"],["1875.46000000","1.56050000"]]}}
{"stream":"btcusd@depth","data":{"e":"depthUpdate","E":1785649753901,"s":"BTCUSD","U":4527243671,"u":4527243671,"b":[],"a":[["63550.75000000","0.00000000"]]}}
{"stream":"ethusd@depth","data":{"e":"depthUpdate","E":1785649753901,"s":"ETHUSD","U":3656116988,"u":3656116989,"b":[],"a":[["1874.49000000","1.56050000"],["1875.46000000","0.00000000"]]}}
{"stream":"btcusd@depth","data":{"e":"depthUpdate","E":1785649754901,"s":"BTCUSD","U":4527243672,"u":4527243673,"b":[],"a":[["63376.33000000","0.03155000"],["63376.35000000","0.00000000"]]}}
{"stream":"ethusd@depth","data":{"e":"depthUpdate","E":1785649754901,"s":"ETHUSD","U":3656116990,"u":3656116996,"b":[["1871.42000000","11.20660000"],["1871.41000000","0.00000000"]],"a":[["1874.42000000","1.56050000"],["1874.49000000","0.00000000"],["1874.70000000","1.56050000"],["1875.18000000","0.00000000"],["1875.46000000","0.00000000"]]}}
{"stream":"btcusd@depth","data":{"e":"depthUpdate","E":1785649755901,"s":"BTCUSD","U":4527243674,"u":4527243674,"b":[],"a":[["63553.60000000","0.00157000"]]}}
{"stream":"ethusd@depth","data":{"e":"depthUpdate","E":1785649755901,"s":"ETHUSD","U":3656116997,"u":3656116998,"b":[["1874.00000000","0.00000000"],["1873.92000000","1.06710000"]],"a":[]}}
{"stream":"ethusd@depth","data":{"e":"depthUpdate","E":1785649756901,"s":"ETHUSD","U":3656116999,"u":3656117001,"b":[],"a":[["1874.42000000","0.00000000"],["1874.70000000","0.00000000"],["1875.46000000","1.56050000"]]}}
{"stream":"btcusd@depth","data":{"e":"depthUpdate","E":1785649757901,"s":"BTCUSD","U":4527243675,"u":4527243675,"b":[],"a":[["63376.32000000","0.00300000"],["63376.34000000","0.00000000"]]}}
{"stream":"ethusd@depth","data":{"e":"depthUpdate","E":1785649757901,"s":"ETHUSD","U":3656117002,"u":3656117004,"b":[],"a":[["1874.42000000","1.56050000"],["1874.70000000","1.56050000"],["1875.46000000","0.00000000"]]}}
{"stream":"ethusd@depth","data":{"e":"depthUpdate","E":1785649758901,"s":"ETHUSD","U":3656117005,"u":3656117008,"b":[],"a":[["1874.42000000","0.00000000"],["1874.70000000","0.00000000"],["1875.18000000","1.56050000"],["1875.46000000","1.56050000"]]}}
{"stream":"ethusd@depth","data":{"e":"depthUpdate","E":1785649759901,"s":"ETHUSD","U":3656117009,"u":3656117012,"b":[],"a":[["1874.42000000","1.56050000"],["1874.67000000","1.56050000"],["1875.18000000","0.00000000"],["1875.46000000","0.00000000"]]}}
{"stream":"ethusd@depth","data":{"e":"depthUpdate","E":1785649761901,"s":"ETHUSD","U":3656117013,"u":3656117024,"b":[["1873.99000000","1.06710000"],["1873.92000000","0.00000000"],["1871.51000000","11.20600000"],["1871.48000000","0.00000000"],["1871.43000000","0.00000000"],["1871.42000000","0.00000000"]],"a":[["1874.42000000","0.00000000"],["1874.66000000","2.19650000"],["1874.67000000","0.00000000"],["1874.86000000","0.00000000"],["1875.46000000","1.56050000"],["1875.58000000","1.56050000"]]}}
{"stream":"ethusd@depth","data":{"e":"depthUpdate","E":1785649762901,"s":"ETHUSD","U":3656117025,"u":3656117029,"b":[],"a":[["1874.55000000","1.56050000"],["1874.83000000","1.56050000"],["1875.18000000","1.56050000"],["1875.46000000","0.00000000"],["1875.58000000","0.00000000"]]}}
{"stream":"ethusd@depth","data":{"e":"depthUpdate","E":1785649763901,"s":"ETHUSD","U":3656117030,"u":3656117033,"b":[["1874.05000000","1.06710000"],["1873.99000000","0.00000000"]],"a":[["1874.55000000","0.00000000"],["1875.22000000","1.56050000"]]}}
{"stream":"ethusd@depth","data":{"e":"depthUpdate","E":1785649765902,"s":"ETHUSD","U":3656117034,"u":3656117035,"b":[["1872.89000000","2.13420000"],["1872.51000000","0.00000000"]],"a":[]}}
{"stream":"btcusd@depth","data":{"e":"depthUpdate","E":1785649771902,"s":"BTCUSD","U":4527243676,"u":4527243691,"b":[["63363.81000000","0.00000000"],["63301.74000000","0.00000000"],["63199.87000000","0.00000000"],["63099.31000000","0.00000000"],["60274.34000000","0.01659000"],["60215.54000000","0.16607000"],["60118.83000000","0.83168000"],["60023.35000000","0.83300000"]],"a":[["63387.68000000","0.00000000"],["63449.83000000","0.00000000"],["63552.11000000","0.00000000"],["63653.38000000","0.00000000"],["66638.54000000","0.01500000"],["66703.59000000","0.14991000"],["66810.85000000","0.74838000"],["66917.09000000","0.74719000"]]}}
{"stream":"btcusd@depth","data":{"e":"depthUpdate","E":1785649775902,"s":"BTCUSD","U":4527243692,"u":4527243707,"b":[["63365.23000000","0.01578000"],["63303.49000000","0.15796000"],["63201.89000000","0.79111000"],["63101.57000000","0.79237000"],["60274.34000000","0.00000000"],["60215.54000000","0.00000000"],["60118.83000000","0.00000000"],["60023.35000000","0.00000000"]],"a":[["63388.89000000","0.01577000"],["63450.72000000","0.15760000"],["63552.72000000","0.78674000"],["63653.75000000","0.78549000"],["66638.54000000","0.00000000"],["66703.59000000","0.00000000"],["66810.85000000","0.00000000"],["66917.09000000","0.00000000"]]}}
{"stream":"ethusd@depth","data":{"e":"depthUpdate","E":1785649777902,"s":"ETHUSD","U":3656117036,"u":3656117051,"b":[["1873.71000000","0.00000000"],["1871.94000000","0.00000000"],["1868.77000000","0.00000000"],["1865.73000000","9.00120000"],["1782.32000000","0.56100000"],["1780.59000000","5.61610000"],["1777.73000000","56.25130000"],["1774.91000000","56.34080000"]],"a":[["1874.45000000","0.00000000"],["1876.02000000","0.00000000"],["1880.64000000","0.00000000"],["1882.82000000","0.00000000"],["1970.52000000","0.50740000"],["1972.44000000","5.06980000"],["1975.61000000","25.30870000"],["1978.75000000","25.26850000"]]}}
{"stream":"ethusd@depth","data":{"e":"depthUpdate","E":1785649779902,"s":"ETHUSD","U":3656117052,"u":3656117069,"b":[["1874.05000000","0.00000000"],["1874.00000000","1.06710000"],["1873.70000000","0.53370000"],["1871.88000000","5.34220000"],["1868.87000000","53.50790000"],["1865.91000000","62.63840000"],["1782.32000000","0.00000000"],["1780.59000000","0.00000000"],["1777.73000000","0.00000000"],["1774.91000000","0.00000000"]],"a":[["1874.42000000","0.53350000"],["1876.24000000","5.32980000"],["1879.26000000","26.60620000"],["1882.25000000","26.56400000"],["1970.52000000","0.00000000"],["1972.44000000","0.00000000"],["1975.61000000","0.00000000"],["1978.75000000","0.00000000"]]}}
{"stream":"ethusd@depth","data":{"e":"depthUpdate","E":1785649782903,"s":"ETHUSD","U":3656117070,"u":3656117102,"b":[["1874.13000000","1.06700000"],["1874.12000000","1.16600000"],["1874.05000000","0.00000000"],["1874.04000000","0.02960000"],["1874.00000000","0.00000000"],["1873.84000000","0.53360000"],["1873.76000000","0.13870000"],["1873.71000000","1.60050000"],["1873.70000000","0.00000000"],["1873.66000000","0.00000000"],["1873.51000000","0.00000000"],["1873.46000000","1.47320000"],["1873.36000000","0.00000000"],["1873.13000000","0.10000000"],["1873.12000000","2.66900000"],["1872.95000000","0.00000000"],["1872.94000000","0.00000000"],["1872.51000000","2.66750000"],["1872.41000000","9.18590000"],["1872.31000000","3.73450000"],["1872.20000000","0.00000000"],["1871.74000000","0.00000000"],["1871.60000000","11.20550000"],["1871.54000000","0.00000000"],["1871.51000000","0.00000000"]],"a":[["1874.20000000","0.00000000"],["1874.27000000","1.06700000"],["1874.32000000","0.00000000"],["1874.42000000","0.00000000"],["1874.43000000","0.13870000"],["1874.58000000","0.53340000"],["1874.61000000","0.00000000"],["1874.62000000","0.00000000"],["1874.66000000","0.00000000"],["1874.69000000","1.09170000"],["1874.73000000","1.47220000"],["1874.83000000","3.75700000"],["1875.56000000","0.00000000"],["1875.78000000","9.16940000"],["1876.15000000","0.00000000"],["1876.47000000","8.94920000"]]}}
{"stream":"ethusd@depth","data":{"e":"depthUpdate","E":1785649783903,"s":"ETHUSD","U":3656117103,"u":3656117103,"b":[],"a":[["1876.46000000","8.94920000"],["1876.47000000","0.00000000"]]}}
{"stream":"btcusd@depth","data":{"e":"depthUpdate","E":1785649784903,"s":"BTCUSD","U":4527243708,"u":4527243709,"b":[],"a":[["63582.14000000","0.00000000"],["63588.87000000","0.00000000"]]}}
{"stream":"ethusd@depth","data":{"e":"depthUpdate","E":1785649784903,"s":"ETHUSD","U":3656117104,"u":3656117105,"b":[],"a":[["1876.44000000","8.94900000"],["1876.45000000","0.00000000"],["1876.46000000","0.00000000"]]}}
{"stream":"ethusd@depth","data":{"e":"depthUpdate","E":1785649786903,"s":"ETHUSD","U":3656117106,"u":3656117112,"b":[["1874.18000000","1.15280000"],["1874.12000000","0.00000000"]],"a":[["1874.43000000","0.00000000"],["1874.47000000","0.13840000"],["1874.54000000","0.05470000"],["1874.69000000","0.00000000"],["1874.75000000","0.53360000"],["1876.39000000","8.94860000"],["1876.44000000","0.00000000"]]}}
{"stream":"btcusd@depth","data":{"e":"depthUpdate","E":1785649787903,"s":"BTCUSD","U":4527243710,"u":4527243735,"b":[["63365.23000000","0.00000000"],["63363.21000000","0.01578000"],["63303.49000000","0.00000000"],["63201.89000000","0.00000000"],["63101.57000000","0.00000000"],["60274.56000000","0.00000000"],["60215.53000000","0.00000000"],["60118.62000000","0.00000000"],["60022.97000000","0.00000000"]],"a":[["63387.22000000","0.01577000"],["63388.89000000","0.00000000"],["63450.72000000","0.00000000"],["63552.72000000","0.00000000"],["63653.75000000","0.00000000"],["66638.73000000","0.00000000"],["66704.03000000","0.00000000"],["66811.51000000","0.00000000"],["66917.93000000","0.00000000"]]}}
{"stream":"ethusd@depth","data":{"e":"depthUpdate","E":1785649787903,"s":"ETHUSD","U":3656117113,"u":3656117138,"b":[["1874.13000000","0.00000000"],["1874.04000000","0.02960000"],["1873.90000000","0.00000000"],["1873.84000000","0.00000000"],["1873.80000000","0.65580000"],["1873.71000000","0.00000000"],["1873.67000000","0.00000000"],["1873.50000000","0.00000000"],["1873.31000000","1.50760000"],["1873.13000000","0.00000000"],["1873.12000000","0.00000000"],["1872.90000000","0.10000000"],["1872.89000000","0.00000000"],["1872.87000000","2.67000000"],["1872.50000000","1.72440000"]],"a":[["1874.40000000","0.00000000"],["1874.58000000","0.00000000"],["1876.24000000","14.27700000"],["1876.29000000","0.00000000"],["1876.30000000","0.00000000"],["1876.39000000","0.00000000"]]}}
{"stream":"btcusd@depth","data":{"e":"depthUpdate","E":1785649788903,"s":"BTCUSD","U":4527243736,"u":4527243737,"b":[["63301.06000000","0.15797000"]],"a":[["63449.45000000","0.15760000"]]}}
{"stream":"ethusd@depth","data":{"e":"depthUpdate","E":1785649788903,"s":"ETHUSD","U":3656117139,"u":3656117180,"b":[["1874.18000000","0.00000000"],["1874.12000000","0.00000000"],["1873.95000000","1.10780000"],["1873.76000000","0.00000000"],["1873.65000000","0.13870000"],["1873.52000000","0.53370000"],["1873.46000000","0.00000000"],["1873.35000000","1.47320000"],["1872.91000000","0.00000000"],["1872.90000000","0.10000000"],["1872.89000000","0.00000000"],["1872.88000000","0.00000000"],["1872.51000000","0.00000000"],["1872.31000000","0.00000000"],["1871.74000000","1.33970000"],["1871.60000000","0.00000000"],["1871.55000000","1.87560000"],["1871.35000000","11.20700000"]],"a":[["1874.26000000","0.53350000"],["1874.32000000","0.13870000"],["1874.34000000","0.05850000"],["1874.47000000","0.00000000"],["1874.48000000","0.00000000"],["1874.52000000","0.53360000"],["1874.54000000","0.00000000"],["1874.62000000","1.47230000"],["1874.69000000","0.00000000"],["1874.73000000","0.00000000"],["1874.75000000","0.00000000"],["1876.19000000","8.94680000"],["1876.21000000","0.00000000"],["1876.22000000","0.00000000"],["1876.24000000","5.32980000"]]}}
{"stream":"btcusd@depth","data":{"e":"depthUpdate","E":1785649789903,"s":"BTCUSD","U":4527243738,"u":4527243739,"b":[["63199.12000000","0.79115000"]],"a":[["63551.80000000","0.78675000"]]}}
{"stream":"ethusd@depth","data":{"e":"depthUpdate","E":1785649789903,"s":"ETHUSD","U":3656117181,"u":3656117191,"b":[["1873.80000000","0.00000000"],["1873.75000000","0.53750000"],["1873.65000000","0.00000000"],["1873.58000000","0.13870000"],["1872.90000000","0.00000000"],["1872.88000000","0.10000000"],["1872.41000000","0.00000000"],["1872.23000000","9.18680000"]],"a":[["1874.24000000","0.53350000"],["1874.25000000","0.13870000"],["1874.26000000","0.00000000"],["1874.32000000","0.00000000"],["1874.55000000","1.47230000"],["1874.62000000","0.00000000"],["1875.60000000","9.17040000"],["1875.78000000","0.00000000"],["1876.12000000","8.94640000"],["1876.19000000","0.00000000"]]}}
{"stream":"ethusd@depth","data":{"e":"depthUpdate","E":1785649790903,"s":"ETHUSD","U":3656117192,"u":3656117209,"b":[["1873.81000000","0.00000000"],["1873.75000000","0.00000000"],["1873.58000000","0.70260000"],["1873.52000000","0.00000000"],["1873.37000000","0.53370000"],["1873.31000000","0.00000000"],["1872.99000000","0.84580000"],["1872.50000000","0.00000000"],["1872.12000000","1.12780000"],["1871.37000000","11.20680000"],["1871.35000000","0.00000000"]],"a":[["1874.31000000","0.84580000"],["1874.43000000","1.56050000"],["1874.71000000","1.56050000"],["1874.87000000","2.66700000"],["1875.05000000","0.00000000"],["1875.18000000","0.00000000"],["1875.22000000","0.00000000"]]}}
{"stream":"btcusd@depth","data":{"e":"depthUpdate","E":1785649791903,"s":"BTCUSD","U":4527243740,"u":4527243743,"b":[["63098.51000000","0.79241000"]],"a":[["63580.19000000","0.00000000"],["63590.30000000","0.00000000"],["63653.12000000","0.78550000"]]}}
{"stream":"ethusd@depth","data":{"e":"depthUpdate","E":1785649791903,"s":"ETHUSD","U":3656117210,"u":3656117225,"b":[["1873.95000000","0.00000000"],["1873.89000000","1.15210000"],["1873.75000000","0.57990000"],["1873.70000000","0.00000000"],["1873.64000000","0.00000000"],["1873.58000000","0.13870000"]],"a":[["1874.31000000","0.05700000"],["1874.34000000","0.00000000"],["1874.46000000","1.19040000"],["1874.51000000","0.86990000"],["1874.52000000","0.00000000"],["1875.88000000","1.41710000"],["1876.17000000","0.00000000"]]}}
{"stream":"ethusd@depth","data":{"e":"depthUpdate","E":1785649792903,"s":"ETHUSD","U":3656117226,"u":3656117227,"b":[["1873.18000000","0.88130000"],["1872.99000000","0.00000000"]],"a":[]}}
{"stream":"ethusd@depth","data":{"e":"depthUpdate","E":1785649793903,"s":"ETHUSD","U":3656117228,"u":3656117233,"b":[["1873.58000000","0.00000000"],["1873.52000000","0.13870000"],["1873.35000000","0.00000000"],["1873.22000000","1.47330000"]],"a":[["1874.18000000","0.60310000"],["1874.19000000","0.13870000"],["1874.25000000","0.00000000"],["1874.27000000","0.00000000"],["1874.49000000","1.47240000"],["1874.55000000","0.00000000"]]}}
{"stream":"ethusd@depth","data":{"e":"depthUpdate","E":1785649794903,"s":"ETHUSD","U":3656117234,"u":3656117296,"b":[["1874.04000000","0.00000000"],["1873.89000000","0.00000000"],["1873.75000000","1.17080000"],["1873.73000000","0.00000000"],["1873.67000000","0.00000000"],["1873.59000000","0.00000000"],["1873.53000000","0.62620000"],["1873.49000000","0.00000000"],["1873.26000000","0.00000000"],["1873.18000000","0.00000000"],["1872.96000000","0.93810000"],["1872.89000000","6.59910000"],["1872.88000000","0.00000000"],["1872.87000000","1.56050000"],["1872.81000000","1.56050000"],["1872.62000000","2.67000000"],["1872.24000000","0.10000000"],["1871.39000000","0.00000000"],["1871.37000000","0.00000000"],["1871.16000000","11.20810000"],["1871.14000000","0.00000000"],["1870.79000000","0.00000000"],["1870.42000000","0.31810000"],["1866.81000000","0.00000000"],["1866.71000000","0.00000000"],["1866.67000000","0.00000000"],["1866.63000000","0.00000000"],["1866.58000000","0.00000000"],["1866.56000000","7.03020000"],["1866.54000000","0.00000000"],["1866.51000000","7.10730000"],["1865.50000000","0.00000000"]],"a":[["1874.10000000","0.62620000"],["1874.11000000","0.00000000"],["1874.13000000","0.05680000"],["1874.16000000","0.00000000"],["1874.18000000","0.00000000"],["1874.24000000","0.00000000"],["1874.31000000","0.93810000"],["1874.32000000","0.39040000"],["1874.42000000","0.14840000"],["1874.44000000","0.00000000"],["1874.46000000","0.00000000"],["1874.51000000","0.00000000"],["1874.75000000","2.66700000"],["1874.87000000","0.00000000"],["1875.13000000","2.41050000"],["1875.43000000","0.00000000"],["1875.92000000","8.94490000"],["1875.95000000","0.00000000"],["1875.99000000","0.00000000"],["1876.00000000","0.00000000"],["1876.01000000","0.00000000"],["1876.10000000","0.00000000"],["1876.12000000","0.00000000"],["1881.54000000","7.12500000"],["1881.58000000","7.07200000"],["1883.29000000","0.00000000"],["1883.35000000","0.00000000"]]}}
{"stream":"ethusd@depth","data":{"e":"depthUpdate","E":1785649795904,"s":"ETHUSD","U":3656117297,"u":3656117311,"b":[["1873.73000000","0.02970000"],["1873.52000000","0.00000000"],["1873.38000000","0.13870000"],["1873.22000000","0.00000000"],["1873.08000000","1.47350000"],["1872.63000000","0.10000000"],["1872.24000000","0.00000000"],["1872.23000000","0.00000000"],["1872.03000000","9.18770000"],["1865.50000000","8.97380000"],["1865.45000000","8.88040000"],["1865.38000000","8.91970000"],["1865.32000000","8.97610000"],["1865.26000000","9.03790000"]],"a":[["1874.01000000","0.53360000"],["1874.05000000","0.13870000"],["1874.19000000","0.00000000"],["1874.24000000","0.02940000"],["1874.35000000","1.47250000"],["1874.49000000","0.00000000"],["1875.40000000","9.17140000"],["1875.60000000","0.00000000"]]}}
{"stream":"ethusd@depth","data":{"e":"depthUpdate","E":1785649796904,"s":"ETHUSD","U":3656117312,"u":3656117312,"b":[],"a":[["1875.89000000","8.94470000"],["1875.92000000","0.00000000"]]}}
{"stream":"ethusd@depth","data":{"e":"depthUpdate","E":1785649797904,"s":"ETHUSD","U":3656117313,"u":3656117314,"b":[["1873.73000000","0.00000000"]],"a":[["1874.24000000","0.00000000"]]}}
{"stream":"ethusd@depth","data":{"e":"depthUpdate","E":1785649798904,"s":"ETHUSD","U":3656117315,"u":3656117316,"b":[["1873.80000000","0.02960000"]],"a":[["1874.31000000","0.96780000"]]}}
{"stream":"ethusd@depth","data":{"e":"depthUpdate","E":1785649799904,"s":"ETHUSD","U":3656117317,"u":3656117318,"b":[],"a":[["1874.07000000","1.56050000"],["1874.83000000","2.19650000"]]}}
{"stream":"btcusd@depth","data":{"e":"depthUpdate","E":1785649800904,"s":"BTCUSD","U":4527243744,"u":4527243769,"b":[["63363.21000000","0.00000000"],["63362.22000000","0.01578000"],["63301.06000000","0.00000000"],["63199.12000000","0.00000000"],["63098.51000000","0.00000000"],["60271.67000000","0.00000000"],["60212.29000000","0.00000000"],["60115.09000000","0.00000000"],["60019.20000000","0.00000000"]],"a":[["63386.21000000","0.01577000"],["63387.22000000","0.00000000"],["63449.45000000","0.00000000"],["63551.80000000","0.00000000"],["63653.12000000","0.00000000"],["66635.76000000","0.00000000"],["66701.44000000","0.00000000"],["66809.25000000","0.00000000"],["66915.95000000","0.00000000"]]}}
{"stream":"ethusd@depth","data":{"e":"depthUpdate","E":1785649800904,"s":"ETHUSD","U":3656117319,"u":3656117321,"b":[["1873.53000000","0.00000000"]],"a":[["1874.10000000","0.00000000"],["1875.87000000","8.94500000"],["1875.89000000","0.00000000"]]}}
{"stream":"btcusd@depth","data":{"e":"depthUpdate","E":1785649801904,"s":"BTCUSD","U":4527243770,"u":4527243771,"b":[["63299.86000000","0.15797000"]],"a":[["63448.66000000","0.15760000"]]}}
{"stream":"ethusd@depth","data":{"e":"depthUpdate","E":1785649801904,"s":"ETHUSD","U":3656117322,"u":3656117348,"b":[["1873.94000000","1.10480000"],["1873.76000000","0.73460000"],["1873.75000000","0.00000000"],["1873.71000000","0.00000000"],["1873.60000000","0.00000000"],["1873.54000000","0.53370000"],["1873.37000000","0.00000000"],["1873.15000000","1.10200000"],["1872.96000000","0.00000000"],["1872.76000000","2.67000000"],["1872.63000000","0.00000000"],["1872.62000000","0.00000000"],["1871.20000000","11.20790000"],["1871.19000000","0.00000000"],["1871.18000000","0.00000000"],["1871.16000000","0.00000000"]],"a":[["1874.00000000","0.73360000"],["1874.01000000","0.00000000"],["1874.07000000","0.00000000"],["1874.13000000","0.00000000"],["1874.17000000","0.53350000"],["1874.31000000","0.02970000"],["1874.32000000","0.00000000"],["1874.51000000","1.09870000"],["1874.52000000","1.10390000"],["1874.73000000","1.56050000"]]}}
{"stream":"btcusd@depth","data":{"e":"depthUpdate","E":1785649802904,"s":"BTCUSD","U":4527243772,"u":4527243773,"b":[["63197.73000000","0.79116000"]],"a":[["63551.18000000","0.78676000"]]}}
{"stream":"ethusd@depth","data":{"e":"depthUpdate","E":1785649802904,"s":"ETHUSD","U":3656117349,"u":3656117354,"b":[["1873.94000000","0.00000000"],["1873.88000000","1.13810000"]],"a":[["1874.41000000","2.19650000"],["1874.45000000","1.12460000"],["1874.51000000","0.00000000"],["1874.83000000","0.00000000"]]}}
{"stream":"ethusd@depth","data":{"e":"depthUpdate","E":1785649803904,"s":"ETHUSD","U":3656117355,"u":3656117359,"b":[["1873.88000000","0.00000000"],["1873.76000000","1.84180000"],["1871.21000000","11.20780000"],["1871.20000000","0.00000000"]],"a":[["1874.34000000","1.09870000"],["1874.45000000","0.00000000"]]}}
{"stream":"btcusd@depth","data":{"e":"depthUpdate","E":1785649804904,"s":"BTCUSD","U":4527243774,"u":4527243775,"b":[["63096.98000000","0.79243000"]],"a":[["63652.66000000","0.78551000"]]}}
{"stream":"ethusd@depth","data":{"e":"depthUpdate","E":1785649805904,"s":"ETHUSD","U":3656117360,"u":3656117384,"b":[["1873.86000000","0.00000000"],["1873.85000000","0.00000000"],["1873.79000000","0.00000000"],["1873.78000000","0.00000000"],["1873.76000000","0.73460000"],["1873.44000000","0.13840000"],["1873.38000000","0.00000000"],["1871.22000000","11.20780000"],["1871.21000000","0.00000000"]],"a":[["1874.05000000","0.00000000"],["1874.10000000","0.13870000"],["1874.34000000","0.00000000"],["1874.35000000","0.00000000"],["1874.36000000","0.00000000"],["1874.40000000","1.47200000"],["1874.42000000","1.31050000"],["1874.43000000","1.56050000"]]}}
{"stream":"ethusd@depth","data":{"e":"depthUpdate","E":1785649806904,"s":"ETHUSD","U":3656117385,"u":3656117407,"b":[["1873.84000000","1.15570000"],["1873.78000000","0.00000000"],["1873.77000000","0.00000000"]],"a":[["1874.34000000","0.00000000"],["1874.35000000","0.00000000"],["1874.41000000","2.19650000"],["1874.42000000","1.30300000"]]}}
{"stream":"ethusd@depth","data":{"e":"depthUpdate","E":1785649807904,"s":"ETHUSD","U":3656117408,"u":3656117448,"b":[["1873.87000000","0.00000000"],["1873.86000000","0.00000000"],["1873.85000000","1.18150000"],["1873.84000000","0.00000000"],["1873.80000000","0.02960000"],["1873.78000000","0.00000000"],["1873.77000000","0.00000000"],["1873.50000000","0.13830000"],["1873.44000000","0.00000000"],["1873.18000000","1.47330000"],["1873.08000000","0.00000000"],["1871.23000000","11.20770000"],["1871.22000000","0.00000000"]],"a":[["1874.10000000","0.00000000"],["1874.15000000","0.13860000"],["1874.34000000","0.00000000"],["1874.36000000","0.00000000"],["1874.37000000","0.00000000"],["1874.40000000","0.00000000"],["1874.42000000","0.14840000"],["1874.43000000","2.00500000"],["1874.44000000","0.00000000"],["1874.46000000","1.47180000"]]}}
{"stream":"btcusd@depth","data":{"e":"depthUpdate","E":1785649808904,"s":"BTCUSD","U":4527243776,"u":4527243780,"b":[["63369.31000000","0.04733000"],["63366.47000000","0.00000000"]],"a":[["63550.75000000","0.00100000"],["63570.88000000","0.00129000"]]}}
{"stream":"ethusd@depth","data":{"e":"depthUpdate","E":1785649808904,"s":"ETHUSD","U":3656117449,"u":3656117454,"b":[["1873.85000000","0.00000000"],["1873.80000000","1.21350000"],["1872.50000000","1.78010000"],["1872.12000000","0.00000000"]],"a":[["1874.37000000","1.10590000"],["1874.43000000","1.56050000"]]}}
{"stream":"ethusd@depth","data":{"e":"depthUpdate","E":1785649809904,"s":"ETHUSD","U":3656117455,"u":3656117491,"b":[["1873.88000000","1.09240000"],["1873.87000000","0.00000000"],["1873.86000000","0.00000000"],["1873.85000000","0.00000000"],["1873.83000000","0.92010000"],["1873.80000000","0.02960000"],["1873.79000000","0.00000000"],["1873.76000000","0.00000000"],["1872.90000000","0.10000000"]],"a":[["1874.36000000","0.00000000"],["1874.37000000","0.00000000"],["1874.43000000","1.56050000"],["1874.44000000","0.00000000"],["1874.45000000","1.13970000"]]}}
{"stream":"ethusd@depth","data":{"e":"depthUpdate","E":1785649810905,"s":"ETHUSD","U":3656117492,"u":3656117523,"b":[["1873.88000000","0.00000000"],["1873.87000000","1.18020000"],["1873.84000000","0.00000000"],["1873.81000000","0.00000000"],["1873.77000000","0.00000000"]],"a":[["1874.34000000","0.00000000"],["1874.38000000","0.00000000"],["1874.42000000","0.14840000"],["1874.44000000","0.46340000"],["1874.45000000","0.00000000"]]}}
{"stream":"btcusd@depth","data":{"e":"depthUpdate","E":1785649811905,"s":"BTCUSD","U":4527243781,"u":4527243782,"b":[["63348.33000000","0.06310000"],["63347.91000000","0.00000000"]],"a":[]}}
{"stream":"ethusd@depth","data":{"e":"depthUpdate","E":1785649812905,"s":"ETHUSD","U":3656117524,"u":3656117531,"b":[["1873.88000000","1.11720000"],["1873.87000000","0.00000000"],["1873.81000000","0.00000000"]],"a":[["1874.38000000","0.00000000"],["1874.44000000","0.00000000"],["1874.45000000","1.08510000"]]}}
{"stream":"ethusd@depth","data":{"e":"depthUpdate","E":1785649813905,"s":"ETHUSD","U":3656117532,"u":3656117538,"b":[["1873.89000000","1.01980000"],["1873.83000000","0.00000000"],["1873.35000000","1.52970000"],["1873.15000000","0.00000000"],["1871.24000000","11.20760000"],["1871.23000000","0.00000000"]],"a":[["1874.17000000","0.00000000"],["1874.33000000","0.53350000"]]}}
{"stream":"ethusd@depth","data":{"e":"depthUpdate","E":1785649814905,"s":"ETHUSD","U":3656117539,"u":3656117550,"b":[["1873.89000000","0.00000000"],["1873.88000000","0.00000000"],["1873.86000000","1.19280000"],["1873.81000000","1.05140000"],["1873.80000000","0.02960000"]],"a":[["1874.19000000","0.53350000"],["1874.33000000","0.00000000"],["1874.37000000","0.00000000"],["1874.43000000","2.71500000"],["1874.45000000","0.00000000"]]}}
{"stream":"ethusd@depth","data":{"e":"depthUpdate","E":1785649818905,"s":"ETHUSD","U":3656117551,"u":3656117552,"b":[["1873.87000000","1.06720000"],["1873.81000000","0.00000000"]],"a":[]}}
{"stream":"ethusd@depth","data":{"e":"depthUpdate","E":1785649819905,"s":"ETHUSD","U":3656117553,"u":3656117554,"b":[["1871.25000000","11.20750000"],["1871.24000000","0.00000000"]],"a":[["1875.87000000","0.00000000"],["1876.12000000","8.94670000"]]}}
{"stream":"ethusd@depth","data":{"e":"depthUpdate","E":1785649820905,"s":"ETHUSD","U":3656117555,"u":3656117556,"b":[["1873.87000000","0.00000000"],["1873.82000000","1.06720000"]],"a":[]}}
{"stream":"btcusd@depth","data":{"e":"depthUpdate","E":1785649821905,"s":"BTCUSD","U":4527243783,"u":4527243785,"b":[],"a":[["63376.32000000","0.00000000"],["63381.61000000","0.00300000"],["63578.10000000","0.00050000"],["63580.99000000","0.00055000"]]}}
{"stream":"ethusd@depth","data":{"e":"depthUpdate","E":1785649823905,"s":"ETHUSD","U":3656117557,"u":3656117558,"b":[["1870.42000000","0.00000000"]],"a":[["1876.08000000","8.94640000"],["1876.12000000","0.00000000"]]}}
{"stream":"ethusd@depth","data":{"e":"depthUpdate","E":1785649824905,"s":"ETHUSD","U":3656117559,"u":3656117559,"b":[["1873.87000000","0.99470000"]],"a":[]}}
{"stream":"ethusd@depth","data":{"e":"depthUpdate","E":1785649828906,"s":"ETHUSD","U":3656117560,"u":3656117566,"b":[["1870.61000000","0.25300000"]],"a":[["1874.42000000","0.00000000"],["1874.43000000","1.15450000"],["1874.71000000","0.00000000"],["1874.73000000","0.00000000"],["1875.16000000","1.56050000"],["1875.72000000","1.56050000"]]}}
{"stream":"btcusd@depth","data":{"e":"depthUpdate","E":1785649829906,"s":"BTCUSD","U":4527243786,"u":4527243786,"b":[],"a":[["63376.32000000","0.00300000"],["63381.61000000","0.00000000"]]}}
{"stream":"ethusd@depth","data":{"e":"depthUpdate","E":1785649829906,"s":"ETHUSD","U":3656117567,"u":3656117570,"b":[],"a":[["1874.55000000","1.56050000"],["1874.73000000","0.14840000"],["1874.83000000","1.56050000"],["1875.72000000","0.00000000"]]}}
{"stream":"ethusd@depth","data":{"e":"depthUpdate","E":1785649830906,"s":"ETHUSD","U":3656117571,"u":3656117572,"b":[],"a":[["1874.28000000","1.56050000"],["1875.16000000","0.00000000"]]}}
{"stream":"btcusd@depth","data":{"e":"depthUpdate","E":1785649832906,"s":"BTCUSD","U":4527243787,"u":4527243788,"b":[["63369.31000000","0.00000000"],["63365.83000000","0.04733000"]],"a":[]}}
{"stream":"btcusd@depth","data":{"e":"depthUpdate","E":1785649833906,"s":"BTCUSD","U":4527243789,"u":4527243790,"b":[["63369.31000000","0.03155000"],["63369.24000000","0.00000000"]],"a":[]}}
{"stream":"ethusd@depth","data":{"e":"depthUpdate","E":1785649833906,"s":"ETHUSD","U":3656117573,"u":3656117580,"b":[["1873.86000000","0.00000000"],["1873.83000000","1.14370000"],["1873.76000000","0.00000000"]],"a":[["1874.34000000","0.00000000"],["1874.40000000","1.14210000"],["1874.43000000","0.00000000"]]}}
{"stream":"ethusd@depth","data":{"e":"depthUpdate","E":1785649834906,"s":"ETHUSD","U":3656117581,"u":3656117584,"b":[["1873.83000000","0.00000000"],["1873.77000000","1.17170000"]],"a":[["1874.34000000","0.40630000"],["1874.40000000","0.00000000"]]}}
{"stream":"ethusd@depth","data":{"e":"depthUpdate","E":1785649835906,"s":"ETHUSD","U":3656117585,"u":3656117586,"b":[["1873.50000000","0.00000000"],["1873.45000000","0.13860000"]],"a":[["1874.11000000","0.13870000"],["1874.15000000","0.00000000"]]}}
{"stream":"ethusd@depth","data":{"e":"depthUpdate","E":1785649839906,"s":"ETHUSD","U":3656117587,"u":3656117590,"b":[["1873.86000000","1.17510000"],["1873.77000000","0.00000000"]],"a":[["1874.34000000","0.00000000"],["1874.43000000","1.17280000"]]}}
{"stream":"ethusd@depth","data":{"e":"depthUpdate","E":1785649840906,"s":"ETHUSD","U":3656117591,"u":3656117638,"b":[["1874.06000000","0.00000000"],["1874.05000000","1.12850000"],["1874.01000000","0.96920000"],["1873.95000000","0.00000000"],["1873.89000000","0.02960000"],["1873.87000000","0.99470000"],["1873.86000000","0.00000000"],["1873.82000000","0.00000000"],["1873.80000000","0.00000000"],["1873.59000000","1.60060000"],["1873.35000000","0.00000000"],["1872.96000000","2.13410000"],["1872.50000000","0.00000000"],["1866.65000000","7.09030000"],["1865.26000000","0.00000000"]],"a":[["1874.00000000","0.00000000"],["1874.09000000","0.00000000"],["1874.11000000","1.10950000"],["1874.17000000","0.00000000"],["1874.19000000","0.00000000"],["1874.24000000","0.00000000"],["1874.31000000","0.00000000"],["1874.35000000","0.53350000"],["1874.40000000","0.02960000"],["1874.41000000","3.66840000"],["1874.43000000","0.00000000"],["1874.46000000","0.00000000"],["1874.52000000","0.00000000"],["1874.53000000","0.00000000"],["1874.62000000","1.15650000"],["1874.71000000","1.60060000"],["1881.03000000","0.00000000"],["1881.54000000","0.00000000"],["1881.55000000","0.00000000"],["1881.58000000","0.00000000"],["1881.63000000","7.04260000"],["1881.69000000","7.76540000"],["1881.74000000","7.66750000"],["1881.89000000","8.16330000"],["1883.22000000","0.00420000"],["1883.27000000","0.00000000"]]}}
{"stream":"ethusd@depth","data":{"e":"depthUpdate","E":1785649841907,"s":"ETHUSD","U":3656117639,"u":3656117642,"b":[["1874.01000000","0.00000000"],["1873.96000000","0.97340000"],["1873.59000000","0.00000000"],["1873.39000000","1.46010000"]],"a":[]}}
{"stream":"btcusd@depth","data":{"e":"depthUpdate","E":1785649842907,"s":"BTCUSD","U":4527243791,"u":4527243792,"b":[["63369.01000000","0.04733000"],["63365.83000000","0.00000000"]],"a":[]}}
{"stream":"ethusd@depth","data":{"e":"depthUpdate","E":1785649842907,"s":"ETHUSD","U":3656117643,"u":3656117643,"b":[],"a":[["1874.11000000","0.97080000"],["1874.12000000","0.13870000"]]}}
{"stream":"ethusd@depth","data":{"e":"depthUpdate","E":1785649844907,"s":"ETHUSD","U":3656117644,"u":3656117654,"b":[["1873.96000000","0.00000000"],["1873.91000000","1.05450000"],["1873.67000000","0.13870000"],["1873.45000000","0.00000000"],["1873.37000000","1.47320000"],["1873.18000000","0.00000000"],["1872.32000000","9.18640000"],["1872.03000000","0.00000000"],["1871.40000000","11.20670000"],["1871.39000000","0.00000000"],["1871.26000000","0.00000000"],["1871.25000000","0.00000000"]],"a":[["1874.12000000","0.00000000"],["1874.34000000","0.13870000"],["1874.41000000","2.19650000"],["1874.64000000","1.47220000"],["1875.40000000","0.00000000"],["1875.69000000","9.16990000"]]}}
{"stream":"ethusd@depth","data":{"e":"depthUpdate","E":1785649845907,"s":"ETHUSD","U":3656117655,"u":3656117655,"b":[],"a":[["1881.03000000","0.00160000"]]}}
{"stream":"ethusd@depth","data":{"e":"depthUpdate","E":1785649847907,"s":"ETHUSD","U":3656117656,"u":3656117661,"b":[["1873.91000000","0.00000000"],["1873.85000000","1.06720000"],["1872.96000000","0.00000000"],["1872.58000000","2.13440000"]],"a":[["1874.50000000","1.60080000"],["1874.71000000","0.00000000"]]}}
{"stream":"btcusd@depth","data":{"e":"depthUpdate","E":1785649851907,"s":"BTCUSD","U":4527243793,"u":4527243794,"b":[["63335.78000000","0.00000000"],["63333.58000000","0.07888000"]],"a":[]}}
{"stream":"ethusd@depth","data":{"e":"depthUpdate","E":1785649853907,"s":"ETHUSD","U":3656117662,"u":3656117663,"b":[],"a":[["1874.22000000","0.53350000"],["1874.35000000","0.00000000"]]}}
{"stream":"btcusd@depth","data":{"e":"depthUpdate","E":1785649855907,"s":"BTCUSD","U":4527243795,"u":4527243795,"b":[],"a":[["63376.32000000","0.00000000"],["63381.61000000","0.00300000"]]}}
{"stream":"btcusd@depth","data":{"e":"depthUpdate","E":1785649856908,"s":"BTCUSD","U":4527243796,"u":4527243797,"b":[["62225.03000000","0.00657000"],["62208.82000000","0.00000000"]],"a":[]}}
{"stream":"ethusd@depth","data":{"e":"depthUpdate","E":1785649856908,"s":"ETHUSD","U":3656117664,"u":3656117664,"b":[["1832.09000000","0.00000000"]],"a":[]}}
{"stream":"ethusd@depth","data":{"e":"depthUpdate","E":1785649857908,"s":"ETHUSD","U":3656117665,"u":3656117666,"b":[["1873.87000000","0.00000000"],["1832.44000000","0.22360000"]],"a":[]}}
{"stream":"ethusd@depth","data":{"e":"depthUpdate","E":1785649859908,"s":"ETHUSD","U":3656117667,"u":3656117667,"b":[],"a":[["1874.38000000","0.05550000"]]}}
{"stream":"ethusd@depth","data":{"e":"depthUpdate","E":1785649860908,"s":"ETHUSD","U":3656117668,"u":3656117681,"b":[["1874.05000000","0.00000000"],["1873.88000000","1.12420000"],["1873.67000000","0.00000000"],["1873.58000000","0.13870000"],["1873.37000000","0.00000000"],["1873.28000000","1.47330000"]],"a":[["1874.25000000","0.13870000"],["1874.28000000","1.56050000"],["1874.34000000","0.00000000"],["1874.38000000","0.05630000"],["1874.45000000","0.00000000"],["1874.49000000","1.14200000"],["1874.55000000","3.03280000"],["1874.62000000","0.00000000"],["1874.64000000","0.00000000"]]}}
{"stream":"ethusd@depth","data":{"e":"depthUpdate","E":1785649861908,"s":"ETHUSD","U":3656117682,"u":3656117712,"b":[["1874.05000000","1.09170000"],["1874.01000000","1.06710000"],["1873.96000000","0.00000000"],["1873.90000000","0.00000000"],["1873.88000000","0.00000000"],["1873.85000000","0.00000000"],["1873.62000000","1.56050000"],["1873.07000000","1.56050000"],["1872.87000000","0.00000000"],["1872.81000000","0.00000000"],["1871.47000000","11.20630000"],["1871.46000000","0.00000000"],["1871.44000000","0.00000000"],["1871.41000000","0.00000000"],["1871.40000000","0.00000000"]],"a":[["1874.22000000","0.00000000"],["1874.28000000","0.00000000"],["1874.38000000","0.00000000"],["1874.40000000","0.08840000"],["1874.41000000","0.00000000"],["1874.45000000","0.53340000"],["1874.49000000","0.00000000"],["1874.58000000","1.18860000"],["1874.72000000","1.92620000"],["1874.75000000","0.00000000"],["1874.93000000","1.56050000"],["1874.94000000","2.66700000"],["1875.13000000","2.13450000"],["1875.40000000","0.23380000"],["1876.08000000","0.00000000"],["1876.33000000","8.94820000"]]}}
{"stream":"ethusd@depth","data":{"e":"depthUpdate","E":1785649862908,"s":"ETHUSD","U":3656117713,"u":3656117717,"b":[["1873.08000000","0.10000000"],["1872.95000000","2.67000000"],["1872.90000000","0.00000000"],["1872.76000000","0.00000000"]],"a":[["1874.31000000","0.53350000"],["1874.45000000","0.00000000"]]}}
{"stream":"ethusd@depth","data":{"e":"depthUpdate","E":1785649864908,"s":"ETHUSD","U":3656117718,"u":3656117757,"b":[["1874.05000000","0.00000000"],["1874.01000000","0.00000000"],["1873.95000000","0.00000000"],["1873.89000000","0.02960000"],["1873.81000000","1.16100000"],["1873.80000000","1.03060000"],["1873.75000000","0.00000000"],["1873.72000000","1.06730000"],["1873.58000000","0.00000000"],["1873.54000000","0.00000000"],["1873.53000000","0.13870000"],["1873.39000000","0.53370000"],["1873.18000000","1.60090000"]],"a":[["1874.10000000","0.53350000"],["1874.17000000","0.00000000"],["1874.20000000","0.13870000"],["1874.21000000","0.00000000"],["1874.23000000","0.05520000"],["1874.25000000","0.00000000"],["1874.30000000","1.60090000"],["1874.31000000","0.00000000"],["1874.32000000","0.00000000"],["1874.36000000","0.97250000"],["1874.38000000","1.15190000"],["1874.40000000","0.02960000"],["1874.50000000","0.00000000"],["1874.58000000","0.00000000"],["1876.23000000","8.94740000"],["1876.24000000","5.32980000"],["1876.25000000","0.00000000"],["1876.30000000","0.00000000"],["1876.33000000","0.00000000"]]}}
{"stream":"ethusd@depth","data":{"e":"depthUpdate","E":1785649865908,"s":"ETHUSD","U":3656117758,"u":3656117765,"b":[["1873.53000000","0.00000000"],["1873.42000000","0.13870000"],["1873.28000000","0.00000000"],["1873.13000000","0.10000000"],["1873.12000000","1.47340000"],["1873.08000000","0.00000000"],["1872.32000000","0.00000000"],["1872.08000000","9.18760000"]],"a":[["1874.09000000","0.13870000"],["1874.20000000","0.00000000"],["1874.39000000","1.47240000"],["1874.55000000","1.56050000"],["1875.44000000","9.17120000"],["1875.69000000","0.00000000"],["1876.21000000","8.94730000"],["1876.23000000","0.00000000"]]}}
{"stream":"btcusd@depth","data":{"e":"depthUpdate","E":1785649866908,"s":"BTCUSD","U":4527243798,"u":4527243799,"b":[["63368.59000000","0.02986000"]],"a":[["63382.52000000","0.02899000"]]}}
{"stream":"ethusd@depth","data":{"e":"depthUpdate","E":1785649866908,"s":"ETHUSD","U":3656117766,"u":3656117766,"b":[],"a":[["1876.17000000","8.94700000"],["1876.21000000","0.00000000"]]}}
{"stream":"ethusd@depth","data":{"e":"depthUpdate","E":1785649867908,"s":"ETHUSD","U":3656117767,"u":3656117768,"b":[["1873.77000000","1.06720000"],["1873.72000000","0.00000000"]],"a":[]}}
{"stream":"ethusd@depth","data":{"e":"depthUpdate","E":1785649868908,"s":"ETHUSD","U":3656117769,"u":3656117772,"b":[["1873.48000000","0.13840000"],["1873.42000000","0.00000000"]],"a":[["1874.09000000","0.00000000"],["1874.14000000","0.13870000"],["1874.39000000","0.00000000"],["1874.44000000","1.47200000"],["1876.14000000","8.94680000"],["1876.17000000","0.00000000"]]}}
{"stream":"btcusd@depth","data":{"e":"depthUpdate","E":1785649870908,"s":"BTCUSD","U":4527243800,"u":4527243879,"b":[["63376.28000000","0.03901000"],["63376.27000000","0.03501000"],["63375.59000000","0.00079000"],["63372.84000000","0.00000000"],["63372.83000000","0.00000000"],["63369.31000000","0.00000000"],["63369.30000000","0.00000000"],["63369.23000000","0.00000000"],["63369.01000000","0.00000000"],["63367.12000000","0.00000000"],["63366.98000000","0.03150000"],["63366.76000000","0.00000000"],["63366.26000000","0.00000000"],["63365.97000000","0.00000000"],["63365.58000000","0.00410000"],["63365.52000000","0.00000000"],["63364.44000000","0.00000000"],["63364.12000000","0.00000000"],["63363.84000000","0.00000000"],["63362.22000000","0.00000000"],["63361.77000000","0.00000000"],["63359.42000000","0.00000000"],["63353.70000000","0.04355000"],["63349.28000000","0.00000000"],["63341.63000000","0.07900000"],["63337.46000000","0.00000000"],["63333.08000000","0.20655000"],["63330.88000000","0.20561000"],["63306.23000000","0.33130000"],["63306.01000000","0.00000000"],["63305.51000000","0.00000000"],["63305.23000000","0.00000000"],["63305.22000000","0.15654000"],["63304.77000000","0.00000000"],["63303.69000000","0.00000000"],["63303.37000000","0.00000000"],["63155.72000000","0.00000000"],["63146.99000000","0.00000000"],["63104.93000000","0.00616000"],["63097.57000000","0.00000000"]],"a":[["63376.33000000","0.00000000"],["63381.60000000","0.00000000"],["63381.61000000","0.00000000"],["63381.62000000","0.00000000"],["63382.09000000","0.00000000"],["63382.23000000","0.00000000"],["63382.50000000","0.01579000"],["63382.51000000","0.00300000"],["63382.68000000","0.00000000"],["63383.96000000","0.00000000"],["63386.03000000","0.00000000"],["63386.20000000","0.36224000"],["63386.21000000","0.00000000"],["63387.78000000","0.00410000"],["63388.32000000","0.00000000"],["63389.92000000","0.00000000"],["63389.93000000","0.00000000"],["63391.43000000","0.00000000"],["63391.53000000","0.00000000"],["63391.88000000","0.00000000"],["63394.10000000","0.00000000"],["63395.31000000","0.03418000"],["63396.04000000","0.00079000"],["63396.17000000","0.00000000"],["63397.92000000","0.04353000"],["63424.90000000","0.00000000"],["63431.66000000","0.27114000"],["63441.06000000","0.00000000"],["63442.24000000","0.00000000"],["63444.94000000","0.00000000"],["63548.58000000","0.00000000"],["63551.08000000","0.26221000"],["63559.65000000","0.26356000"]]}}
{"stream":"ethusd@depth","data":{"e":"depthUpdate","E":1785649870909,"s":"ETHUSD","U":3656117773,"u":3656117806,"b":[["1874.04000000","1.09550000"],["1874.01000000","1.06710000"],["1873.96000000","0.00000000"],["1873.89000000","0.02960000"],["1873.83000000","0.00000000"],["1873.81000000","0.00000000"],["1873.77000000","0.00000000"],["1873.58000000","0.13870000"],["1873.54000000","0.53370000"],["1873.48000000","0.00000000"],["1873.39000000","0.00000000"],["1873.38000000","1.60070000"],["1873.28000000","1.47250000"],["1873.18000000","0.00000000"],["1873.13000000","0.00000000"],["1873.12000000","0.00000000"],["1873.08000000","0.10000000"]],"a":[["1874.10000000","0.00000000"],["1874.14000000","0.00000000"],["1874.23000000","0.00000000"],["1874.24000000","0.13870000"],["1874.25000000","0.00000000"],["1874.30000000","0.00000000"],["1874.38000000","0.00000000"],["1874.39000000","0.00000000"],["1874.41000000","0.53350000"],["1874.43000000","0.05810000"],["1874.44000000","0.00000000"],["1874.52000000","1.60080000"],["1874.53000000","0.00000000"],["1874.54000000","1.47230000"],["1874.61000000","1.09290000"],["1875.44000000","0.00000000"],["1875.59000000","9.17040000"]]}}
{"stream":"btcusd@depth","data":{"e":"depthUpdate","E":1785649871909,"s":"BTCUSD","U":4527243880,"u":4527243907,"b":[["63370.02000000","0.01578000"],["63367.39000000","0.03150000"],["63367.20000000","0.00000000"],["63367.14000000","0.00000000"],["63367.08000000","0.00000000"],["63367.06000000","0.00000000"],["63366.98000000","0.00410000"],["63365.58000000","0.00000000"],["63356.83000000","0.04354000"],["63353.70000000","0.00000000"],["63306.65000000","0.33130000"],["63306.45000000","0.00000000"],["63306.39000000","0.00000000"],["63306.34000000","0.00000000"],["63306.33000000","0.00000000"],["63306.31000000","0.00000000"],["63306.23000000","0.00000000"]],"a":[["63382.48000000","0.00000000"],["63382.49000000","0.00000000"],["63382.50000000","0.00300000"],["63382.51000000","0.00000000"],["63387.78000000","0.00000000"],["63389.17000000","0.00410000"],["63396.33000000","0.01577000"]]}}
{"stream":"ethusd@depth","data":{"e":"depthUpdate","E":1785649871909,"s":"ETHUSD","U":3656117807,"u":3656117854,"b":[["1873.89000000","0.00000000"],["1873.69000000","0.53370000"],["1873.58000000","1.73930000"],["1873.54000000","0.00000000"],["1873.38000000","0.00000000"],["1873.29000000","0.10000000"],["1873.14000000","0.00000000"],["1873.12000000","2.66900000"],["1873.08000000","0.00000000"],["1872.96000000","2.13410000"],["1872.95000000","0.00000000"],["1872.58000000","0.00000000"],["1871.61000000","11.20550000"],["1871.60000000","0.00000000"],["1871.51000000","0.00000000"],["1871.49000000","0.00000000"],["1871.47000000","0.00000000"],["1870.93000000","0.25480000"],["1870.61000000","0.00000000"],["1866.86000000","7.10390000"],["1865.32000000","0.00000000"]],"a":[["1874.11000000","0.00000000"],["1874.18000000","0.00000000"],["1874.25000000","1.06700000"],["1874.40000000","0.00000000"],["1874.41000000","0.00000000"],["1874.52000000","0.00000000"],["1874.55000000","0.00000000"],["1874.59000000","0.53340000"],["1874.72000000","3.52680000"],["1874.94000000","0.00000000"],["1875.13000000","0.00000000"],["1875.20000000","2.66600000"],["1875.25000000","1.56050000"],["1876.14000000","0.00000000"],["1876.39000000","8.94860000"],["1881.63000000","0.00000000"],["1881.65000000","0.00000000"],["1881.69000000","0.00000000"],["1881.74000000","0.00000000"],["1881.79000000","0.00000000"],["1881.84000000","8.03150000"],["1882.03000000","7.99920000"],["1882.08000000","8.01170000"],["1883.11000000","8.95790000"],["1883.12000000","0.00000000"],["1883.16000000","9.06890000"],["1883.17000000","0.00000000"]]}}
{"stream":"btcusd@depth","data":{"e":"depthUpdate","E":1785649872909,"s":"BTCUSD","U":4527243908,"u":4527243921,"b":[["63368.81000000","0.03150000"],["63368.51000000","0.00000000"],["63368.41000000","0.00000000"],["63368.30000000","0.00000000"],["63367.39000000","0.00000000"],["63308.06000000","0.33130000"],["63307.76000000","0.00000000"],["63307.66000000","0.00000000"],["63307.55000000","0.00000000"],["63306.65000000","0.00000000"]],"a":[["63382.48000000","0.00000000"],["63382.50000000","0.00000000"],["63382.51000000","0.00300000"],["63392.43000000","0.00000000"]]}}
{"stream":"ethusd@depth","data":{"e":"depthUpdate","E":1785649872909,"s":"ETHUSD","U":3656117855,"u":3656117861,"b":[["1874.10000000","1.06700000"],["1874.09000000","0.02980000"],["1874.01000000","0.00000000"],["1871.62000000","11.20540000"],["1871.61000000","0.00000000"]],"a":[["1874.24000000","0.00000000"],["1874.25000000","1.20570000"],["1874.44000000","0.02940000"],["1883.21000000","8.96100000"]]}}
{"stream":"btcusd@depth","data":{"e":"depthUpdate","E":1785649873909,"s":"BTCUSD","U":4527243922,"u":4527243942,"b":[["63379.05000000","0.03314000"],["63376.27000000","0.00000000"],["63369.52000000","0.03150000"],["63369.51000000","0.00000000"],["63369.47000000","0.00000000"],["63368.96000000","0.00000000"],["63368.92000000","0.00000000"],["63368.89000000","0.00000000"],["63368.81000000","0.00000000"],["63368.37000000","0.00410000"],["63366.98000000","0.00000000"],["63322.03000000","0.27161000"],["63315.55000000","0.00000000"],["63308.77000000","0.33130000"],["63308.76000000","0.00000000"],["63308.72000000","0.00000000"],["63308.22000000","0.00000000"],["63308.17000000","0.00000000"],["63308.14000000","0.00000000"],["63308.06000000","0.00000000"]],"a":[["63389.17000000","0.00000000"],["63390.56000000","0.00408000"],["63395.31000000","0.00000000"],["63397.92000000","0.00000000"],["63398.09000000","0.03445000"],["63399.72000000","0.00420000"],["63400.01000000","0.04353000"]]}}
{"stream":"btcusd@depth","data":{"e":"depthUpdate","E":1785649874909,"s":"BTCUSD","U":4527243943,"u":4527243946,"b":[["63369.73000000","0.03150000"],["63369.57000000","0.00000000"],["63369.52000000","0.00000000"],["63308.98000000","0.33130000"],["63308.82000000","0.00000000"],["63308.77000000","0.00000000"]],"a":[]}}
{"stream":"ethusd@depth","data":{"e":"depthUpdate","E":1785649874909,"s":"ETHUSD","U":3656117862,"u":3656117863,"b":[],"a":[["1874.45000000","0.53340000"],["1874.59000000","0.00000000"]]}}
{"stream":"btcusd@depth","data":{"e":"depthUpdate","E":1785649876909,"s":"BTCUSD","U":4527243947,"u":4527243948,"b":[["63370.04000000","0.03150000"],["63369.73000000","0.00000000"],["63309.29000000","0.33130000"],["63308.98000000","0.00000000"]],"a":[]}}
{"stream":"btcusd@depth","data":{"e":"depthUpdate","E":1785649877909,"s":"BTCUSD","U":4527243949,"u":4527243950,"b":[["63371.55000000","0.03150000"],["63370.04000000","0.00000000"],["63310.80000000","0.33130000"],["63309.29000000","0.00000000"]],"a":[]}}
{"stream":"btcusd@depth","data":{"e":"depthUpdate","E":1785649878909,"s":"BTCUSD","U":4527243951,"u":4527243952,"b":[["63379.06000000","0.01872000"],["63376.28000000","0.02343000"]],"a":[]}}
{"stream":"btcusd@depth","data":{"e":"depthUpdate","E":1785649879909,"s":"BTCUSD","U":4527243953,"u":4527243954,"b":[["63326.81000000","0.06970000"],["63316.35000000","0.00000000"]],"a":[]}}
{"stream":"ethusd@depth","data":{"e":"depthUpdate","E":1785649880909,"s":"ETHUSD","U":3656117864,"u":3656117881,"b":[["1874.10000000","1.15780000"],["1874.04000000","0.00000000"],["1874.03000000","1.06710000"],["1873.68000000","0.13870000"],["1873.58000000","1.60060000"],["1873.38000000","1.47320000"],["1873.30000000","0.00000000"],["1873.29000000","0.00000000"],["1873.28000000","0.00000000"],["1873.14000000","0.00000000"],["1873.13000000","0.10000000"],["1872.34000000","9.18620000"],["1872.08000000","0.00000000"]],"a":[["1874.25000000","1.06700000"],["1874.35000000","0.13870000"],["1874.43000000","0.00000000"],["1874.54000000","0.00000000"],["1874.61000000","0.00000000"],["1874.65000000","1.47160000"],["1874.67000000","0.52610000"],["1876.35000000","8.94830000"],["1876.39000000","0.00000000"]]}}
{"stream":"btcusd@depth","data":{"e":"depthUpdate","E":1785649881909,"s":"BTCUSD","U":4527243955,"u":4527243984,"b":[["63375.59000000","0.00000000"],["63375.02000000","0.01577000"],["63373.22000000","0.03150000"],["63373.11000000","0.00000000"],["63371.56000000","0.00000000"],["63371.55000000","0.00000000"],["63370.02000000","0.00000000"],["63335.38000000","0.20311000"],["63312.47000000","0.33130000"],["63312.35000000","0.00000000"],["63310.81000000","0.00000000"],["63310.80000000","0.00000000"],["63164.43000000","0.00000000"]],"a":[["63382.51000000","0.00000000"],["63386.20000000","0.00000000"],["63389.57000000","0.00000000"],["63390.35000000","0.00000000"],["63390.55000000","0.00300000"],["63392.67000000","0.36224000"],["63392.68000000","0.00000000"],["63396.04000000","0.00000000"],["63396.15000000","0.00626000"],["63401.25000000","0.11800000"],["63412.66000000","0.04696000"],["63419.55000000","0.00000000"],["63448.61000000","0.00000000"],["63449.46000000","0.00000000"],["63450.36000000","0.20364000"],["63557.88000000","0.15654000"],["63559.65000000","0.00000000"],["63560.57000000","0.26101000"]]}}
{"stream":"ethusd@depth","data":{"e":"depthUpdate","E":1785649881909,"s":"ETHUSD","U":3656117882,"u":3656117897,"b":[["1873.16000000","0.00000000"],["1873.15000000","0.00000000"],["1873.14000000","0.00000000"],["1873.13000000","0.10000000"]],"a":[]}}
{"stream":"btcusd@depth","data":{"e":"depthUpdate","E":1785649882909,"s":"BTCUSD","U":4527243985,"u":4527243986,"b":[["63378.79000000","0.00079000"]],"a":[["63399.24000000","0.00077000"]]}}
{"stream":"ethusd@depth","data":{"e":"depthUpdate","E":1785649882909,"s":"ETHUSD","U":3656117898,"u":3656117899,"b":[["1874.08000000","1.06710000"],["1874.03000000","0.00000000"]],"a":[]}}
{"stream":"btcusd@depth","data":{"e":"depthUpdate","E":1785649883909,"s":"BTCUSD","U":4527243987,"u":4527243988,"b":[["63347.30000000","0.07900000"],["63341.63000000","0.00000000"]],"a":[]}}
{"stream":"btcusd@depth","data":{"e":"depthUpdate","E":1785649884909,"s":"BTCUSD","U":4527243989,"u":4527244012,"b":[["63381.38000000","0.02436000"],["63381.37000000","0.03397000"],["63379.06000000","0.00000000"],["63379.05000000","0.00000000"],["63374.23000000","0.03150000"],["63374.15000000","0.00000000"],["63374.11000000","0.00000000"],["63373.96000000","0.00000000"],["63373.31000000","0.00000000"],["63373.22000000","0.00000000"],["63370.82000000","0.00410000"],["63368.37000000","0.00000000"],["63360.68000000","0.04355000"],["63356.83000000","0.00000000"],["63313.48000000","0.33130000"],["63313.40000000","0.00000000"],["63313.36000000","0.00000000"],["63313.21000000","0.00000000"],["63312.56000000","0.00000000"],["63312.47000000","0.00000000"]],"a":[["63390.54000000","0.00000000"],["63390.55000000","0.00000000"],["63390.56000000","0.00000000"],["63392.66000000","0.00300000"],["63393.02000000","0.00410000"],["63398.09000000","0.00000000"],["63400.01000000","0.00000000"],["63400.41000000","0.03306000"],["63403.16000000","0.04353000"],["63431.66000000","0.00000000"],["63436.93000000","0.27112000"]]}}
{"stream":"ethusd@depth","data":{"e":"depthUpdate","E":1785649884909,"s":"ETHUSD","U":3656117900,"u":3656117903,"b":[["1873.74000000","0.13860000"],["1873.68000000","0.00000000"]],"a":[["1874.35000000","0.00000000"],["1874.40000000","0.13870000"],["1874.65000000","0.00000000"],["1874.70000000","1.47220000"],["1875.59000000","0.00000000"],["1875.75000000","9.16950000"]]}}
{"stream":"btcusd@depth","data":{"e":"depthUpdate","E":1785649885910,"s":"BTCUSD","U":4527244013,"u":4527244032,"b":[["63337.18000000","0.20685000"],["63174.24000000","0.00000000"]],"a":[["63392.63000000","0.00000000"],["63392.64000000","0.00000000"],["63392.65000000","0.00000000"],["63392.66000000","0.00300000"],["63450.36000000","0.00000000"],["63568.30000000","0.26208000"]]}}
{"stream":"ethusd@depth","data":{"e":"depthUpdate","E":1785649885910,"s":"ETHUSD","U":3656117904,"u":3656117920,"b":[["1874.09000000","0.00000000"],["1873.85000000","0.53360000"],["1873.69000000","0.00000000"],["1873.39000000","4.11760000"],["1872.89000000","0.00000000"],["1866.96000000","7.11480000"],["1865.38000000","0.00000000"]],"a":[["1874.25000000","0.00000000"],["1874.31000000","1.06700000"],["1874.45000000","0.00000000"],["1874.60000000","0.53340000"],["1881.84000000","0.00000000"],["1881.89000000","0.00000000"],["1881.94000000","7.05020000"],["1883.21000000","8.98470000"],["1883.27000000","8.97180000"]]}}
{"stream":"btcusd@depth","data":{"e":"depthUpdate","E":1785649886910,"s":"BTCUSD","U":4527244033,"u":4527244040,"b":[["63374.29000000","0.03150000"],["63374.28000000","0.00000000"],["63374.27000000","0.00000000"],["63374.26000000","0.00000000"],["63374.23000000","0.00000000"],["63313.54000000","0.33130000"],["63313.53000000","0.00000000"],["63313.52000000","0.00000000"],["63313.51000000","0.00000000"],["63313.48000000","0.00000000"]],"a":[]}}
{"stream":"ethusd@depth","data":{"e":"depthUpdate","E":1785649886910,"s":"ETHUSD","U":3656117921,"u":3656117955,"b":[["1874.19000000","0.00000000"],["1874.15000000","0.00000000"],["1874.10000000","0.00000000"],["1874.08000000","0.00000000"],["1874.04000000","0.00000000"],["1874.02000000","1.18720000"],["1873.85000000","0.00000000"],["1873.74000000","0.00000000"],["1873.64000000","0.13870000"],["1873.58000000","0.00000000"],["1873.56000000","0.53370000"],["1873.39000000","0.00000000"],["1873.34000000","3.16130000"],["1873.14000000","4.11820000"],["1873.12000000","0.00000000"],["1872.90000000","2.67000000"],["1871.62000000","0.00000000"],["1871.48000000","11.20700000"],["1871.36000000","0.00000000"],["1870.93000000","0.00000000"],["1870.71000000","0.22110000"]],"a":[["1874.31000000","1.20570000"],["1874.40000000","0.00000000"],["1874.46000000","0.00000000"],["1874.52000000","1.60070000"],["1874.59000000","1.09880000"],["1874.60000000","0.00000000"],["1874.61000000","1.47230000"],["1874.67000000","0.00000000"],["1874.70000000","0.00000000"],["1874.72000000","1.92620000"],["1875.35000000","0.30750000"],["1875.40000000","0.00000000"],["1876.23000000","8.94750000"],["1876.25000000","0.00000000"],["1876.35000000","0.00000000"]]}}
{"stream":"btcusd@depth","data":{"e":"depthUpdate","E":1785649887910,"s":"BTCUSD","U":4527244041,"u":4527244041,"b":[],"a":[["63382.80000000","0.02663000"]]}}
{"stream":"ethusd@depth","data":{"e":"depthUpdate","E":1785649887910,"s":"ETHUSD","U":3656117956,"u":3656118011,"b":[["1874.02000000","0.00000000"],["1873.99000000","0.02970000"],["1873.92000000","0.00000000"],["1873.85000000","1.18750000"],["1873.78000000","1.06720000"],["1873.72000000","0.00000000"],["1873.67000000","0.00000000"],["1873.56000000","0.00000000"],["1873.37000000","0.53370000"],["1873.34000000","1.56050000"],["1873.14000000","5.71920000"],["1873.13000000","0.00000000"],["1872.97000000","0.00000000"],["1872.96000000","0.00000000"],["1872.91000000","0.10000000"],["1872.54000000","2.13460000"],["1870.71000000","0.00000000"],["1870.58000000","0.24910000"],["1866.96000000","0.00000000"],["1866.86000000","0.00000000"],["1866.83000000","0.00000000"],["1866.76000000","7.07640000"],["1866.71000000","7.77650000"],["1866.61000000","7.67880000"],["1865.50000000","8.95020000"],["1865.45000000","0.00000000"]],"a":[["1874.16000000","1.06720000"],["1874.17000000","0.53350000"],["1874.30000000","1.60100000"],["1874.31000000","0.13870000"],["1874.42000000","1.16860000"],["1874.49000000","0.00000000"],["1874.50000000","1.56050000"],["1874.52000000","0.00000000"],["1874.59000000","0.00000000"],["1874.85000000","2.66700000"],["1874.98000000","0.00000000"],["1875.20000000","0.00000000"],["1875.25000000","0.00000000"],["1876.11000000","8.94660000"],["1876.12000000","0.00000000"],["1876.14000000","0.00000000"],["1876.23000000","0.00000000"],["1881.74000000","7.00560000"],["1881.81000000","7.07080000"],["1883.21000000","0.00000000"],["1883.27000000","0.00000000"]]}}
{"stream":"btcusd@depth","data":{"e":"depthUpdate","E":1785649888910,"s":"BTCUSD","U":4527244042,"u":4527244045,"b":[["63374.51000000","0.03150000"],["63374.48000000","0.00000000"],["63374.29000000","0.00000000"],["63313.75000000","0.33130000"],["63313.73000000","0.00000000"],["63313.54000000","0.00000000"]],"a":[]}}
{"stream":"ethusd@depth","data":{"e":"depthUpdate","E":1785649888910,"s":"ETHUSD","U":3656118012,"u":3656118017,"b":[["1873.83000000","1.06720000"],["1873.78000000","0.00000000"],["1873.52000000","0.53370000"],["1873.37000000","0.00000000"]],"a":[["1874.30000000","0.00000000"],["1874.49000000","1.60080000"]]}}
{"stream":"btcusd@depth","data":{"e":"depthUpdate","E":1785649889910,"s":"BTCUSD","U":4527244046,"u":4527244051,"b":[["63374.71000000","0.03150000"],["63374.63000000","0.00000000"],["63374.55000000","0.00000000"],["63374.51000000","0.00000000"],["63313.95000000","0.33130000"],["63313.88000000","0.00000000"],["63313.80000000","0.00000000"],["63313.75000000","0.00000000"]],"a":[]}}
{"stream":"ethusd@depth","data":{"e":"depthUpdate","E":1785649889910,"s":"ETHUSD","U":3656118018,"u":3656118021,"b":[["1873.88000000","1.06720000"],["1873.83000000","0.00000000"],["1873.34000000","3.16130000"],["1873.14000000","4.11820000"]],"a":[]}}
{"stream":"ethusd@depth","data":{"e":"depthUpdate","E":1785649890910,"s":"ETHUSD","U":3656118022,"u":3656118039,"b":[["1874.00000000","1.06710000"],["1873.98000000","1.13350000"],["1873.95000000","0.00000000"],["1873.92000000","0.00000000"],["1873.88000000","0.00000000"],["1873.85000000","0.00000000"],["1873.68000000","0.53370000"],["1873.52000000","0.00000000"]],"a":[["1874.17000000","0.00000000"],["1874.33000000","0.53350000"],["1874.42000000","0.00000000"],["1874.49000000","0.00000000"],["1874.55000000","1.18050000"],["1874.68000000","1.60060000"]]}}
{"stream":"ethusd@depth","data":{"e":"depthUpdate","E":1785649891910,"s":"ETHUSD","U":3656118040,"u":3656118041,"b":[["1873.15000000","0.10000000"],["1872.91000000","0.00000000"]],"a":[["1874.28000000","0.13870000"],["1874.31000000","0.00000000"]]}}
{"stream":"btcusd@depth","data":{"e":"depthUpdate","E":1785649892910,"s":"BTCUSD","U":4527244052,"u":4527244053,"b":[["63374.79000000","0.03150000"],["63374.71000000","0.00000000"],["63314.04000000","0.33130000"],["63313.95000000","0.00000000"]],"a":[]}}
{"stream":"btcusd@depth","data":{"e":"depthUpdate","E":1785649893910,"s":"BTCUSD","U":4527244054,"u":4527244059,"b":[["63375.90000000","0.03150000"],["63375.88000000","0.00000000"],["63374.79000000","0.00000000"],["63372.10000000","0.00408000"],["63370.82000000","0.00000000"],["63315.15000000","0.33130000"],["63315.12000000","0.00000000"],["63314.04000000","0.00000000"]],"a":[["63393.02000000","0.00000000"],["63394.30000000","0.00410000"]]}}
{"stream":"btcusd@depth","data":{"e":"depthUpdate","E":1785649894910,"s":"BTCUSD","U":4527244060,"u":4527244077,"b":[["63381.00000000","0.03837000"],["63378.80000000","0.16077000"],["63376.28000000","0.00000000"],["63376.00000000","0.03150000"],["63375.90000000","0.00000000"],["63369.10000000","0.00000000"],["63315.24000000","0.33130000"],["63315.15000000","0.00000000"]],"a":[["63382.80000000","0.00000000"],["63384.47000000","0.00000000"],["63387.21000000","0.00000000"],["63387.22000000","0.02559000"],["63392.66000000","0.00300000"],["63393.32000000","0.00000000"],["63396.15000000","0.00000000"],["63396.33000000","0.00000000"],["63401.28000000","0.01577000"],["63404.46000000","0.00626000"],["63417.13000000","0.04696000"]]}}
{"stream":"ethusd@depth","data":{"e":"depthUpdate","E":1785649894910,"s":"ETHUSD","U":3656118042,"u":3656118061,"b":[["1874.09000000","1.17610000"],["1874.06000000","1.06710000"],["1874.00000000","0.00000000"],["1873.98000000","0.00000000"],["1873.55000000","1.60060000"],["1873.34000000","1.56050000"],["1872.93000000","2.13410000"],["1872.54000000","0.00000000"],["1870.82000000","0.23570000"],["1870.58000000","0.00000000"]],"a":[["1874.16000000","0.00000000"],["1874.22000000","1.06700000"],["1874.33000000","0.00000000"],["1874.50000000","0.00000000"],["1874.51000000","0.53340000"],["1874.55000000","0.00000000"],["1874.67000000","0.38840000"],["1874.85000000","0.00000000"],["1875.09000000","2.66600000"],["1875.15000000","1.56050000"]]}}
{"stream":"ethusd@depth","data":{"e":"depthUpdate","E":1785649895910,"s":"ETHUSD","U":3656118062,"u":3656118066,"b":[["1873.74000000","0.13850000"],["1873.64000000","0.00000000"],["1873.01000000","2.67000000"],["1872.90000000","0.00000000"]],"a":[["1874.28000000","0.00000000"],["1874.41000000","0.13870000"],["1874.61000000","0.00000000"],["1874.71000000","1.47220000"]]}}
{"stream":"btcusd@depth","data":{"e":"depthUpdate","E":1785649896910,"s":"BTCUSD","U":4527244078,"u":4527244078,"b":[],"a":[["63387.21000000","0.00300000"],["63392.66000000","0.00000000"]]}}
{"stream":"btcusd@depth","data":{"e":"depthUpdate","E":1785649898910,"s":"BTCUSD","U":4527244079,"u":4527244080,"b":[["63376.01000000","0.03150000"],["63376.00000000","0.00000000"],["63315.26000000","0.33130000"],["63315.24000000","0.00000000"]],"a":[]}}
{"stream":"btcusd@depth","data":{"e":"depthUpdate","E":1785649899911,"s":"BTCUSD","U":4527244081,"u":4527244099,"b":[["63382.50000000","0.03293000"],["63381.37000000","0.00000000"],["63376.73000000","0.03150000"],["63376.61000000","0.00000000"],["63376.31000000","0.00000000"],["63376.01000000","0.00000000"],["63373.19000000","0.00410000"],["63372.10000000","0.00000000"],["63363.05000000","0.04353000"],["63360.68000000","0.00000000"],["63315.98000000","0.33130000"],["63315.86000000","0.00000000"],["63315.56000000","0.00000000"],["63315.26000000","0.00000000"]],"a":[["63387.20000000","0.00000000"],["63387.21000000","0.00000000"],["63387.22000000","0.00000000"],["63392.65000000","0.00000000"],["63392.66000000","0.00300000"],["63400.41000000","0.00000000"],["63402.98000000","0.03229000"],["63403.16000000","0.00000000"],["63405.53000000","0.04351000"]]}}
{"stream":"ethusd@depth","data":{"e":"depthUpdate","E":1785649899911,"s":"ETHUSD","U":3656118067,"u":3656118092,"b":[["1873.99000000","0.00000000"],["1873.82000000","0.53360000"],["1873.68000000","0.00000000"],["1872.49000000","2.66750000"],["1872.30000000","3.73450000"],["1871.74000000","0.00000000"],["1871.55000000","11.20580000"],["1871.53000000","0.00000000"],["1871.50000000","0.00000000"],["1871.48000000","0.00000000"],["1866.86000000","7.06180000"],["1865.50000000","0.00000000"]],"a":[["1874.22000000","0.00000000"],["1874.73000000","0.00000000"],["1874.92000000","0.14840000"],["1876.11000000","0.00000000"],["1876.37000000","8.94850000"],["1881.74000000","0.00000000"],["1881.75000000","0.00000000"],["1881.81000000","0.00000000"],["1881.84000000","6.99660000"],["1881.88000000","7.79740000"],["1883.11000000","8.93820000"],["1883.16000000","9.04650000"]]}}
{"stream":"btcusd@depth","data":{"e":"depthUpdate","E":1785649900911,"s":"BTCUSD","U":4527244100,"u":4527244122,"b":[["63378.79000000","0.00000000"],["63376.99000000","0.03150000"],["63376.97000000","0.00000000"],["63376.96000000","0.00000000"],["63376.92000000","0.00000000"],["63376.73000000","0.00000000"],["63316.23000000","0.33130000"],["63316.22000000","0.00000000"],["63316.21000000","0.00000000"],["63316.16000000","0.00000000"],["63315.98000000","0.00000000"],["63104.93000000","0.00000000"]],"a":[["63392.63000000","0.00000000"],["63392.64000000","0.00000000"],["63392.65000000","0.00000000"],["63392.66000000","0.00300000"],["63399.24000000","0.00000000"]]}}
{"stream":"ethusd@depth","data":{"e":"depthUpdate","E":1785649900911,"s":"ETHUSD","U":3656118093,"u":3656118114,"b":[["1874.18000000","1.06700000"],["1874.17000000","0.00000000"],["1874.06000000","0.00000000"],["1873.74000000","1.73900000"],["1873.55000000","0.00000000"],["1873.14000000","6.78720000"],["1873.01000000","0.00000000"],["1871.61000000","11.20550000"],["1871.59000000","5.20170000"],["1871.56000000","0.00000000"],["1871.55000000","0.00000000"],["1866.99000000","7.08440000"],["1865.56000000","0.00000000"]],"a":[["1874.51000000","0.00000000"],["1874.73000000","0.53340000"],["1875.35000000","0.00000000"],["1881.84000000","0.00000000"],["1881.88000000","0.00000000"],["1881.94000000","0.00000000"],["1883.21000000","8.89370000"],["1883.26000000","9.06620000"],["1883.31000000","8.97090000"]]}}
{"stream":"btcusd@depth","data":{"e":"depthUpdate","E":1785649901911,"s":"BTCUSD","U":4527244123,"u":4527244127,"b":[["63381.05000000","0.00079000"],["63377.00000000","0.03150000"],["63376.99000000","0.00000000"],["63316.25000000","0.33130000"],["63316.24000000","0.00000000"],["63316.23000000","0.00000000"]],"a":[["63401.50000000","0.00079000"]]}}
{"stream":"ethusd@depth","data":{"e":"depthUpdate","E":1785649901911,"s":"ETHUSD","U":3656118115,"u":3656118127,"b":[["1874.23000000","0.02970000"],["1874.18000000","0.00000000"],["1874.15000000","1.12670000"],["1874.13000000","1.06700000"],["1874.09000000","0.00000000"],["1873.74000000","0.13850000"],["1873.54000000","1.40620000"],["1871.62000000","11.20540000"],["1871.61000000","0.00000000"]],"a":[["1874.41000000","0.00000000"],["1874.43000000","0.13870000"],["1874.54000000","0.53340000"],["1874.67000000","0.00000000"],["1874.72000000","3.01750000"],["1874.73000000","0.00000000"]]}}
{"stream":"btcusd@depth","data":{"e":"depthUpdate","E":1785649902911,"s":"BTCUSD","U":4527244128,"u":4527244129,"b":[["63113.09000000","0.00560000"]],"a":[["63399.72000000","0.00000000"]]}}
{"stream":"ethusd@depth","data":{"e":"depthUpdate","E":1785649902911,"s":"ETHUSD","U":3656118128,"u":3656118129,"b":[["1873.48000000","1.47290000"],["1873.38000000","0.00000000"]],"a":[["1874.43000000","0.00000000"],["1874.45000000","0.13860000"]]}}
{"stream":"ethusd@depth","data":{"e":"depthUpdate","E":1785649903911,"s":"ETHUSD","U":3656118130,"u":3656118130,"b":[],"a":[["1875.60000000","0.23940000"]]}}
{"stream":"btcusd@depth","data":{"e":"depthUpdate","E":1785649904911,"s":"BTCUSD","U":4527244130,"u":4527244138,"b":[["63368.59000000","0.00000000"]],"a":[["63382.52000000","0.00000000"],["63392.65000000","0.00000000"],["63392.66000000","0.00000000"],["63392.67000000","0.00000000"],["63394.30000000","0.00000000"],["63395.20000000","0.00300000"],["63395.36000000","0.00410000"],["63401.24000000","0.36224000"],["63406.32000000","0.00381000"]]}}
{"stream":"ethusd@depth","data":{"e":"depthUpdate","E":1785649904911,"s":"ETHUSD","U":3656118131,"u":3656118133,"b":[["1873.80000000","0.00000000"]],"a":[["1874.36000000","0.00000000"],["1874.71000000","0.00000000"],["1874.75000000","1.47220000"]]}}
{"stream":"btcusd@depth","data":{"e":"depthUpdate","E":1785649905911,"s":"BTCUSD","U":4527244139,"u":4527244145,"b":[["63377.11000000","0.03150000"],["63377.05000000","0.00000000"],["63377.04000000","0.00000000"],["63377.00000000","0.00000000"],["63316.35000000","0.33130000"],["63316.30000000","0.00000000"],["63316.29000000","0.00000000"],["63316.28000000","0.00000000"],["63316.25000000","0.00000000"]],"a":[]}}
{"stream":"btcusd@depth","data":{"e":"depthUpdate","E":1785649906911,"s":"BTCUSD","U":4527244146,"u":4527244147,"b":[["63377.12000000","0.03150000"],["63377.11000000","0.00000000"],["63316.36000000","0.33130000"],["63316.35000000","0.00000000"]],"a":[]}}
{"stream":"ethusd@depth","data":{"e":"depthUpdate","E":1785649906911,"s":"ETHUSD","U":3656118134,"u":3656118135,"b":[["1874.13000000","0.00000000"],["1874.07000000","1.04960000"]],"a":[]}}
{"stream":"btcusd@depth","data":{"e":"depthUpdate","E":1785649908911,"s":"BTCUSD","U":4527244148,"u":4527244149,"b":[["63377.16000000","0.03150000"],["63377.12000000","0.00000000"],["63316.41000000","0.33130000"],["63316.36000000","0.00000000"]],"a":[]}}
{"stream":"btcusd@depth","data":{"e":"depthUpdate","E":1785649909911,"s":"BTCUSD","U":4527244150,"u":4527244161,"b":[["63377.22000000","0.03150000"],["63377.16000000","0.00000000"],["63361.13000000","0.06309000"],["63348.33000000","0.00000000"],["63338.98000000","0.20639000"],["63316.47000000","0.33130000"],["63316.41000000","0.00000000"],["63182.42000000","0.00000000"]],"a":[["63401.25000000","0.00000000"],["63409.30000000","0.11800000"],["63452.17000000","0.00000000"],["63453.96000000","0.00000000"],["63576.97000000","0.00000000"]]}}
{"stream":"ethusd@depth","data":{"e":"depthUpdate","E":1785649909911,"s":"ETHUSD","U":3656118136,"u":3656118137,"b":[["1874.12000000","1.06700000"],["1874.07000000","0.00000000"]],"a":[]}}
{"stream":"btcusd@depth","data":{"e":"depthUpdate","E":1785649910911,"s":"BTCUSD","U":4527244162,"u":4527244169,"b":[["63381.05000000","0.00000000"],["63352.15000000","0.07900000"],["63347.30000000","0.00000000"],["63340.78000000","0.20511000"],["63192.32000000","0.00000000"]],"a":[["63401.50000000","0.00000000"],["63454.86000000","0.20501000"],["63576.73000000","0.26295000"]]}}
{"stream":"ethusd@depth","data":{"e":"depthUpdate","E":1785649910911,"s":"ETHUSD","U":3656118138,"u":3656118139,"b":[["1873.81000000","0.13840000"],["1873.74000000","0.00000000"]],"a":[["1874.45000000","0.00000000"],["1874.48000000","0.13830000"]]}}
{"stream":"btcusd@depth","data":{"e":"depthUpdate","E":1785649911911,"s":"BTCUSD","U":4527244170,"u":4527244175,"b":[["63383.62000000","0.03154000"],["63383.61000000","0.00079000"],["63381.38000000","0.00000000"],["63379.49000000","0.03150000"],["63377.22000000","0.00000000"],["63318.73000000","0.33120000"],["63316.47000000","0.00000000"]],"a":[["63403.69000000","0.00080000"]]}}
{"stream":"ethusd@depth","data":{"e":"depthUpdate","E":1785649916912,"s":"ETHUSD","U":3656118140,"u":3656118145,"b":[["1874.24000000","1.13430000"],["1874.15000000","0.00000000"],["1873.35000000","4.11770000"],["1873.14000000","2.66900000"]],"a":[["1874.72000000","1.92620000"],["1874.81000000","0.44410000"]]}}
{"stream":"btcusd@depth","data":{"e":"depthUpdate","E":1785649917912,"s":"BTCUSD","U":4527244176,"u":4527244183,"b":[["61500.91000000","0.00000000"],["61487.72000000","0.01411000"],["60549.87000000","0.00000000"],["60536.88000000","0.01911000"],["54907.00000000","0.00000000"]],"a":[["64671.07000000","0.00000000"],["69743.31000000","0.00000000"],["85594.06000000","0.00000000"]]}}
