{"stream":"ethusd@depth","data":{"e":"depthUpdate","E":1785649917912,"s":"ETHUSD","U":3656118146,"u":3656118163,"b":[["1874.30000000","1.14050000"],["1874.24000000","0.00000000"],["1873.94000000","0.13870000"],["1873.81000000","0.00000000"],["1873.64000000","1.47300000"],["1873.48000000","0.00000000"],["1872.59000000","9.18510000"],["1872.34000000","0.00000000"],["1871.73000000","11.20470000"],["1871.63000000","0.00000000"],["1871.62000000","0.00000000"],["1837.41000000","0.00000000"],["1790.53000000","0.00000000"],["1623.67000000","0.00000000"]],"a":[["1874.48000000","0.00000000"],["1874.60000000","0.13860000"],["1874.75000000","0.00000000"],["1874.81000000","0.00000000"],["1874.87000000","1.09480000"],["1874.90000000","1.47200000"],["1875.75000000","0.00000000"],["1875.95000000","9.16860000"],["1912.40000000","0.00000000"],["2006.15000000","0.00000000"],["2249.89000000","0.00000000"]]}}
{"stream":"btcusd@depth","data":{"e":"depthUpdate","E":1785649918912,"s":"BTCUSD","U":4527244184,"u":4527244187,"b":[["54895.22000000","0.03162000"]],"a":[["64657.19000000","0.43072000"],["69728.35000000","0.68916000"],["85575.70000000","1.11989000"]]}}
{"stream":"ethusd@depth","data":{"e":"depthUpdate","E":1785649918912,"s":"ETHUSD","U":3656118164,"u":3656118173,"b":[["1874.17000000","0.00000000"],["1874.12000000","1.06700000"],["1836.84000000","0.47260000"],["1789.98000000","0.48490000"],["1623.17000000","0.89130000"]],"a":[["1911.82000000","1.26440000"],["2005.53000000","1.68590000"],["2249.20000000","3.37180000"]]}}
{"stream":"btcusd@depth","data":{"e":"depthUpdate","E":1785649919912,"s":"BTCUSD","U":4527244188,"u":4527244207,"b":[["63386.32000000","0.07885000"],["63386.31000000","0.00079000"],["63383.62000000","0.00000000"],["63383.61000000","0.00000000"],["63381.00000000","0.00000000"],["63380.28000000","0.01577000"],["63379.77000000","0.03150000"],["63379.49000000","0.00000000"],["63375.02000000","0.00000000"],["63343.48000000","0.20405000"],["63319.01000000","0.33120000"],["63318.73000000","0.00000000"],["63201.00000000","0.00000000"]],"a":[["63395.20000000","0.00000000"],["63395.21000000","0.00000000"],["63395.35000000","0.00300000"],["63454.86000000","0.00000000"],["63456.65000000","0.00000000"],["63457.57000000","0.20551000"],["63576.73000000","0.00000000"],["63577.46000000","0.26468000"]]}}
{"stream":"ethusd@depth","data":{"e":"depthUpdate","E":1785649919912,"s":"ETHUSD","U":3656118174,"u":3656118176,"b":[["1874.17000000","1.06700000"],["1874.12000000","0.00000000"]],"a":[["1874.69000000","0.05880000"]]}}
{"stream":"btcusd@depth","data":{"e":"depthUpdate","E":1785649920912,"s":"BTCUSD","U":4527244208,"u":4527244234,"b":[["63379.84000000","0.03150000"],["63379.82000000","0.00000000"],["63379.77000000","0.00000000"],["63319.08000000","0.33120000"],["63319.06000000","0.00000000"],["63319.01000000","0.00000000"]],"a":[["63395.19000000","0.00000000"],["63395.32000000","0.00000000"],["63395.33000000","0.00000000"],["63395.34000000","0.00000000"],["63395.35000000","0.00300000"],["63419.40000000","0.04696000"],["63513.21000000","0.00000000"],["63523.51000000","0.00000000"]]}}
{"stream":"ethusd@depth","data":{"e":"depthUpdate","E":1785649920912,"s":"ETHUSD","U":3656118177,"u":3656118216,"b":[["1874.43000000","1.10680000"],["1874.39000000","0.00000000"],["1874.30000000","0.00000000"],["1874.28000000","1.06690000"],["1874.23000000","0.02970000"],["1874.17000000","0.00000000"],["1874.09000000","0.13870000"],["1873.97000000","0.53360000"],["1873.94000000","0.00000000"],["1873.84000000","1.56050000"],["1873.82000000","0.00000000"],["1873.79000000","1.47200000"],["1873.74000000","1.60040000"],["1873.64000000","0.00000000"],["1873.54000000","0.00000000"],["1873.36000000","0.10000000"],["1873.15000000","0.00000000"],["1873.07000000","0.00000000"],["1871.83000000","0.00000000"],["1871.82000000","0.00000000"],["1871.80000000","0.00000000"],["1871.74000000","0.00000000"],["1871.73000000","0.00000000"],["1871.58000000","11.20560000"],["1870.82000000","0.00000000"]],"a":[["1874.60000000","0.00000000"],["1874.63000000","0.00000000"],["1874.68000000","0.00000000"],["1874.69000000","0.00000000"],["1874.76000000","0.13860000"],["1874.78000000","0.00000000"],["1874.79000000","0.05720000"],["1874.87000000","1.60050000"],["1874.90000000","0.00000000"],["1874.97000000","0.00000000"],["1875.02000000","0.48070000"],["1875.06000000","1.47120000"],["1876.37000000","0.00000000"],["1876.46000000","8.94910000"],["1876.60000000","0.00000000"],["1876.63000000","0.00000000"],["1876.64000000","0.00000000"]]}}
{"stream":"btcusd@depth","data":{"e":"depthUpdate","E":1785649921912,"s":"BTCUSD","U":4527244235,"u":4527244241,"b":[["63386.22000000","0.03422000"],["63382.50000000","0.00000000"]],"a":[["63395.35000000","0.00000000"],["63395.36000000","0.00000000"],["63395.90000000","0.00300000"],["63395.91000000","0.00410000"],["63402.98000000","0.00000000"],["63405.25000000","0.03285000"],["63436.93000000","0.00000000"],["63441.55000000","0.27111000"]]}}
{"stream":"ethusd@depth","data":{"e":"depthUpdate","E":1785649921912,"s":"ETHUSD","U":3656118217,"u":3656118227,"b":[["1874.34000000","0.02960000"],["1874.23000000","0.00000000"],["1871.68000000","11.20510000"],["1871.67000000","0.00000000"],["1871.65000000","0.00000000"],["1871.58000000","0.00000000"],["1867.09000000","7.00230000"],["1865.62000000","0.00000000"]],"a":[["1881.98000000","0.00000000"],["1882.03000000","0.00000000"],["1883.36000000","9.07860000"],["1883.42000000","9.08560000"]]}}
{"stream":"btcusd@depth","data":{"e":"depthUpdate","E":1785649922912,"s":"BTCUSD","U":4527244242,"u":4527244258,"b":[["63382.75000000","0.03150000"],["63379.89000000","0.00000000"],["63379.84000000","0.00000000"],["63375.33000000","0.00410000"],["63373.19000000","0.00000000"],["63355.52000000","0.07900000"],["63352.15000000","0.00000000"],["63329.31000000","0.27158000"],["63322.03000000","0.00000000"],["63321.99000000","0.33120000"],["63319.14000000","0.00000000"],["63319.08000000","0.00000000"],["63113.09000000","0.00000000"]],"a":[["63395.90000000","0.00000000"],["63395.91000000","0.00000000"],["63397.13000000","0.00000000"],["63397.14000000","0.00410000"],["63401.28000000","0.00000000"],["63405.53000000","0.00000000"],["63406.26000000","0.01577000"],["63406.32000000","0.00000000"],["63407.28000000","0.04352000"],["63545.00000000","0.00000000"]]}}
{"stream":"ethusd@depth","data":{"e":"depthUpdate","E":1785649922912,"s":"ETHUSD","U":3656118228,"u":3656118230,"b":[["1871.05000000","0.30290000"]],"a":[["1874.54000000","0.00000000"],["1874.72000000","2.45960000"]]}}
{"stream":"btcusd@depth","data":{"e":"depthUpdate","E":1785649923912,"s":"BTCUSD","U":4527244259,"u":4527244266,"b":[["63382.91000000","0.03150000"],["63382.75000000","0.00000000"],["63366.69000000","0.04354000"],["63363.05000000","0.00000000"],["63322.14000000","0.33120000"],["63321.99000000","0.00000000"],["63119.45000000","0.00329000"]],"a":[["63397.14000000","0.00000000"],["63398.16000000","0.00000000"],["63399.03000000","0.00410000"],["63407.28000000","0.00000000"],["63409.17000000","0.04350000"],["63417.12000000","0.00384000"]]}}
{"stream":"btcusd@depth","data":{"e":"depthUpdate","E":1785649924912,"s":"BTCUSD","U":4527244267,"u":4527244268,"b":[],"a":[["63448.66000000","0.00000000"],["63471.12000000","0.15755000"]]}}
{"stream":"ethusd@depth","data":{"e":"depthUpdate","E":1785649924912,"s":"ETHUSD","U":3656118231,"u":3656118237,"b":[["1874.34000000","1.09650000"],["1874.28000000","0.00000000"],["1871.73000000","11.20470000"],["1871.68000000","0.00000000"]],"a":[["1874.72000000","0.53340000"],["1874.83000000","3.21650000"],["1875.09000000","0.00000000"],["1875.39000000","2.66600000"]]}}
{"stream":"btcusd@depth","data":{"e":"depthUpdate","E":1785649925912,"s":"BTCUSD","U":4527244269,"u":4527244278,"b":[["63383.01000000","0.03150000"],["63382.92000000","0.00000000"],["63382.91000000","0.00000000"],["63322.51000000","0.15792000"],["63322.25000000","0.33120000"],["63322.16000000","0.00000000"],["63322.14000000","0.00000000"],["63299.86000000","0.00000000"]],"a":[["63457.57000000","0.00000000"],["63458.47000000","0.20493000"],["63576.21000000","0.26136000"],["63577.46000000","0.00000000"]]}}
{"stream":"ethusd@depth","data":{"e":"depthUpdate","E":1785649925912,"s":"ETHUSD","U":3656118238,"u":3656118283,"b":[["1874.41000000","1.06690000"],["1874.34000000","0.00000000"],["1874.15000000","0.53350000"],["1873.97000000","0.00000000"],["1873.93000000","1.60030000"],["1873.74000000","0.00000000"],["1873.63000000","0.10000000"],["1873.48000000","2.66900000"],["1873.36000000","0.00000000"],["1873.34000000","0.00000000"],["1873.32000000","2.13370000"],["1873.14000000","0.00000000"],["1872.93000000","0.00000000"],["1871.89000000","11.20380000"],["1871.88000000","5.34220000"],["1871.75000000","0.00000000"],["1871.73000000","0.00000000"],["1871.05000000","0.00000000"],["1867.20000000","7.09190000"],["1865.68000000","0.00000000"]],"a":[["1874.48000000","0.00000000"],["1874.57000000","1.06680000"],["1874.72000000","0.00000000"],["1874.83000000","0.00000000"],["1874.87000000","0.53330000"],["1874.92000000","0.00000000"],["1874.93000000","0.00000000"],["1875.01000000","1.65600000"],["1875.02000000","0.00000000"],["1875.12000000","1.12860000"],["1875.15000000","0.00000000"],["1875.60000000","0.00000000"],["1875.93000000","0.23600000"],["1876.46000000","0.00000000"],["1876.72000000","8.95100000"],["1882.08000000","0.00000000"],["1882.12000000","0.00000000"],["1882.17000000","0.00000000"],["1882.18000000","7.01790000"],["1883.42000000","0.00000000"],["1883.43000000","8.97980000"],["1883.48000000","9.09560000"]]}}
{"stream":"btcusd@depth","data":{"e":"depthUpdate","E":1785649926912,"s":"BTCUSD","U":4527244279,"u":4527244282,"b":[["63383.11000000","0.03150000"],["63383.07000000","0.00000000"],["63383.01000000","0.00000000"],["63322.35000000","0.33120000"],["63322.31000000","0.00000000"],["63322.25000000","0.00000000"]],"a":[]}}
{"stream":"ethusd@depth","data":{"e":"depthUpdate","E":1785649926912,"s":"ETHUSD","U":3656118284,"u":3656118286,"b":[["1874.43000000","1.13620000"]],"a":[["1874.52000000","1.06680000"],["1874.57000000","0.00000000"]]}}
{"stream":"btcusd@depth","data":{"e":"depthUpdate","E":1785649927912,"s":"BTCUSD","U":4527244283,"u":4527244291,"b":[["63388.87000000","0.03154000"],["63388.86000000","0.03421000"],["63386.32000000","0.04731000"],["63386.22000000","0.00000000"],["63377.48000000","0.00410000"],["63375.33000000","0.00000000"]],"a":[["63399.03000000","0.00000000"],["63399.68000000","0.00410000"],["63405.25000000","0.00000000"],["63407.89000000","0.03353000"],["63545.00000000","0.00675000"]]}}
{"stream":"ethusd@depth","data":{"e":"depthUpdate","E":1785649927912,"s":"ETHUSD","U":3656118287,"u":3656118301,"b":[["1874.17000000","0.13870000"],["1874.11000000","1.56050000"],["1874.09000000","0.00000000"],["1873.87000000","1.47280000"],["1873.79000000","0.00000000"],["1872.82000000","9.18380000"],["1872.59000000","0.00000000"],["1871.90000000","11.20380000"],["1871.89000000","0.00000000"],["1871.29000000","0.31980000"]],"a":[["1874.76000000","0.00000000"],["1874.79000000","0.00000000"],["1874.84000000","0.13860000"],["1874.86000000","0.05710000"],["1874.87000000","2.09380000"],["1875.05000000","0.14840000"],["1875.06000000","0.00000000"],["1875.14000000","1.47180000"],["1875.31000000","1.56050000"],["1875.58000000","1.56050000"],["1875.95000000","0.00000000"],["1876.19000000","9.16750000"]]}}
{"stream":"btcusd@depth","data":{"e":"depthUpdate","E":1785649928912,"s":"BTCUSD","U":4527244292,"u":4527244323,"b":[["63391.12000000","0.03525000"],["63390.51000000","0.04731000"],["63388.86000000","0.00000000"],["63386.32000000","0.00000000"],["63384.50000000","0.03150000"],["63384.41000000","0.00000000"],["63384.40000000","0.00000000"],["63384.31000000","0.00000000"],["63384.17000000","0.00000000"],["63383.97000000","0.00000000"],["63383.91000000","0.00000000"],["63383.31000000","0.00000000"],["63383.22000000","0.00000000"],["63383.11000000","0.00000000"],["63379.74000000","0.00410000"],["63377.48000000","0.00000000"],["63369.60000000","0.04353000"],["63366.69000000","0.00000000"],["63323.74000000","0.33120000"],["63323.65000000","0.00000000"],["63323.64000000","0.00000000"],["63323.55000000","0.00000000"],["63323.41000000","0.00000000"],["63323.31000000","0.00000000"],["63323.20000000","0.00000000"],["63323.06000000","0.00000000"],["63322.55000000","0.00000000"],["63322.45000000","0.00000000"],["63322.35000000","0.00000000"]],"a":[["63399.68000000","0.00000000"],["63401.94000000","0.00000000"],["63402.85000000","0.00410000"],["63407.89000000","0.00000000"],["63409.17000000","0.00000000"],["63410.17000000","0.03508000"],["63412.08000000","0.04352000"],["63441.55000000","0.00000000"],["63447.58000000","0.27107000"],["63513.21000000","0.00038000"]]}}
{"stream":"ethusd@depth","data":{"e":"depthUpdate","E":1785649929913,"s":"ETHUSD","U":3656118302,"u":3656118303,"b":[["1871.92000000","11.20360000"],["1871.91000000","0.00000000"],["1871.90000000","0.00000000"]],"a":[]}}
{"stream":"btcusd@depth","data":{"e":"depthUpdate","E":1785649930913,"s":"BTCUSD","U":4527244324,"u":4527244328,"b":[["63384.78000000","0.03150000"],["63384.77000000","0.00000000"],["63384.50000000","0.00000000"],["63324.02000000","0.33120000"],["63324.01000000","0.00000000"],["63323.74000000","0.00000000"]],"a":[["63401.23000000","0.00300000"]]}}
{"stream":"ethusd@depth","data":{"e":"depthUpdate","E":1785649930913,"s":"ETHUSD","U":3656118304,"u":3656118311,"b":[["1871.94000000","11.20350000"],["1871.93000000","0.00000000"],["1871.92000000","0.00000000"]],"a":[["1874.87000000","0.53330000"],["1874.95000000","1.56050000"],["1875.05000000","0.00000000"],["1875.48000000","0.14840000"],["1875.86000000","0.00000000"]]}}
{"stream":"btcusd@depth","data":{"e":"depthUpdate","E":1785649931913,"s":"BTCUSD","U":4527244329,"u":4527244332,"b":[["63386.31000000","0.00000000"],["63345.17000000","0.20667000"],["63209.09000000","0.00000000"]],"a":[["63552.00000000","0.00000000"]]}}
{"stream":"ethusd@depth","data":{"e":"depthUpdate","E":1785649931913,"s":"ETHUSD","U":3656118312,"u":3656118313,"b":[],"a":[["1875.05000000","0.14840000"],["1875.48000000","0.00000000"]]}}
{"stream":"btcusd@depth","data":{"e":"depthUpdate","E":1785649932913,"s":"BTCUSD","U":4527244333,"u":4527244335,"b":[["63387.75000000","0.00077000"],["63384.81000000","0.03150000"],["63384.78000000","0.00000000"],["63324.05000000","0.33120000"],["63324.02000000","0.00000000"]],"a":[]}}
{"stream":"ethusd@depth","data":{"e":"depthUpdate","E":1785649932913,"s":"ETHUSD","U":3656118314,"u":3656118315,"b":[["1874.21000000","0.13860000"],["1874.17000000","0.00000000"],["1871.95000000","11.20340000"],["1871.94000000","0.00000000"]],"a":[]}}
{"stream":"btcusd@depth","data":{"e":"depthUpdate","E":1785649933913,"s":"BTCUSD","U":4527244336,"u":4527244337,"b":[["63384.82000000","0.03150000"],["63384.81000000","0.00000000"],["63324.06000000","0.33120000"],["63324.05000000","0.00000000"]],"a":[]}}
{"stream":"ethusd@depth","data":{"e":"depthUpdate","E":1785649934913,"s":"ETHUSD","U":3656118316,"u":3656118353,"b":[["1874.24000000","0.13870000"],["1874.21000000","0.00000000"],["1873.94000000","1.47260000"],["1873.87000000","0.00000000"],["1873.63000000","0.00000000"],["1872.09000000","11.20270000"],["1872.01000000","0.00000000"],["1871.95000000","0.00000000"],["1867.32000000","7.00450000"],["1867.30000000","7.05650000"],["1865.80000000","0.00000000"],["1865.73000000","0.00000000"]],"a":[["1874.52000000","0.00000000"],["1874.53000000","1.06680000"],["1874.57000000","0.00000000"],["1874.84000000","0.00000000"],["1874.86000000","0.00000000"],["1874.90000000","0.13820000"],["1874.94000000","0.05700000"],["1875.01000000","0.00000000"],["1875.12000000","0.00000000"],["1875.18000000","0.46850000"],["1875.30000000","1.65600000"],["1875.39000000","0.00000000"],["1875.56000000","2.66600000"],["1875.73000000","0.00000000"],["1876.72000000","0.00000000"],["1876.79000000","8.95150000"],["1876.80000000","0.00000000"],["1876.84000000","0.00000000"],["1876.94000000","0.00000000"],["1876.95000000","0.00000000"],["1876.97000000","0.00000000"],["1882.18000000","0.00000000"],["1882.26000000","0.00000000"],["1882.28000000","0.00000000"],["1882.30000000","7.02150000"],["1883.48000000","8.95100000"],["1883.55000000","9.00420000"]]}}
{"stream":"btcusd@depth","data":{"e":"depthUpdate","E":1785649935913,"s":"BTCUSD","U":4527244338,"u":4527244339,"b":[],"a":[["63404.46000000","0.00000000"],["63410.97000000","0.00626000"]]}}
