{"channel":"status","type":"update","data":[{"version":"2.0.10","system":"online","api_version":"v2","connection_id":11278572044473960836}]}
{"method":"subscribe","result":{"channel":"book","depth":10,"snapshot":true,"symbol":"BTC/USD"},"success":true,"time_in":"2026-08-02T05:43:30.758130Z","time_out":"2026-08-02T05:43:30.758175Z"}
{"method":"subscribe","result":{"channel":"book","depth":10,"snapshot":true,"symbol":"ETH/USD"},"success":true,"time_in":"2026-08-02T05:43:30.758130Z","time_out":"2026-08-02T05:43:30.758175Z"}
{"method":"subscribe","result":{"channel":"trade","snapshot":false,"symbol":"BTC/USD"},"success":true,"time_in":"2026-08-02T05:43:30.770018Z","time_out":"2026-08-02T05:43:30.770049Z"}
{"method":"subscribe","result":{"channel":"trade","snapshot":false,"symbol":"ETH/USD"},"success":true,"time_in":"2026-08-02T05:43:30.770018Z","time_out":"2026-08-02T05:43:30.770049Z"}
{"channel":"book","type":"snapshot","data":[{"symbol":"BTC/USD","bids":[{"price":63348.4,"qty":0.12158347},{"price":63348.1,"qty":0.78928964},{"price":63347.8,"qty":0.00005100},{"price":63347.2,"qty":0.78930017},{"price":63345.8,"qty":0.01511055},{"price":63345.1,"qty":0.05960180},{"price":63344.7,"qty":0.00005100},{"price":63344.5,"qty":0.78933399},{"price":63343.0,"qty":0.00157871},{"price":63342.8,"qty":0.01000000}],"asks":[{"price":63348.5,"qty":0.03310673},{"price":63350.2,"qty":0.01534274},{"price":63350.7,"qty":0.00126056},{"price":63350.8,"qty":0.05019216},{"price":63350.9,"qty":0.00005100},{"price":63351.6,"qty":0.33270772},{"price":63351.7,"qty":0.60995873},{"price":63352.7,"qty":0.50464000},{"price":63354.1,"qty":0.00005100},{"price":63356.6,"qty":0.23557134}],"checksum":2976216659,"timestamp":"2026-08-02T05:43:31.000562Z"}]}
{"channel":"book","type":"snapshot","data":[{"symbol":"ETH/USD","bids":[{"price":1873.38,"qty":1.60630847},{"price":1873.36,"qty":2.66899270},{"price":1873.30,"qty":0.50000000},{"price":1873.21,"qty":0.02372606},{"price":1873.20,"qty":1.12107625},{"price":1873.19,"qty":0.41450200},{"price":1873.17,"qty":1.48852013},{"price":1873.10,"qty":2.00000000},{"price":1873.09,"qty":0.01332630},{"price":1873.08,"qty":8.51649082}],"asks":[{"price":1873.40,"qty":0.75143648},{"price":1873.42,"qty":0.01439800},{"price":1873.43,"qty":0.47001888},{"price":1873.44,"qty":2.90159344},{"price":1873.51,"qty":1.60630847},{"price":1873.52,"qty":0.17654172},{"price":1873.58,"qty":0.00805100},{"price":1873.59,"qty":1.26441371},{"price":1873.60,"qty":2.85800239},{"price":1873.63,"qty":0.03993899}],"checksum":2074836580,"timestamp":"2026-08-02T05:43:31.007833Z"}]}
{"channel":"book","type":"update","data":[{"symbol":"ETH/USD","bids":[],"asks":[{"price":1873.59,"qty":0.85311371}],"checksum":2839908831,"timestamp":"2026-08-02T05:43:31.066741Z"}]}
{"channel":"book","type":"update","data":[{"symbol":"BTC/USD","bids":[{"price":63348.4,"qty":0.17658347}],"asks":[],"checksum":3342699774,"timestamp":"2026-08-02T05:43:31.196635Z"}]}
{"channel":"book","type":"update","data":[{"symbol":"BTC/USD","bids":[],"asks":[{"price":63351.6,"qty":0.00000000},{"price":63356.7,"qty":0.78918373}],"checksum":3161278731,"timestamp":"2026-08-02T05:43:31.208168Z"}]}
{"channel":"book","type":"update","data":[{"symbol":"BTC/USD","bids":[],"asks":[{"price":63356.7,"qty":0.00000000},{"price":63357.0,"qty":0.00157836}],"checksum":3572938338,"timestamp":"2026-08-02T05:43:31.211728Z"}]}
{"channel":"book","type":"update","data":[{"symbol":"BTC/USD","bids":[{"price":63348.4,"qty":0.18823826}],"asks":[],"checksum":1612541452,"timestamp":"2026-08-02T05:43:31.211960Z"}]}
{"channel":"book","type":"update","data":[{"symbol":"BTC/USD","bids":[],"asks":[{"price":63348.5,"qty":0.00118252}],"checksum":2063043250,"timestamp":"2026-08-02T05:43:31.212166Z"}]}
{"channel":"book","type":"update","data":[{"symbol":"BTC/USD","bids":[],"asks":[{"price":63356.6,"qty":0.00000000},{"price":63357.1,"qty":0.29127085}],"checksum":2385494899,"timestamp":"2026-08-02T05:43:31.213008Z"}]}
{"channel":"book","type":"update","data":[{"symbol":"BTC/USD","bids":[],"asks":[{"price":63357.1,"qty":0.06387237}],"checksum":4097655252,"timestamp":"2026-08-02T05:43:31.213659Z"}]}
{"channel":"book","type":"update","data":[{"symbol":"BTC/USD","bids":[],"asks":[{"price":63357.1,"qty":0.58935788}],"checksum":2535712408,"timestamp":"2026-08-02T05:43:31.215333Z"}]}
{"channel":"book","type":"update","data":[{"symbol":"BTC/USD","bids":[],"asks":[{"price":63357.1,"qty":0.84854794}],"checksum":3045895480,"timestamp":"2026-08-02T05:43:31.215350Z"}]}
{"channel":"book","type":"update","data":[{"symbol":"BTC/USD","bids":[],"asks":[{"price":63357.1,"qty":0.78467557}],"checksum":3360407175,"timestamp":"2026-08-02T05:43:31.215432Z"}]}
{"channel":"book","type":"update","data":[{"symbol":"BTC/USD","bids":[],"asks":[{"price":63357.1,"qty":0.52548551}],"checksum":1885955025,"timestamp":"2026-08-02T05:43:31.215580Z"}]}
{"channel":"book","type":"update","data":[{"symbol":"BTC/USD","bids":[],"asks":[{"price":63348.5,"qty":0.03310673}],"checksum":1787004783,"timestamp":"2026-08-02T05:43:31.217183Z"}]}
{"channel":"book","type":"update","data":[{"symbol":"BTC/USD","bids":[{"price":63348.4,"qty":0.17658347}],"asks":[],"checksum":3731382017,"timestamp":"2026-08-02T05:43:31.217424Z"}]}
{"channel":"book","type":"update","data":[{"symbol":"BTC/USD","bids":[{"price":63348.4,"qty":0.12158347}],"asks":[],"checksum":2821760428,"timestamp":"2026-08-02T05:43:31.218197Z"}]}
{"channel":"book","type":"update","data":[{"symbol":"ETH/USD","bids":[{"price":1873.38,"qty":2.01760847}],"asks":[],"checksum":701361785,"timestamp":"2026-08-02T05:43:31.254503Z"}]}
{"channel":"book","type":"update","data":[{"symbol":"ETH/USD","bids":[{"price":1873.39,"qty":0.41130000}],"asks":[],"checksum":3969193198,"timestamp":"2026-08-02T05:43:31.255670Z"}]}
{"channel":"book","type":"update","data":[{"symbol":"BTC/USD","bids":[],"asks":[{"price":63357.0,"qty":0.00000000},{"price":63357.3,"qty":0.00005100}],"checksum":1786265959,"timestamp":"2026-08-02T05:43:31.264681Z"}]}
{"channel":"book","type":"update","data":[{"symbol":"BTC/USD","bids":[],"asks":[{"price":63350.2,"qty":0.00000000},{"price":63357.4,"qty":0.78917399}],"checksum":4080762599,"timestamp":"2026-08-02T05:43:31.268021Z"}]}
{"channel":"book","type":"update","data":[{"symbol":"BTC/USD","bids":[],"asks":[{"price":63351.6,"qty":0.01517145}],"checksum":1978699305,"timestamp":"2026-08-02T05:43:31.269470Z"}]}
{"channel":"book","type":"update","data":[{"symbol":"BTC/USD","bids":[],"asks":[{"price":63350.7,"qty":0.00000000},{"price":63357.4,"qty":0.78917399}],"checksum":3139950489,"timestamp":"2026-08-02T05:43:31.276065Z"}]}
{"channel":"book","type":"update","data":[{"symbol":"BTC/USD","bids":[{"price":63348.4,"qty":0.17658347}],"asks":[],"checksum":3447663924,"timestamp":"2026-08-02T05:43:31.278835Z"}]}
{"channel":"book","type":"update","data":[{"symbol":"BTC/USD","bids":[{"price":63347.1,"qty":0.01511055}],"asks":[],"checksum":4176225769,"timestamp":"2026-08-02T05:43:31.284512Z"}]}
{"channel":"book","type":"update","data":[{"symbol":"BTC/USD","bids":[{"price":63345.8,"qty":0.00000000},{"price":63342.8,"qty":0.01000000}],"asks":[],"checksum":1572431701,"timestamp":"2026-08-02T05:43:31.284550Z"}]}
{"channel":"book","type":"update","data":[{"symbol":"BTC/USD","bids":[],"asks":[{"price":63350.7,"qty":0.00126056}],"checksum":2473475813,"timestamp":"2026-08-02T05:43:31.398476Z"}]}
{"channel":"book","type":"update","data":[{"symbol":"ETH/USD","bids":[{"price":1873.38,"qty":1.60630847}],"asks":[],"checksum":1100055698,"timestamp":"2026-08-02T05:43:31.407256Z"}]}
{"channel":"book","type":"update","data":[{"symbol":"ETH/USD","bids":[{"price":1873.38,"qty":0.00000000},{"price":1873.08,"qty":8.51649082},{"price":1873.37,"qty":1.60630847}],"asks":[],"checksum":3223699218,"timestamp":"2026-08-02T05:43:31.408453Z"}]}
{"channel":"book","type":"update","data":[{"symbol":"ETH/USD","bids":[{"price":1873.39,"qty":0.00000000},{"price":1873.08,"qty":8.51649082}],"asks":[],"checksum":2682560284,"timestamp":"2026-08-02T05:43:31.408492Z"}]}
{"channel":"book","type":"update","data":[{"symbol":"ETH/USD","bids":[{"price":1873.37,"qty":2.01760847}],"asks":[],"checksum":527229114,"timestamp":"2026-08-02T05:43:31.414969Z"}]}
{"channel":"book","type":"update","data":[{"symbol":"ETH/USD","bids":[{"price":1873.37,"qty":0.41130000},{"price":1873.38,"qty":1.60630847}],"asks":[],"checksum":1288700575,"timestamp":"2026-08-02T05:43:31.416127Z"}]}
{"channel":"book","type":"update","data":[{"symbol":"ETH/USD","bids":[{"price":1873.25,"qty":14.94577946}],"asks":[],"checksum":3915149752,"timestamp":"2026-08-02T05:43:31.545079Z"}]}
{"channel":"book","type":"update","data":[{"symbol":"ETH/USD","bids":[{"price":1873.21,"qty":0.00000000},{"price":1873.09,"qty":0.01332630},{"price":1873.26,"qty":0.02372543}],"asks":[],"checksum":4168374160,"timestamp":"2026-08-02T05:43:31.546758Z"}]}
{"channel":"book","type":"update","data":[{"symbol":"BTC/USD","bids":[{"price":63348.4,"qty":0.18823826}],"asks":[],"checksum":663086731,"timestamp":"2026-08-02T05:43:31.549017Z"}]}
{"channel":"book","type":"update","data":[{"symbol":"BTC/USD","bids":[],"asks":[{"price":63348.5,"qty":0.00118252}],"checksum":2730040164,"timestamp":"2026-08-02T05:43:31.549262Z"}]}
{"channel":"book","type":"update","data":[{"symbol":"BTC/USD","bids":[],"asks":[{"price":63350.6,"qty":0.11000000}],"checksum":2550815898,"timestamp":"2026-08-02T05:43:31.550780Z"}]}
{"channel":"book","type":"update","data":[{"symbol":"ETH/USD","bids":[{"price":1873.38,"qty":2.01760847}],"asks":[],"checksum":3230900442,"timestamp":"2026-08-02T05:43:31.565806Z"}]}
{"channel":"book","type":"update","data":[{"symbol":"ETH/USD","bids":[{"price":1873.37,"qty":0.00000000},{"price":1873.09,"qty":0.01332630}],"asks":[],"checksum":487720261,"timestamp":"2026-08-02T05:43:31.566719Z"}]}
{"channel":"book","type":"update","data":[{"symbol":"BTC/USD","bids":[],"asks":[{"price":63350.7,"qty":0.00000000},{"price":63357.3,"qty":0.00005100},{"price":63350.5,"qty":0.00126056}],"checksum":3705028824,"timestamp":"2026-08-02T05:43:31.567679Z"}]}
{"channel":"book","type":"update","data":[{"symbol":"BTC/USD","bids":[{"price":63345.0,"qty":0.00157866}],"asks":[],"checksum":871859027,"timestamp":"2026-08-02T05:43:31.604755Z"}]}
{"channel":"book","type":"update","data":[{"symbol":"BTC/USD","bids":[],"asks":[{"price":63350.7,"qty":0.01517145}],"checksum":355129017,"timestamp":"2026-08-02T05:43:31.622308Z"}]}
{"channel":"book","type":"update","data":[{"symbol":"BTC/USD","bids":[],"asks":[{"price":63351.6,"qty":0.00000000},{"price":63357.1,"qty":0.52548551}],"checksum":2434876386,"timestamp":"2026-08-02T05:43:31.622551Z"}]}
{"channel":"heartbeat"}
{"channel":"book","type":"update","data":[{"symbol":"BTC/USD","bids":[{"price":63347.1,"qty":0.00000000},{"price":63342.8,"qty":0.01000000}],"asks":[],"checksum":1674968709,"timestamp":"2026-08-02T05:43:32.025343Z"}]}
{"channel":"book","type":"update","data":[{"symbol":"BTC/USD","bids":[{"price":63345.7,"qty":0.01511055}],"asks":[],"checksum":2959159551,"timestamp":"2026-08-02T05:43:32.026557Z"}]}
{"channel":"book","type":"update","data":[{"symbol":"BTC/USD","bids":[],"asks":[{"price":63350.4,"qty":0.11000000}],"checksum":25196992,"timestamp":"2026-08-02T05:43:32.026988Z"}]}
{"channel":"book","type":"update","data":[{"symbol":"BTC/USD","bids":[],"asks":[{"price":63350.6,"qty":0.00000000},{"price":63357.1,"qty":0.52548551}],"checksum":2789899574,"timestamp":"2026-08-02T05:43:32.128047Z"}]}
{"channel":"book","type":"update","data":[{"symbol":"BTC/USD","bids":[],"asks":[{"price":63350.5,"qty":0.00000000},{"price":63357.3,"qty":0.00005100},{"price":63357.0,"qty":0.00126056}],"checksum":2599169823,"timestamp":"2026-08-02T05:43:32.130277Z"}]}
{"channel":"book","type":"update","data":[{"symbol":"ETH/USD","bids":[{"price":1873.20,"qty":1.06769166}],"asks":[],"checksum":3240669688,"timestamp":"2026-08-02T05:43:32.507981Z"}]}
{"channel":"heartbeat"}
{"channel":"book","type":"update","data":[{"symbol":"ETH/USD","bids":[{"price":1873.38,"qty":1.60630847}],"asks":[],"checksum":4263329626,"timestamp":"2026-08-02T05:43:32.731052Z"}]}
{"channel":"book","type":"update","data":[{"symbol":"BTC/USD","bids":[],"asks":[{"price":63357.0,"qty":0.00000000},{"price":63357.3,"qty":0.00005100},{"price":63351.6,"qty":0.00126056}],"checksum":750784229,"timestamp":"2026-08-02T05:43:33.234904Z"}]}
{"channel":"book","type":"update","data":[{"symbol":"BTC/USD","bids":[],"asks":[{"price":63351.6,"qty":0.00000000},{"price":63357.3,"qty":0.00005100},{"price":63350.3,"qty":0.00126056}],"checksum":2402630370,"timestamp":"2026-08-02T05:43:33.335141Z"}]}
{"channel":"book","type":"update","data":[{"symbol":"BTC/USD","bids":[],"asks":[{"price":63350.2,"qty":0.11000000}],"checksum":2679640983,"timestamp":"2026-08-02T05:43:33.336632Z"}]}
{"channel":"book","type":"update","data":[{"symbol":"BTC/USD","bids":[],"asks":[{"price":63348.5,"qty":0.03310673}],"checksum":3011209208,"timestamp":"2026-08-02T05:43:33.340482Z"}]}
{"channel":"book","type":"update","data":[{"symbol":"BTC/USD","bids":[{"price":63348.4,"qty":0.17658347}],"asks":[],"checksum":1394425348,"timestamp":"2026-08-02T05:43:33.340652Z"}]}
{"channel":"book","type":"update","data":[{"symbol":"BTC/USD","bids":[],"asks":[{"price":63350.3,"qty":0.00000000},{"price":63357.1,"qty":0.52548551},{"price":63350.1,"qty":0.00126056}],"checksum":472053846,"timestamp":"2026-08-02T05:43:33.342424Z"}]}
{"channel":"book","type":"update","data":[{"symbol":"BTC/USD","bids":[],"asks":[{"price":63350.4,"qty":0.00000000},{"price":63357.1,"qty":0.52548551}],"checksum":2895058265,"timestamp":"2026-08-02T05:43:33.437621Z"}]}
{"channel":"book","type":"update","data":[{"symbol":"BTC/USD","bids":[{"price":63348.4,"qty":0.18823826}],"asks":[],"checksum":1290357925,"timestamp":"2026-08-02T05:43:33.441066Z"}]}
{"channel":"book","type":"update","data":[{"symbol":"BTC/USD","bids":[],"asks":[{"price":63348.5,"qty":0.00118252}],"checksum":1613379786,"timestamp":"2026-08-02T05:43:33.441539Z"}]}
{"channel":"book","type":"update","data":[{"symbol":"BTC/USD","bids":[],"asks":[{"price":63350.0,"qty":0.11000000}],"checksum":1745507641,"timestamp":"2026-08-02T05:43:33.443020Z"}]}
{"channel":"book","type":"update","data":[{"symbol":"BTC/USD","bids":[],"asks":[{"price":63348.5,"qty":0.03310673}],"checksum":1154031958,"timestamp":"2026-08-02T05:43:33.446443Z"}]}
{"channel":"book","type":"update","data":[{"symbol":"BTC/USD","bids":[{"price":63348.4,"qty":0.17658347}],"asks":[],"checksum":2762963114,"timestamp":"2026-08-02T05:43:33.446671Z"}]}
{"channel":"book","type":"update","data":[{"symbol":"BTC/USD","bids":[],"asks":[{"price":63350.1,"qty":0.00000000},{"price":63357.1,"qty":0.52548551},{"price":63351.6,"qty":0.00126056}],"checksum":3819508264,"timestamp":"2026-08-02T05:43:33.496002Z"}]}
{"channel":"book","type":"update","data":[{"symbol":"BTC/USD","bids":[],"asks":[{"price":63350.2,"qty":0.00000000},{"price":63357.1,"qty":0.52548551}],"checksum":1521233489,"timestamp":"2026-08-02T05:43:33.544010Z"}]}
{"channel":"book","type":"update","data":[{"symbol":"BTC/USD","bids":[],"asks":[{"price":63348.5,"qty":0.00118252}],"checksum":1987009086,"timestamp":"2026-08-02T05:43:33.547204Z"}]}
{"channel":"book","type":"update","data":[{"symbol":"BTC/USD","bids":[{"price":63348.4,"qty":0.18823826}],"asks":[],"checksum":2517173186,"timestamp":"2026-08-02T05:43:33.547256Z"}]}
{"channel":"heartbeat"}
{"channel":"book","type":"update","data":[{"symbol":"BTC/USD","bids":[],"asks":[{"price":63350.8,"qty":0.00000000},{"price":63357.3,"qty":0.00005100}],"checksum":565999161,"timestamp":"2026-08-02T05:43:33.823939Z"}]}
{"channel":"book","type":"update","data":[{"symbol":"BTC/USD","bids":[],"asks":[{"price":63350.0,"qty":0.00000000},{"price":63357.4,"qty":0.78917399}],"checksum":3924554360,"timestamp":"2026-08-02T05:43:33.825269Z"}]}
{"channel":"book","type":"update","data":[{"symbol":"BTC/USD","bids":[],"asks":[{"price":63350.6,"qty":0.11000000}],"checksum":1670683895,"timestamp":"2026-08-02T05:43:33.825577Z"}]}
{"channel":"book","type":"update","data":[{"symbol":"BTC/USD","bids":[],"asks":[{"price":63351.5,"qty":0.05019216}],"checksum":973485033,"timestamp":"2026-08-02T05:43:33.825711Z"}]}
{"channel":"book","type":"update","data":[{"symbol":"BTC/USD","bids":[{"price":63348.4,"qty":0.17658347}],"asks":[],"checksum":3663751701,"timestamp":"2026-08-02T05:43:33.825749Z"}]}
{"channel":"book","type":"update","data":[{"symbol":"BTC/USD","bids":[],"asks":[{"price":63348.5,"qty":0.03310673}],"checksum":4137885306,"timestamp":"2026-08-02T05:43:33.825966Z"}]}
{"channel":"book","type":"update","data":[{"symbol":"BTC/USD","bids":[{"price":63348.4,"qty":0.12158347}],"asks":[],"checksum":1914184506,"timestamp":"2026-08-02T05:43:33.879807Z"}]}
{"channel":"book","type":"update","data":[{"symbol":"BTC/USD","bids":[],"asks":[{"price":63351.6,"qty":0.00000000},{"price":63357.3,"qty":0.00005100},{"price":63350.5,"qty":0.00126056}],"checksum":523150343,"timestamp":"2026-08-02T05:43:33.881797Z"}]}
{"channel":"book","type":"update","data":[{"symbol":"BTC/USD","bids":[],"asks":[{"price":63351.5,"qty":0.00000000},{"price":63357.3,"qty":0.00005100},{"price":63351.6,"qty":0.05019216}],"checksum":592533861,"timestamp":"2026-08-02T05:43:33.885621Z"}]}
{"channel":"book","type":"update","data":[{"symbol":"ETH/USD","bids":[{"price":1873.11,"qty":0.05338715}],"asks":[],"checksum":1249131907,"timestamp":"2026-08-02T05:43:34.659184Z"}]}
{"channel":"heartbeat"}
{"channel":"book","type":"update","data":[{"symbol":"ETH/USD","bids":[{"price":1873.17,"qty":0.73564352}],"asks":[],"checksum":884376601,"timestamp":"2026-08-02T05:43:35.080171Z"}]}
{"channel":"book","type":"update","data":[{"symbol":"ETH/USD","bids":[],"asks":[{"price":1873.40,"qty":0.00000000},{"price":1873.64,"qty":6.13208319},{"price":1873.46,"qty":1.60156782}],"checksum":3507054700,"timestamp":"2026-08-02T05:43:35.107384Z"}]}
{"channel":"book","type":"update","data":[{"symbol":"ETH/USD","bids":[],"asks":[{"price":1873.42,"qty":1.31439800}],"checksum":1929403071,"timestamp":"2026-08-02T05:43:35.108967Z"}]}
{"channel":"book","type":"update","data":[{"symbol":"ETH/USD","bids":[],"asks":[{"price":1873.42,"qty":1.30000000},{"price":1873.41,"qty":0.01439800}],"checksum":1807128032,"timestamp":"2026-08-02T05:43:35.110177Z"}]}
{"channel":"book","type":"update","data":[{"symbol":"ETH/USD","bids":[],"asks":[{"price":1873.41,"qty":0.48441688}],"checksum":1576505897,"timestamp":"2026-08-02T05:43:35.110423Z"}]}
{"channel":"book","type":"update","data":[{"symbol":"ETH/USD","bids":[],"asks":[{"price":1873.44,"qty":1.60159344}],"checksum":1215189413,"timestamp":"2026-08-02T05:43:35.209951Z"}]}
{"channel":"book","type":"update","data":[{"symbol":"ETH/USD","bids":[],"asks":[{"price":1873.43,"qty":0.00000000},{"price":1873.63,"qty":0.03993899}],"checksum":1840382468,"timestamp":"2026-08-02T05:43:35.211571Z"}]}
{"channel":"book","type":"update","data":[{"symbol":"ETH/USD","bids":[{"price":1873.38,"qty":2.01760847}],"asks":[],"checksum":3980033442,"timestamp":"2026-08-02T05:43:35.458401Z"}]}
{"channel":"book","type":"update","data":[{"symbol":"ETH/USD","bids":[{"price":1873.38,"qty":1.60630847}],"asks":[],"checksum":1840382468,"timestamp":"2026-08-02T05:43:35.459358Z"}]}
{"channel":"book","type":"update","data":[{"symbol":"ETH/USD","bids":[{"price":1873.39,"qty":0.41130000}],"asks":[],"checksum":1246886698,"timestamp":"2026-08-02T05:43:35.460855Z"}]}
{"channel":"book","type":"update","data":[{"symbol":"ETH/USD","bids":[{"price":1873.38,"qty":0.00000000},{"price":1873.10,"qty":2.00000000},{"price":1873.37,"qty":1.60630847}],"asks":[],"checksum":3420831914,"timestamp":"2026-08-02T05:43:35.462037Z"}]}
{"channel":"heartbeat"}
{"channel":"book","type":"update","data":[{"symbol":"BTC/USD","bids":[],"asks":[{"price":63356.7,"qty":0.78918361}],"checksum":2423670469,"timestamp":"2026-08-02T05:43:35.914025Z"}]}
{"channel":"book","type":"update","data":[{"symbol":"BTC/USD","bids":[],"asks":[{"price":63351.6,"qty":0.38289988}],"checksum":373593521,"timestamp":"2026-08-02T05:43:35.915682Z"}]}
{"channel":"book","type":"update","data":[{"symbol":"BTC/USD","bids":[{"price":63348.4,"qty":0.13323826}],"asks":[],"checksum":833656791,"timestamp":"2026-08-02T05:43:35.916277Z"}]}
{"channel":"book","type":"update","data":[{"symbol":"BTC/USD","bids":[],"asks":[{"price":63348.5,"qty":0.00118252}],"checksum":3968936042,"timestamp":"2026-08-02T05:43:35.916509Z"}]}
{"channel":"book","type":"update","data":[{"symbol":"BTC/USD","bids":[],"asks":[{"price":63351.6,"qty":0.33270772},{"price":63351.5,"qty":0.05019216}],"checksum":1205620475,"timestamp":"2026-08-02T05:43:35.916961Z"}]}
{"channel":"book","type":"update","data":[{"symbol":"BTC/USD","bids":[],"asks":[{"price":63350.4,"qty":0.11000000}],"checksum":2427038893,"timestamp":"2026-08-02T05:43:35.918245Z"}]}
{"channel":"book","type":"update","data":[{"symbol":"BTC/USD","bids":[],"asks":[{"price":63348.5,"qty":0.03310673}],"checksum":1914397466,"timestamp":"2026-08-02T05:43:35.919327Z"}]}
{"channel":"book","type":"update","data":[{"symbol":"BTC/USD","bids":[{"price":63348.4,"qty":0.12158347}],"asks":[],"checksum":1441751420,"timestamp":"2026-08-02T05:43:35.919643Z"}]}
{"channel":"book","type":"update","data":[{"symbol":"BTC/USD","bids":[],"asks":[{"price":63350.5,"qty":0.00000000},{"price":63354.1,"qty":0.00005100},{"price":63350.3,"qty":0.00126056}],"checksum":1662593442,"timestamp":"2026-08-02T05:43:35.921378Z"}]}
{"channel":"book","type":"update","data":[{"symbol":"BTC/USD","bids":[],"asks":[{"price":63350.6,"qty":0.00000000},{"price":63354.1,"qty":0.00005100}],"checksum":1941910255,"timestamp":"2026-08-02T05:43:36.019166Z"}]}
{"channel":"book","type":"update","data":[{"symbol":"ETH/USD","bids":[{"price":1873.39,"qty":0.00000000},{"price":1873.10,"qty":2.00000000}],"asks":[],"checksum":1527975111,"timestamp":"2026-08-02T05:43:36.028090Z"}]}
{"channel":"book","type":"update","data":[{"symbol":"BTC/USD","bids":[],"asks":[{"price":63349.4,"qty":0.01517145}],"checksum":2719976097,"timestamp":"2026-08-02T05:43:36.131029Z"}]}
{"channel":"book","type":"update","data":[{"symbol":"BTC/USD","bids":[],"asks":[{"price":63350.7,"qty":0.00000000},{"price":63354.1,"qty":0.00005100}],"checksum":3556237800,"timestamp":"2026-08-02T05:43:36.131264Z"}]}
{"channel":"book","type":"update","data":[{"symbol":"ETH/USD","bids":[{"price":1873.38,"qty":0.41130000}],"asks":[],"checksum":729859693,"timestamp":"2026-08-02T05:43:36.588694Z"}]}
{"channel":"book","type":"update","data":[{"symbol":"ETH/USD","bids":[{"price":1873.37,"qty":0.00000000},{"price":1873.10,"qty":2.00000000},{"price":1873.38,"qty":2.01760847}],"asks":[],"checksum":3980033442,"timestamp":"2026-08-02T05:43:36.589864Z"}]}
{"channel":"book","type":"update","data":[{"symbol":"ETH/USD","bids":[{"price":1873.38,"qty":1.60630847}],"asks":[],"checksum":1840382468,"timestamp":"2026-08-02T05:43:36.655196Z"}]}
{"channel":"book","type":"update","data":[{"symbol":"ETH/USD","bids":[{"price":1873.39,"qty":0.41130000}],"asks":[],"checksum":1246886698,"timestamp":"2026-08-02T05:43:36.655213Z"}]}
{"channel":"book","type":"update","data":[{"symbol":"ETH/USD","bids":[{"price":1873.38,"qty":0.00000000},{"price":1873.10,"qty":2.00000000},{"price":1873.37,"qty":1.60630847}],"asks":[],"checksum":3420831914,"timestamp":"2026-08-02T05:43:36.656496Z"}]}
{"channel":"heartbeat"}
{"channel":"book","type":"update","data":[{"symbol":"BTC/USD","bids":[],"asks":[{"price":63351.7,"qty":0.00000000},{"price":63356.7,"qty":0.78918361}],"checksum":4030602480,"timestamp":"2026-08-02T05:43:36.855785Z"}]}
{"channel":"book","type":"update","data":[{"symbol":"BTC/USD","bids":[],"asks":[{"price":63351.6,"qty":0.00000000},{"price":63357.0,"qty":0.00157836}],"checksum":3046050985,"timestamp":"2026-08-02T05:43:36.857967Z"}]}
{"channel":"book","type":"update","data":[{"symbol":"BTC/USD","bids":[],"asks":[{"price":63352.6,"qty":0.15063504}],"checksum":754618050,"timestamp":"2026-08-02T05:43:36.858988Z"}]}
{"channel":"book","type":"update","data":[{"symbol":"BTC/USD","bids":[],"asks":[{"price":63351.5,"qty":0.00000000},{"price":63357.0,"qty":0.00157836},{"price":63352.6,"qty":0.20082720}],"checksum":3608391842,"timestamp":"2026-08-02T05:43:36.859364Z"}]}
{"channel":"book","type":"update","data":[{"symbol":"BTC/USD","bids":[],"asks":[{"price":63352.6,"qty":0.15063504},{"price":63352.5,"qty":0.05019216}],"checksum":2407199051,"timestamp":"2026-08-02T05:43:36.860383Z"}]}
{"channel":"book","type":"update","data":[{"symbol":"BTC/USD","bids":[],"asks":[{"price":63356.6,"qty":0.23557131}],"checksum":3594312640,"timestamp":"2026-08-02T05:43:36.862270Z"}]}
{"channel":"book","type":"update","data":[{"symbol":"BTC/USD","bids":[],"asks":[{"price":63350.3,"qty":0.00000000},{"price":63356.7,"qty":0.78918361},{"price":63352.4,"qty":0.00126056}],"checksum":1392468374,"timestamp":"2026-08-02T05:43:36.935511Z"}]}
{"channel":"book","type":"update","data":[{"symbol":"ETH/USD","bids":[{"price":1873.39,"qty":0.00000000},{"price":1873.10,"qty":2.00000000}],"asks":[],"checksum":1527975111,"timestamp":"2026-08-02T05:43:37.048080Z"}]}
{"channel":"book","type":"update","data":[{"symbol":"ETH/USD","bids":[{"price":1873.37,"qty":2.01760847}],"asks":[],"checksum":3684397921,"timestamp":"2026-08-02T05:43:37.087460Z"}]}
{"channel":"book","type":"update","data":[{"symbol":"ETH/USD","bids":[{"price":1873.37,"qty":0.41130000},{"price":1873.38,"qty":1.60630847}],"asks":[],"checksum":1192262951,"timestamp":"2026-08-02T05:43:37.088494Z"}]}
{"channel":"book","type":"update","data":[{"symbol":"BTC/USD","bids":[],"asks":[{"price":63352.5,"qty":0.00000000},{"price":63356.7,"qty":0.78918361},{"price":63352.3,"qty":0.05019216}],"checksum":1370873184,"timestamp":"2026-08-02T05:43:37.093078Z"}]}
{"channel":"book","type":"update","data":[{"symbol":"BTC/USD","bids":[],"asks":[{"price":63352.4,"qty":0.00000000},{"price":63356.7,"qty":0.78918361},{"price":63352.2,"qty":0.00126056}],"checksum":3102929164,"timestamp":"2026-08-02T05:43:37.109337Z"}]}
{"channel":"book","type":"update","data":[{"symbol":"ETH/USD","bids":[{"price":1873.38,"qty":2.01760847}],"asks":[],"checksum":2852655282,"timestamp":"2026-08-02T05:43:37.153945Z"}]}
{"channel":"book","type":"update","data":[{"symbol":"ETH/USD","bids":[{"price":1873.37,"qty":0.00000000},{"price":1873.10,"qty":2.00000000}],"asks":[],"checksum":3980033442,"timestamp":"2026-08-02T05:43:37.308098Z"}]}
{"channel":"book","type":"update","data":[{"symbol":"BTC/USD","bids":[],"asks":[{"price":63352.3,"qty":0.00000000},{"price":63356.7,"qty":0.78918361},{"price":63352.1,"qty":0.05019216}],"checksum":1861771485,"timestamp":"2026-08-02T05:43:37.320391Z"}]}
{"channel":"book","type":"update","data":[{"symbol":"BTC/USD","bids":[],"asks":[{"price":63351.4,"qty":0.74253867}],"checksum":3274549919,"timestamp":"2026-08-02T05:43:37.571434Z"}]}
{"channel":"book","type":"update","data":[{"symbol":"BTC/USD","bids":[],"asks":[{"price":63352.1,"qty":0.00000000},{"price":63356.6,"qty":0.23557131},{"price":63351.3,"qty":0.05019216}],"checksum":201347851,"timestamp":"2026-08-02T05:43:37.573017Z"}]}
{"channel":"book","type":"update","data":[{"symbol":"BTC/USD","bids":[],"asks":[{"price":63352.2,"qty":0.00000000},{"price":63356.6,"qty":0.23557131},{"price":63350.3,"qty":0.00126056}],"checksum":1902740207,"timestamp":"2026-08-02T05:43:37.575198Z"}]}
{"channel":"book","type":"update","data":[{"symbol":"ETH/USD","bids":[{"price":1873.39,"qty":0.41130000}],"asks":[],"checksum":3881134934,"timestamp":"2026-08-02T05:43:37.698680Z"}]}
{"channel":"heartbeat"}
{"channel":"book","type":"update","data":[{"symbol":"ETH/USD","bids":[{"price":1873.38,"qty":1.60630847}],"asks":[],"checksum":1246886698,"timestamp":"2026-08-02T05:43:37.853002Z"}]}
{"channel":"book","type":"update","data":[{"symbol":"ETH/USD","bids":[{"price":1873.38,"qty":0.00000000},{"price":1873.10,"qty":2.00000000},{"price":1873.37,"qty":1.60630847}],"asks":[],"checksum":3420831914,"timestamp":"2026-08-02T05:43:37.854515Z"}]}
{"channel":"heartbeat"}
{"channel":"book","type":"update","data":[{"symbol":"ETH/USD","bids":[{"price":1873.39,"qty":0.00000000},{"price":1873.10,"qty":2.00000000}],"asks":[],"checksum":1527975111,"timestamp":"2026-08-02T05:43:39.060158Z"}]}
{"channel":"trade","type":"update","data":[{"symbol":"BTC/USD","side":"sell","price":63348.4,"qty":0.00009417,"ord_type":"limit","trade_id":104622323,"timestamp":"2026-08-02T05:43:39.154709Z"}]}
{"channel":"book","type":"update","data":[{"symbol":"BTC/USD","bids":[{"price":63348.4,"qty":0.12148930}],"asks":[],"checksum":949691762,"timestamp":"2026-08-02T05:43:39.154709Z"}]}
{"channel":"book","type":"update","data":[{"symbol":"BTC/USD","bids":[],"asks":[{"price":63351.3,"qty":0.00000000},{"price":63356.6,"qty":0.23557131},{"price":63350.9,"qty":0.05024316}],"checksum":1049972208,"timestamp":"2026-08-02T05:43:39.156554Z"}]}
{"channel":"book","type":"update","data":[{"symbol":"BTC/USD","bids":[{"price":63348.4,"qty":0.17648930}],"asks":[],"checksum":3123605680,"timestamp":"2026-08-02T05:43:39.516212Z"}]}
{"channel":"book","type":"update","data":[{"symbol":"ETH/USD","bids":[{"price":1873.37,"qty":2.01760847}],"asks":[],"checksum":3684397921,"timestamp":"2026-08-02T05:43:39.605367Z"}]}
{"channel":"book","type":"update","data":[{"symbol":"ETH/USD","bids":[{"price":1873.37,"qty":0.41130000},{"price":1873.38,"qty":1.60630847}],"asks":[],"checksum":1192262951,"timestamp":"2026-08-02T05:43:39.606657Z"}]}
{"channel":"book","type":"update","data":[{"symbol":"ETH/USD","bids":[{"price":1873.38,"qty":2.01760847}],"asks":[],"checksum":2852655282,"timestamp":"2026-08-02T05:43:39.606678Z"}]}
{"channel":"book","type":"update","data":[{"symbol":"ETH/USD","bids":[],"asks":[{"price":1873.40,"qty":1.30000000}],"checksum":1768488334,"timestamp":"2026-08-02T05:43:39.606839Z"}]}
{"channel":"book","type":"update","data":[{"symbol":"ETH/USD","bids":[{"price":1873.39,"qty":0.41130000}],"asks":[],"checksum":1472718400,"timestamp":"2026-08-02T05:43:39.607972Z"}]}
{"channel":"book","type":"update","data":[{"symbol":"ETH/USD","bids":[{"price":1873.38,"qty":1.60630847}],"asks":[],"checksum":249159623,"timestamp":"2026-08-02T05:43:39.608724Z"}]}
{"channel":"book","type":"update","data":[{"symbol":"ETH/USD","bids":[],"asks":[{"price":1873.40,"qty":1.77001888}],"checksum":2641531158,"timestamp":"2026-08-02T05:43:39.610039Z"}]}
{"channel":"heartbeat"}
{"channel":"book","type":"update","data":[{"symbol":"ETH/USD","bids":[],"asks":[{"price":1873.42,"qty":0.00000000},{"price":1873.63,"qty":0.03993899}],"checksum":1909589270,"timestamp":"2026-08-02T05:43:39.708048Z"}]}
{"channel":"book","type":"update","data":[{"symbol":"ETH/USD","bids":[],"asks":[{"price":1873.41,"qty":0.47001888},{"price":1873.43,"qty":0.01439800}],"checksum":290656104,"timestamp":"2026-08-02T05:43:39.709327Z"}]}
{"channel":"book","type":"update","data":[{"symbol":"ETH/USD","bids":[],"asks":[{"price":1873.41,"qty":0.00000000},{"price":1873.63,"qty":0.03993899}],"checksum":3822790804,"timestamp":"2026-08-02T05:43:39.709400Z"}]}
{"channel":"book","type":"update","data":[{"symbol":"ETH/USD","bids":[{"price":1873.37,"qty":0.00000000},{"price":1873.11,"qty":0.05338715}],"asks":[],"checksum":860186006,"timestamp":"2026-08-02T05:43:39.759385Z"}]}
{"channel":"book","type":"update","data":[{"symbol":"ETH/USD","bids":[{"price":1873.38,"qty":0.00000000},{"price":1873.10,"qty":2.00000000},{"price":1873.37,"qty":1.60630847}],"asks":[],"checksum":3002162710,"timestamp":"2026-08-02T05:43:39.760597Z"}]}
{"channel":"book","type":"update","data":[{"symbol":"BTC/USD","bids":[{"price":63348.4,"qty":0.12148930}],"asks":[],"checksum":1049972208,"timestamp":"2026-08-02T05:43:40.461175Z"}]}
{"channel":"book","type":"update","data":[{"symbol":"BTC/USD","bids":[],"asks":[{"price":63352.6,"qty":0.00000000},{"price":63356.7,"qty":0.78918361}],"checksum":1003590537,"timestamp":"2026-08-02T05:43:40.462249Z"}]}
{"channel":"book","type":"update","data":[{"symbol":"BTC/USD","bids":[],"asks":[{"price":63350.3,"qty":0.03409556}],"checksum":4107711344,"timestamp":"2026-08-02T05:43:40.463860Z"}]}
{"channel":"book","type":"update","data":[{"symbol":"ETH/USD","bids":[{"price":1873.39,"qty":0.00000000},{"price":1873.10,"qty":2.00000000}],"asks":[],"checksum":2579359742,"timestamp":"2026-08-02T05:43:40.466095Z"}]}
{"channel":"book","type":"update","data":[{"symbol":"ETH/USD","bids":[],"asks":[{"price":1873.39,"qty":0.47001888}],"checksum":865093008,"timestamp":"2026-08-02T05:43:40.467632Z"}]}
{"channel":"book","type":"update","data":[{"symbol":"BTC/USD","bids":[],"asks":[{"price":63350.3,"qty":0.03283500},{"price":63350.2,"qty":0.00126056}],"checksum":3262126403,"timestamp":"2026-08-02T05:43:40.467995Z"}]}
{"channel":"book","type":"update","data":[{"symbol":"BTC/USD","bids":[{"price":63343.0,"qty":0.00000000},{"price":63342.8,"qty":0.01000000}],"asks":[],"checksum":3831493228,"timestamp":"2026-08-02T05:43:40.479567Z"}]}
{"channel":"book","type":"update","data":[{"symbol":"BTC/USD","bids":[{"price":63345.0,"qty":0.00000000},{"price":63342.4,"qty":0.01000000}],"asks":[],"checksum":3540672079,"timestamp":"2026-08-02T05:43:40.479633Z"}]}
{"channel":"book","type":"update","data":[{"symbol":"ETH/USD","bids":[],"asks":[{"price":1873.40,"qty":1.30000000}],"checksum":175975701,"timestamp":"2026-08-02T05:43:40.568696Z"}]}
{"channel":"heartbeat"}
{"channel":"book","type":"update","data":[{"symbol":"ETH/USD","bids":[],"asks":[{"price":1873.58,"qty":0.41935100}],"checksum":2162062879,"timestamp":"2026-08-02T05:43:40.958544Z"}]}
{"channel":"book","type":"update","data":[{"symbol":"ETH/USD","bids":[],"asks":[{"price":1873.58,"qty":0.00805100}],"checksum":175975701,"timestamp":"2026-08-02T05:43:41.068925Z"}]}
{"channel":"book","type":"update","data":[{"symbol":"ETH/USD","bids":[{"price":1873.36,"qty":0.00000000},{"price":1873.09,"qty":0.01332630}],"asks":[],"checksum":2087838813,"timestamp":"2026-08-02T05:43:41.085979Z"}]}
{"channel":"book","type":"update","data":[{"symbol":"ETH/USD","bids":[{"price":1873.37,"qty":0.00000000},{"price":1873.08,"qty":8.51649082},{"price":1873.31,"qty":1.60630847}],"asks":[],"checksum":1760771811,"timestamp":"2026-08-02T05:43:41.087568Z"}]}
{"channel":"book","type":"update","data":[{"symbol":"BTC/USD","bids":[],"asks":[{"price":63356.6,"qty":0.00000000},{"price":63357.0,"qty":0.00157836}],"checksum":2917186523,"timestamp":"2026-08-02T05:43:41.087640Z"}]}
{"channel":"book","type":"update","data":[{"symbol":"ETH/USD","bids":[{"price":1873.31,"qty":4.27537004}],"asks":[],"checksum":1176501695,"timestamp":"2026-08-02T05:43:41.087731Z"}]}
{"channel":"book","type":"update","data":[{"symbol":"BTC/USD","bids":[{"price":63344.5,"qty":0.00000000},{"price":63342.1,"qty":0.06224631}],"asks":[],"checksum":4211745294,"timestamp":"2026-08-02T05:43:41.088030Z"}]}
{"channel":"book","type":"update","data":[{"symbol":"BTC/USD","bids":[{"price":63347.2,"qty":0.00000000},{"price":63342.0,"qty":0.04894068}],"asks":[],"checksum":3938220340,"timestamp":"2026-08-02T05:43:41.088678Z"}]}
{"channel":"book","type":"update","data":[{"symbol":"ETH/USD","bids":[{"price":1873.19,"qty":0.00320200}],"asks":[],"checksum":3528275653,"timestamp":"2026-08-02T05:43:41.089028Z"}]}
{"channel":"book","type":"update","data":[{"symbol":"ETH/USD","bids":[{"price":1873.32,"qty":0.41130000}],"asks":[],"checksum":2038861924,"timestamp":"2026-08-02T05:43:41.089385Z"}]}
{"channel":"book","type":"update","data":[{"symbol":"BTC/USD","bids":[],"asks":[{"price":63351.3,"qty":0.37228283}],"checksum":1447618245,"timestamp":"2026-08-02T05:43:41.089447Z"}]}
{"channel":"book","type":"update","data":[{"symbol":"ETH/USD","bids":[{"price":1873.31,"qty":4.68667004}],"asks":[],"checksum":1388039830,"timestamp":"2026-08-02T05:43:41.089505Z"}]}
{"channel":"book","type":"update","data":[{"symbol":"ETH/USD","bids":[{"price":1873.26,"qty":0.00000000},{"price":1873.09,"qty":0.01332630},{"price":1873.32,"qty":0.43502467}],"asks":[],"checksum":4111610000,"timestamp":"2026-08-02T05:43:41.089950Z"}]}
{"channel":"book","type":"update","data":[{"symbol":"ETH/USD","bids":[{"price":1873.31,"qty":3.08036157},{"price":1873.32,"qty":2.04133314}],"asks":[],"checksum":3176374628,"timestamp":"2026-08-02T05:43:41.090412Z"}]}
{"channel":"book","type":"update","data":[{"symbol":"ETH/USD","bids":[{"price":1873.32,"qty":2.01760847},{"price":1873.33,"qty":0.02372454}],"asks":[],"checksum":3085179152,"timestamp":"2026-08-02T05:43:41.091525Z"}]}
{"channel":"book","type":"update","data":[{"symbol":"ETH/USD","bids":[{"price":1873.33,"qty":0.43502454}],"asks":[],"checksum":209841109,"timestamp":"2026-08-02T05:43:41.091655Z"}]}
{"channel":"book","type":"update","data":[{"symbol":"BTC/USD","bids":[{"price":63346.0,"qty":0.78931487}],"asks":[],"checksum":4248638156,"timestamp":"2026-08-02T05:43:41.091998Z"}]}
{"channel":"book","type":"update","data":[{"symbol":"ETH/USD","bids":[{"price":1873.33,"qty":0.41130000},{"price":1873.34,"qty":0.02372441}],"asks":[],"checksum":4277060540,"timestamp":"2026-08-02T05:43:41.093174Z"}]}
{"channel":"book","type":"update","data":[{"symbol":"BTC/USD","bids":[{"price":63348.4,"qty":0.13314409}],"asks":[],"checksum":340121713,"timestamp":"2026-08-02T05:43:41.095466Z"}]}
{"channel":"book","type":"update","data":[{"symbol":"BTC/USD","bids":[],"asks":[{"price":63348.5,"qty":0.00118252}],"checksum":4143388614,"timestamp":"2026-08-02T05:43:41.095735Z"}]}
{"channel":"book","type":"update","data":[{"symbol":"ETH/USD","bids":[{"price":1873.31,"qty":2.66906157}],"asks":[],"checksum":2918711314,"timestamp":"2026-08-02T05:43:41.242348Z"}]}
{"channel":"book","type":"update","data":[{"symbol":"ETH/USD","bids":[{"price":1873.32,"qty":1.60630847}],"asks":[],"checksum":3812089269,"timestamp":"2026-08-02T05:43:41.244344Z"}]}
{"channel":"book","type":"update","data":[{"symbol":"ETH/USD","bids":[{"price":1873.32,"qty":0.00000000},{"price":1873.10,"qty":2.00000000},{"price":1873.34,"qty":1.63003288}],"asks":[],"checksum":4228131516,"timestamp":"2026-08-02T05:43:41.364822Z"}]}
{"channel":"book","type":"update","data":[{"symbol":"ETH/USD","bids":[{"price":1873.34,"qty":1.60630847},{"price":1873.32,"qty":0.02372467}],"asks":[],"checksum":1294051578,"timestamp":"2026-08-02T05:43:41.366475Z"}]}
{"channel":"book","type":"update","data":[{"symbol":"ETH/USD","bids":[{"price":1873.33,"qty":0.00000000},{"price":1873.10,"qty":2.00000000}],"asks":[],"checksum":689506707,"timestamp":"2026-08-02T05:43:41.458536Z"}]}
{"channel":"book","type":"update","data":[{"symbol":"ETH/USD","bids":[],"asks":[{"price":1873.58,"qty":0.41935100}],"checksum":3072762025,"timestamp":"2026-08-02T05:43:41.459067Z"}]}
{"channel":"book","type":"update","data":[{"symbol":"BTC/USD","bids":[{"price":63348.4,"qty":0.18814409}],"asks":[],"checksum":2427585898,"timestamp":"2026-08-02T05:43:41.488285Z"}]}
{"channel":"book","type":"update","data":[{"symbol":"ETH/USD","bids":[{"price":1873.35,"qty":0.32495410}],"asks":[],"checksum":3172394563,"timestamp":"2026-08-02T05:43:41.491142Z"}]}
{"channel":"book","type":"update","data":[{"symbol":"ETH/USD","bids":[{"price":1873.32,"qty":0.00000000},{"price":1873.10,"qty":2.00000000},{"price":1873.35,"qty":0.34867839}],"asks":[],"checksum":277525721,"timestamp":"2026-08-02T05:43:41.492515Z"}]}
{"channel":"book","type":"update","data":[{"symbol":"ETH/USD","bids":[{"price":1873.31,"qty":0.00000000},{"price":1873.09,"qty":0.01332630}],"asks":[],"checksum":3866300108,"timestamp":"2026-08-02T05:43:41.494475Z"}]}
{"channel":"book","type":"update","data":[{"symbol":"ETH/USD","bids":[],"asks":[{"price":1873.58,"qty":0.00805100}],"checksum":3176110027,"timestamp":"2026-08-02T05:43:41.494662Z"}]}
{"channel":"book","type":"update","data":[{"symbol":"ETH/USD","bids":[{"price":1873.35,"qty":3.01769199}],"asks":[],"checksum":2956956928,"timestamp":"2026-08-02T05:43:41.496022Z"}]}
{"channel":"book","type":"update","data":[{"symbol":"ETH/USD","bids":[{"price":1873.35,"qty":3.42899199}],"asks":[],"checksum":1216825336,"timestamp":"2026-08-02T05:43:41.497587Z"}]}
{"channel":"book","type":"update","data":[{"symbol":"ETH/USD","bids":[{"price":1873.35,"qty":3.40526770},{"price":1873.26,"qty":0.02372543}],"asks":[],"checksum":2986560526,"timestamp":"2026-08-02T05:43:41.498414Z"}]}
{"channel":"book","type":"update","data":[{"symbol":"ETH/USD","bids":[{"price":1873.36,"qty":0.41130000}],"asks":[],"checksum":542415633,"timestamp":"2026-08-02T05:43:41.498440Z"}]}
{"channel":"book","type":"update","data":[{"symbol":"ETH/USD","bids":[{"price":1873.35,"qty":2.99396770}],"asks":[],"checksum":1556392217,"timestamp":"2026-08-02T05:43:41.498641Z"}]}
{"channel":"book","type":"update","data":[{"symbol":"ETH/USD","bids":[{"price":1873.35,"qty":2.66901360}],"asks":[],"checksum":999825374,"timestamp":"2026-08-02T05:43:41.499802Z"}]}
{"channel":"book","type":"update","data":[{"symbol":"ETH/USD","bids":[{"price":1873.36,"qty":0.00000000},{"price":1873.10,"qty":2.00000000}],"asks":[],"checksum":50274329,"timestamp":"2026-08-02T05:43:41.505942Z"}]}
{"channel":"book","type":"update","data":[{"symbol":"BTC/USD","bids":[],"asks":[{"price":63351.4,"qty":0.00000000},{"price":63355.7,"qty":0.78919566}],"checksum":2366978991,"timestamp":"2026-08-02T05:43:41.589313Z"}]}
{"channel":"book","type":"update","data":[{"symbol":"BTC/USD","bids":[],"asks":[{"price":63351.3,"qty":0.00000000},{"price":63357.0,"qty":0.00157836}],"checksum":2837146066,"timestamp":"2026-08-02T05:43:41.590991Z"}]}
{"channel":"book","type":"update","data":[{"symbol":"BTC/USD","bids":[],"asks":[{"price":63352.6,"qty":0.15063504}],"checksum":738295173,"timestamp":"2026-08-02T05:43:41.592156Z"}]}
{"channel":"book","type":"update","data":[{"symbol":"ETH/USD","bids":[{"price":1873.34,"qty":0.00000000},{"price":1873.09,"qty":0.01332630},{"price":1873.36,"qty":1.60630847}],"asks":[],"checksum":3657077417,"timestamp":"2026-08-02T05:43:41.596044Z"}]}
{"channel":"heartbeat"}
{"channel":"book","type":"update","data":[{"symbol":"ETH/USD","bids":[{"price":1873.19,"qty":0.00000000},{"price":1873.09,"qty":0.01332630},{"price":1873.23,"qty":0.00320200}],"asks":[],"checksum":1717096594,"timestamp":"2026-08-02T05:43:41.802335Z"}]}
{"channel":"book","type":"update","data":[{"symbol":"BTC/USD","bids":[{"price":63342.5,"qty":0.00009400}],"asks":[],"checksum":3428906956,"timestamp":"2026-08-02T05:43:41.802378Z"}]}
{"channel":"book","type":"update","data":[{"symbol":"BTC/USD","bids":[{"price":63348.4,"qty":0.13314409}],"asks":[],"checksum":2631661862,"timestamp":"2026-08-02T05:43:41.947476Z"}]}
{"channel":"heartbeat"}
{"channel":"book","type":"update","data":[{"symbol":"ETH/USD","bids":[{"price":1873.17,"qty":0.10677088}],"asks":[],"checksum":944655825,"timestamp":"2026-08-02T05:43:42.764103Z"}]}
{"channel":"book","type":"update","data":[{"symbol":"ETH/USD","bids":[],"asks":[{"price":1873.39,"qty":1.34044232}],"checksum":2255928251,"timestamp":"2026-08-02T05:43:42.765517Z"}]}
{"channel":"book","type":"update","data":[{"symbol":"ETH/USD","bids":[],"asks":[{"price":1873.39,"qty":0.47001888}],"checksum":944655825,"timestamp":"2026-08-02T05:43:42.767309Z"}]}
{"channel":"book","type":"update","data":[{"symbol":"ETH/USD","bids":[],"asks":[{"price":1873.38,"qty":0.41437831}],"checksum":2679444627,"timestamp":"2026-08-02T05:43:42.767387Z"}]}
{"channel":"book","type":"update","data":[{"symbol":"ETH/USD","bids":[{"price":1873.35,"qty":0.00000000},{"price":1873.09,"qty":0.01332630}],"asks":[],"checksum":1510868407,"timestamp":"2026-08-02T05:43:42.767570Z"}]}
{"channel":"book","type":"update","data":[{"symbol":"ETH/USD","bids":[],"asks":[{"price":1873.57,"qty":0.41130000}],"checksum":1499438354,"timestamp":"2026-08-02T05:43:42.768748Z"}]}
{"channel":"book","type":"update","data":[{"symbol":"ETH/USD","bids":[{"price":1873.36,"qty":0.00000000},{"price":1873.08,"qty":8.51649082},{"price":1873.31,"qty":1.60630847}],"asks":[],"checksum":4161135011,"timestamp":"2026-08-02T05:43:42.769295Z"}]}
{"channel":"book","type":"update","data":[{"symbol":"ETH/USD","bids":[{"price":1873.09,"qty":0.00000000},{"price":1873.08,"qty":8.51649082}],"asks":[],"checksum":1355484828,"timestamp":"2026-08-02T05:43:42.769332Z"}]}
{"channel":"book","type":"update","data":[{"symbol":"ETH/USD","bids":[],"asks":[{"price":1873.37,"qty":0.47001888}],"checksum":4058643115,"timestamp":"2026-08-02T05:43:42.769547Z"}]}
{"channel":"book","type":"update","data":[{"symbol":"ETH/USD","bids":[{"price":1873.25,"qty":0.00000000},{"price":1873.00,"qty":9.06780566}],"asks":[],"checksum":1549949458,"timestamp":"2026-08-02T05:43:42.770020Z"}]}
{"channel":"book","type":"update","data":[{"symbol":"ETH/USD","bids":[],"asks":[{"price":1873.39,"qty":1.34044232}],"checksum":1451666090,"timestamp":"2026-08-02T05:43:42.770447Z"}]}
{"channel":"book","type":"update","data":[{"symbol":"ETH/USD","bids":[{"price":1873.11,"qty":0.00000000},{"price":1872.99,"qty":5.86997900}],"asks":[],"checksum":3791368473,"timestamp":"2026-08-02T05:43:42.770937Z"}]}
{"channel":"book","type":"update","data":[{"symbol":"ETH/USD","bids":[{"price":1873.17,"qty":0.00000000},{"price":1872.98,"qty":17.01400000}],"asks":[],"checksum":472699579,"timestamp":"2026-08-02T05:43:42.771054Z"}]}
{"channel":"book","type":"update","data":[{"symbol":"ETH/USD","bids":[{"price":1873.26,"qty":0.00000000},{"price":1872.88,"qty":1.60156356},{"price":1873.32,"qty":0.02372467}],"asks":[],"checksum":2904670755,"timestamp":"2026-08-02T05:43:42.772855Z"}]}
{"channel":"book","type":"update","data":[{"symbol":"ETH/USD","bids":[{"price":1873.08,"qty":8.40971481}],"asks":[],"checksum":2016061062,"timestamp":"2026-08-02T05:43:42.773661Z"}]}
{"channel":"book","type":"update","data":[{"symbol":"ETH/USD","bids":[],"asks":[{"price":1873.38,"qty":0.00000000},{"price":1873.58,"qty":0.00805100}],"checksum":3336533585,"timestamp":"2026-08-02T05:43:42.773753Z"}]}
{"channel":"book","type":"update","data":[{"symbol":"ETH/USD","bids":[{"price":1873.23,"qty":2.67237450}],"asks":[],"checksum":2189731547,"timestamp":"2026-08-02T05:43:42.773948Z"}]}
{"channel":"book","type":"update","data":[{"symbol":"ETH/USD","bids":[{"price":1873.20,"qty":0.00000000},{"price":1872.88,"qty":1.60156356}],"asks":[],"checksum":3008739756,"timestamp":"2026-08-02T05:43:42.774127Z"}]}
{"channel":"book","type":"update","data":[{"symbol":"ETH/USD","bids":[{"price":1872.97,"qty":26.69553384}],"asks":[],"checksum":3877752548,"timestamp":"2026-08-02T05:43:42.774151Z"}]}
{"channel":"book","type":"update","data":[{"symbol":"ETH/USD","bids":[],"asks":[{"price":1873.36,"qty":1.30000000}],"checksum":2181690442,"timestamp":"2026-08-02T05:43:42.775754Z"}]}
{"channel":"book","type":"update","data":[{"symbol":"ETH/USD","bids":[],"asks":[{"price":1873.43,"qty":0.00000000},{"price":1873.58,"qty":0.00805100},{"price":1873.36,"qty":1.31439800}],"checksum":581246556,"timestamp":"2026-08-02T05:43:42.775888Z"}]}
{"channel":"book","type":"update","data":[{"symbol":"ETH/USD","bids":[],"asks":[{"price":1873.36,"qty":1.30000000},{"price":1873.38,"qty":0.01439800}],"checksum":4066985607,"timestamp":"2026-08-02T05:43:42.777834Z"}]}
{"channel":"book","type":"update","data":[{"symbol":"ETH/USD","bids":[{"price":1872.99,"qty":5.48997900}],"asks":[],"checksum":1023929499,"timestamp":"2026-08-02T05:43:42.778547Z"}]}
{"channel":"book","type":"update","data":[{"symbol":"ETH/USD","bids":[],"asks":[{"price":1873.37,"qty":0.64656060}],"checksum":1736443913,"timestamp":"2026-08-02T05:43:42.780037Z"}]}
{"channel":"book","type":"update","data":[{"symbol":"ETH/USD","bids":[],"asks":[{"price":1873.39,"qty":0.47001888}],"checksum":287606797,"timestamp":"2026-08-02T05:43:42.780314Z"}]}
{"channel":"book","type":"update","data":[{"symbol":"ETH/USD","bids":[{"price":1873.08,"qty":0.00000000},{"price":1872.88,"qty":1.60156356}],"asks":[],"checksum":4056797542,"timestamp":"2026-08-02T05:43:42.780474Z"}]}
{"channel":"book","type":"update","data":[{"symbol":"ETH/USD","bids":[],"asks":[{"price":1873.52,"qty":0.00000000},{"price":1873.58,"qty":0.00805100}],"checksum":983950078,"timestamp":"2026-08-02T05:43:42.780532Z"}]}
{"channel":"book","type":"update","data":[{"symbol":"ETH/USD","bids":[{"price":1873.01,"qty":2.82951304}],"asks":[],"checksum":4211352639,"timestamp":"2026-08-02T05:43:42.782808Z"}]}
{"channel":"book","type":"update","data":[{"symbol":"ETH/USD","bids":[],"asks":[{"price":1873.45,"qty":1.01024878}],"checksum":3187694018,"timestamp":"2026-08-02T05:43:42.782825Z"}]}
{"channel":"book","type":"update","data":[{"symbol":"ETH/USD","bids":[],"asks":[{"price":1873.35,"qty":1.59177242}],"checksum":208312628,"timestamp":"2026-08-02T05:43:42.782851Z"}]}
{"channel":"book","type":"update","data":[{"symbol":"ETH/USD","bids":[],"asks":[{"price":1873.51,"qty":0.00000000},{"price":1873.57,"qty":0.41130000},{"price":1873.56,"qty":1.60630847}],"checksum":2314749068,"timestamp":"2026-08-02T05:43:42.783506Z"}]}
{"channel":"book","type":"update","data":[{"symbol":"ETH/USD","bids":[],"asks":[{"price":1873.38,"qty":0.00000000},{"price":1873.57,"qty":0.41130000},{"price":1873.43,"qty":0.01439800}],"checksum":2969964395,"timestamp":"2026-08-02T05:43:42.784703Z"}]}
{"channel":"book","type":"update","data":[{"symbol":"ETH/USD","bids":[],"asks":[{"price":1873.45,"qty":0.00000000},{"price":1873.57,"qty":0.41130000}],"checksum":2267904104,"timestamp":"2026-08-02T05:43:42.785104Z"}]}
{"channel":"book","type":"update","data":[{"symbol":"ETH/USD","bids":[],"asks":[{"price":1873.55,"qty":1.45777307}],"checksum":1226711473,"timestamp":"2026-08-02T05:43:42.785235Z"}]}
{"channel":"book","type":"update","data":[{"symbol":"ETH/USD","bids":[],"asks":[{"price":1873.56,"qty":0.00000000},{"price":1873.57,"qty":0.41130000},{"price":1873.54,"qty":1.60630847}],"checksum":1132245456,"timestamp":"2026-08-02T05:43:42.787521Z"}]}
{"channel":"book","type":"update","data":[{"symbol":"ETH/USD","bids":[],"asks":[{"price":1873.55,"qty":0.00000000},{"price":1873.57,"qty":0.41130000}],"checksum":3816592647,"timestamp":"2026-08-02T05:43:42.788898Z"}]}
{"channel":"book","type":"update","data":[{"symbol":"ETH/USD","bids":[],"asks":[{"price":1873.55,"qty":0.97828999}],"checksum":4127703319,"timestamp":"2026-08-02T05:43:42.789006Z"}]}
{"channel":"book","type":"update","data":[{"symbol":"ETH/USD","bids":[],"asks":[{"price":1873.35,"qty":0.00000000},{"price":1873.57,"qty":0.41130000}],"checksum":2630222609,"timestamp":"2026-08-02T05:43:42.790931Z"}]}
{"channel":"book","type":"update","data":[{"symbol":"ETH/USD","bids":[],"asks":[{"price":1873.43,"qty":0.00000000},{"price":1873.58,"qty":0.00805100},{"price":1873.38,"qty":0.01439800}],"checksum":2924242776,"timestamp":"2026-08-02T05:43:42.792059Z"}]}
{"channel":"book","type":"update","data":[{"symbol":"ETH/USD","bids":[{"price":1873.31,"qty":0.00000000},{"price":1872.88,"qty":1.60156356}],"asks":[],"checksum":3921134706,"timestamp":"2026-08-02T05:43:42.801916Z"}]}
{"channel":"book","type":"update","data":[{"symbol":"ETH/USD","bids":[{"price":1873.11,"qty":1.60630847}],"asks":[],"checksum":3755171016,"timestamp":"2026-08-02T05:43:42.803034Z"}]}
{"channel":"book","type":"update","data":[{"symbol":"ETH/USD","bids":[{"price":1873.32,"qty":0.00000000},{"price":1872.88,"qty":1.60156356},{"price":1873.31,"qty":0.02372479}],"asks":[],"checksum":3351531361,"timestamp":"2026-08-02T05:43:42.803074Z"}]}
{"channel":"book","type":"update","data":[{"symbol":"ETH/USD","bids":[],"asks":[{"price":1873.38,"qty":0.00000000},{"price":1873.58,"qty":0.00805100},{"price":1873.36,"qty":1.31439800}],"checksum":1214653498,"timestamp":"2026-08-02T05:43:42.804713Z"}]}
{"channel":"book","type":"update","data":[{"symbol":"ETH/USD","bids":[],"asks":[{"price":1873.44,"qty":0.80078177}],"checksum":2010362387,"timestamp":"2026-08-02T05:43:42.811032Z"}]}
{"channel":"book","type":"update","data":[{"symbol":"ETH/USD","bids":[],"asks":[{"price":1873.44,"qty":0.00000000},{"price":1873.60,"qty":2.85800239}],"checksum":3408232143,"timestamp":"2026-08-02T05:43:42.814057Z"}]}
{"channel":"book","type":"update","data":[{"symbol":"ETH/USD","bids":[],"asks":[{"price":1873.46,"qty":0.00000000},{"price":1873.63,"qty":0.03993899},{"price":1873.40,"qty":2.90162334}],"checksum":1493907174,"timestamp":"2026-08-02T05:43:42.814070Z"}]}
{"channel":"book","type":"update","data":[{"symbol":"ETH/USD","bids":[{"price":1873.02,"qty":0.01332630}],"asks":[],"checksum":3188847588,"timestamp":"2026-08-02T05:43:42.816971Z"}]}
{"channel":"book","type":"update","data":[{"symbol":"ETH/USD","bids":[],"asks":[{"price":1873.38,"qty":0.80081166}],"checksum":4163442511,"timestamp":"2026-08-02T05:43:42.817682Z"}]}
{"channel":"book","type":"update","data":[{"symbol":"ETH/USD","bids":[],"asks":[{"price":1873.39,"qty":0.00000000},{"price":1873.63,"qty":0.03993899}],"checksum":3976009572,"timestamp":"2026-08-02T05:43:42.870707Z"}]}
{"channel":"book","type":"update","data":[{"symbol":"ETH/USD","bids":[],"asks":[{"price":1873.35,"qty":0.47001888}],"checksum":1311453549,"timestamp":"2026-08-02T05:43:42.871965Z"}]}
{"channel":"book","type":"update","data":[{"symbol":"ETH/USD","bids":[{"price":1873.04,"qty":14.94574237}],"asks":[],"checksum":3614112621,"timestamp":"2026-08-02T05:43:42.873580Z"}]}
{"channel":"book","type":"update","data":[{"symbol":"ETH/USD","bids":[{"price":1873.12,"qty":1.07648308}],"asks":[],"checksum":2404281566,"timestamp":"2026-08-02T05:43:42.875028Z"}]}
{"channel":"book","type":"update","data":[{"symbol":"ETH/USD","bids":[],"asks":[{"price":1873.40,"qty":1.60162334}],"checksum":1977808757,"timestamp":"2026-08-02T05:43:42.876646Z"}]}
{"channel":"book","type":"update","data":[{"symbol":"ETH/USD","bids":[{"price":1873.02,"qty":0.00000000},{"price":1872.99,"qty":5.48997900},{"price":1873.05,"qty":0.01332630}],"asks":[],"checksum":2831072864,"timestamp":"2026-08-02T05:43:42.876978Z"}]}
{"channel":"book","type":"update","data":[{"symbol":"ETH/USD","bids":[],"asks":[{"price":1873.34,"qty":1.30000000}],"checksum":1560815271,"timestamp":"2026-08-02T05:43:42.877784Z"}]}
{"channel":"book","type":"update","data":[{"symbol":"ETH/USD","bids":[],"asks":[{"price":1873.36,"qty":1.30000000},{"price":1873.53,"qty":0.01439800}],"checksum":1393292579,"timestamp":"2026-08-02T05:43:42.877920Z"}]}
{"channel":"book","type":"update","data":[{"symbol":"ETH/USD","bids":[{"price":1873.31,"qty":0.00000000},{"price":1872.99,"qty":5.48997900},{"price":1873.33,"qty":0.02372454}],"asks":[],"checksum":1551587583,"timestamp":"2026-08-02T05:43:42.878902Z"}]}
{"channel":"book","type":"update","data":[{"symbol":"ETH/USD","bids":[{"price":1873.11,"qty":0.00000000},{"price":1872.99,"qty":5.48997900},{"price":1873.13,"qty":1.60630847}],"asks":[],"checksum":2834139995,"timestamp":"2026-08-02T05:43:42.968853Z"}]}
{"channel":"book","type":"update","data":[{"symbol":"ETH/USD","bids":[],"asks":[{"price":1873.54,"qty":0.00000000},{"price":1873.58,"qty":0.00805100},{"price":1873.52,"qty":1.60630847}],"checksum":2738910018,"timestamp":"2026-08-02T05:43:42.969022Z"}]}
{"channel":"book","type":"update","data":[{"symbol":"ETH/USD","bids":[{"price":1873.12,"qty":0.00000000},{"price":1872.99,"qty":5.48997900}],"asks":[],"checksum":708634744,"timestamp":"2026-08-02T05:43:42.970242Z"}]}
{"channel":"book","type":"update","data":[{"symbol":"ETH/USD","bids":[{"price":1873.12,"qty":0.59700000}],"asks":[],"checksum":2730912490,"timestamp":"2026-08-02T05:43:42.970449Z"}]}
{"channel":"book","type":"update","data":[{"symbol":"ETH/USD","bids":[],"asks":[{"price":1873.53,"qty":0.00000000},{"price":1873.58,"qty":0.00805100},{"price":1873.51,"qty":0.01439800}],"checksum":221224440,"timestamp":"2026-08-02T05:43:42.970520Z"}]}
{"channel":"book","type":"update","data":[{"symbol":"ETH/USD","bids":[{"price":1873.13,"qty":0.00000000},{"price":1872.99,"qty":5.48997900},{"price":1873.11,"qty":1.60630847}],"asks":[],"checksum":1179323444,"timestamp":"2026-08-02T05:43:42.972498Z"}]}
{"channel":"book","type":"update","data":[{"symbol":"ETH/USD","bids":[{"price":1873.05,"qty":4.79579623}],"asks":[],"checksum":731100752,"timestamp":"2026-08-02T05:43:42.972910Z"}]}
{"channel":"book","type":"update","data":[{"symbol":"ETH/USD","bids":[{"price":1873.01,"qty":0.00000000},{"price":1872.99,"qty":5.48997900}],"asks":[],"checksum":3332739960,"timestamp":"2026-08-02T05:43:42.972949Z"}]}
{"channel":"book","type":"update","data":[{"symbol":"ETH/USD","bids":[],"asks":[{"price":1873.37,"qty":0.17654172}],"checksum":2503500263,"timestamp":"2026-08-02T05:43:42.972971Z"}]}
{"channel":"book","type":"update","data":[{"symbol":"ETH/USD","bids":[],"asks":[{"price":1873.34,"qty":1.77001888}],"checksum":2625596037,"timestamp":"2026-08-02T05:43:42.974538Z"}]}
{"channel":"book","type":"update","data":[{"symbol":"ETH/USD","bids":[],"asks":[{"price":1873.36,"qty":0.00000000},{"price":1873.58,"qty":0.00805100}],"checksum":3374012512,"timestamp":"2026-08-02T05:43:42.978867Z"}]}
{"channel":"book","type":"update","data":[{"symbol":"ETH/USD","bids":[],"asks":[{"price":1873.35,"qty":0.00000000},{"price":1873.60,"qty":2.85800239}],"checksum":2465110874,"timestamp":"2026-08-02T05:43:43.076540Z"}]}
{"channel":"book","type":"update","data":[{"symbol":"ETH/USD","bids":[{"price":1873.20,"qty":1.06769166}],"asks":[],"checksum":173369649,"timestamp":"2026-08-02T05:43:43.091841Z"}]}
{"channel":"book","type":"update","data":[{"symbol":"ETH/USD","bids":[{"price":1873.11,"qty":0.00000000},{"price":1872.99,"qty":5.48997900},{"price":1873.13,"qty":1.60630847}],"asks":[],"checksum":3472766731,"timestamp":"2026-08-02T05:43:43.142398Z"}]}
{"channel":"book","type":"update","data":[{"symbol":"ETH/USD","bids":[],"asks":[{"price":1873.52,"qty":0.00000000},{"price":1873.63,"qty":0.03993899},{"price":1873.50,"qty":1.60630847}],"checksum":2900382888,"timestamp":"2026-08-02T05:43:43.142418Z"}]}
{"channel":"book","type":"update","data":[{"symbol":"ETH/USD","bids":[],"asks":[{"price":1873.51,"qty":0.00000000},{"price":1873.63,"qty":0.03993899},{"price":1873.49,"qty":0.01439800}],"checksum":1463322494,"timestamp":"2026-08-02T05:43:43.144245Z"}]}
{"channel":"book","type":"update","data":[{"symbol":"ETH/USD","bids":[],"asks":[{"price":1873.50,"qty":0.00000000},{"price":1873.63,"qty":0.03993899},{"price":1873.54,"qty":1.60630847}],"checksum":1085696275,"timestamp":"2026-08-02T05:43:43.145581Z"}]}
{"channel":"book","type":"update","data":[{"symbol":"ETH/USD","bids":[],"asks":[{"price":1873.49,"qty":0.00000000},{"price":1873.63,"qty":0.03993899},{"price":1873.53,"qty":0.01439800}],"checksum":994073119,"timestamp":"2026-08-02T05:43:43.146620Z"}]}
{"channel":"book","type":"update","data":[{"symbol":"ETH/USD","bids":[],"asks":[{"price":1873.60,"qty":5.52667324}],"checksum":1884188097,"timestamp":"2026-08-02T05:43:43.149752Z"}]}
{"channel":"book","type":"update","data":[{"symbol":"ETH/USD","bids":[],"asks":[{"price":1873.55,"qty":1.64981579}],"checksum":3990269773,"timestamp":"2026-08-02T05:43:43.151066Z"}]}
{"channel":"book","type":"update","data":[{"symbol":"ETH/USD","bids":[],"asks":[{"price":1873.53,"qty":0.05433699}],"checksum":3779937741,"timestamp":"2026-08-02T05:43:43.152786Z"}]}
{"channel":"book","type":"update","data":[{"symbol":"ETH/USD","bids":[],"asks":[{"price":1873.54,"qty":0.00000000},{"price":1873.64,"qty":6.13208319},{"price":1873.52,"qty":1.60630847}],"checksum":1581909399,"timestamp":"2026-08-02T05:43:43.312387Z"}]}
{"channel":"book","type":"update","data":[{"symbol":"ETH/USD","bids":[],"asks":[{"price":1873.53,"qty":0.03993899},{"price":1873.51,"qty":0.01439800}],"checksum":3726531351,"timestamp":"2026-08-02T05:43:43.313668Z"}]}
{"channel":"book","type":"update","data":[{"symbol":"ETH/USD","bids":[],"asks":[{"price":1873.53,"qty":0.00000000},{"price":1873.60,"qty":5.52667324},{"price":1873.59,"qty":0.03993899}],"checksum":592931540,"timestamp":"2026-08-02T05:43:43.369686Z"}]}
{"channel":"book","type":"update","data":[{"symbol":"ETH/USD","bids":[{"price":1873.23,"qty":0.00320200}],"asks":[],"checksum":3381583517,"timestamp":"2026-08-02T05:43:43.385206Z"}]}
{"channel":"book","type":"update","data":[{"symbol":"ETH/USD","bids":[{"price":1873.28,"qty":2.66911059}],"asks":[],"checksum":758287805,"timestamp":"2026-08-02T05:43:43.386730Z"}]}
{"channel":"book","type":"update","data":[{"symbol":"ETH/USD","bids":[],"asks":[{"price":1873.58,"qty":0.00000000},{"price":1873.60,"qty":5.52667324}],"checksum":2550216413,"timestamp":"2026-08-02T05:43:43.485348Z"}]}
{"channel":"book","type":"update","data":[{"symbol":"ETH/USD","bids":[],"asks":[{"price":1873.52,"qty":0.00000000},{"price":1873.62,"qty":0.00805100},{"price":1873.50,"qty":1.60630847}],"checksum":1535068801,"timestamp":"2026-08-02T05:43:43.486724Z"}]}
{"channel":"book","type":"update","data":[{"symbol":"ETH/USD","bids":[],"asks":[{"price":1873.51,"qty":0.00000000},{"price":1873.62,"qty":0.00805100},{"price":1873.49,"qty":0.01439800}],"checksum":1474361822,"timestamp":"2026-08-02T05:43:43.487986Z"}]}
{"channel":"book","type":"update","data":[{"symbol":"ETH/USD","bids":[],"asks":[{"price":1873.50,"qty":0.00000000},{"price":1873.62,"qty":0.00805100},{"price":1873.54,"qty":1.60630847}],"checksum":1857083200,"timestamp":"2026-08-02T05:43:43.489034Z"}]}
{"channel":"book","type":"update","data":[{"symbol":"ETH/USD","bids":[],"asks":[{"price":1873.49,"qty":0.00000000},{"price":1873.62,"qty":0.00805100},{"price":1873.53,"qty":0.01439800}],"checksum":698905994,"timestamp":"2026-08-02T05:43:43.490485Z"}]}
{"channel":"book","type":"update","data":[{"symbol":"ETH/USD","bids":[],"asks":[{"price":1873.57,"qty":0.00000000},{"price":1873.62,"qty":0.00805100}],"checksum":1878555571,"timestamp":"2026-08-02T05:43:43.502353Z"}]}
{"channel":"book","type":"update","data":[{"symbol":"BTC/USD","bids":[],"asks":[{"price":63350.9,"qty":0.79278183}],"checksum":3030710550,"timestamp":"2026-08-02T05:43:43.602750Z"}]}
{"channel":"book","type":"update","data":[{"symbol":"BTC/USD","bids":[],"asks":[{"price":63352.6,"qty":0.00000000},{"price":63357.0,"qty":0.00157836}],"checksum":2776721483,"timestamp":"2026-08-02T05:43:43.604548Z"}]}
{"channel":"book","type":"update","data":[{"symbol":"BTC/USD","bids":[],"asks":[{"price":63348.5,"qty":0.03310673}],"checksum":2302811172,"timestamp":"2026-08-02T05:43:43.606359Z"}]}
{"channel":"book","type":"update","data":[{"symbol":"BTC/USD","bids":[],"asks":[{"price":63350.8,"qty":0.38728042}],"checksum":2694692441,"timestamp":"2026-08-02T05:43:43.606521Z"}]}
{"channel":"book","type":"update","data":[{"symbol":"BTC/USD","bids":[{"price":63348.4,"qty":0.12148930}],"asks":[],"checksum":3873836238,"timestamp":"2026-08-02T05:43:43.606836Z"}]}
{"channel":"book","type":"update","data":[{"symbol":"ETH/USD","bids":[],"asks":[{"price":1873.54,"qty":0.00000000},{"price":1873.64,"qty":6.13208319},{"price":1873.52,"qty":1.60630847}],"checksum":2489733275,"timestamp":"2026-08-02T05:43:43.677522Z"}]}
{"channel":"book","type":"update","data":[{"symbol":"ETH/USD","bids":[],"asks":[{"price":1873.53,"qty":0.00000000},{"price":1873.64,"qty":6.13208319},{"price":1873.51,"qty":0.01439800}],"checksum":2734305936,"timestamp":"2026-08-02T05:43:43.678696Z"}]}
{"channel":"heartbeat"}
{"channel":"book","type":"update","data":[{"symbol":"ETH/USD","bids":[],"asks":[{"price":1873.52,"qty":0.00000000},{"price":1873.64,"qty":6.13208319},{"price":1873.50,"qty":1.60630847}],"checksum":1465928278,"timestamp":"2026-08-02T05:43:43.850525Z"}]}
{"channel":"book","type":"update","data":[{"symbol":"ETH/USD","bids":[],"asks":[{"price":1873.51,"qty":0.00000000},{"price":1873.64,"qty":6.13208319},{"price":1873.49,"qty":0.01439800}],"checksum":651041071,"timestamp":"2026-08-02T05:43:43.851788Z"}]}
{"channel":"book","type":"update","data":[{"symbol":"ETH/USD","bids":[],"asks":[{"price":1873.50,"qty":0.00000000},{"price":1873.64,"qty":6.13208319},{"price":1873.54,"qty":1.60630847}],"checksum":134335197,"timestamp":"2026-08-02T05:43:43.852972Z"}]}
{"channel":"book","type":"update","data":[{"symbol":"ETH/USD","bids":[],"asks":[{"price":1873.49,"qty":0.00000000},{"price":1873.64,"qty":6.13208319},{"price":1873.53,"qty":0.01439800}],"checksum":1878555571,"timestamp":"2026-08-02T05:43:43.854148Z"}]}
{"channel":"book","type":"update","data":[{"symbol":"ETH/USD","bids":[{"price":1873.33,"qty":0.43502454}],"asks":[],"checksum":2072615815,"timestamp":"2026-08-02T05:43:43.968115Z"}]}
{"channel":"book","type":"update","data":[{"symbol":"ETH/USD","bids":[],"asks":[{"price":1873.54,"qty":0.00000000},{"price":1873.64,"qty":6.13208319},{"price":1873.52,"qty":1.60630847}],"checksum":1321708886,"timestamp":"2026-08-02T05:43:44.116060Z"}]}
{"channel":"book","type":"update","data":[{"symbol":"ETH/USD","bids":[],"asks":[{"price":1873.53,"qty":0.00000000},{"price":1873.64,"qty":6.13208319},{"price":1873.51,"qty":0.01439800}],"checksum":3643009212,"timestamp":"2026-08-02T05:43:44.117319Z"}]}
{"channel":"book","type":"update","data":[{"symbol":"ETH/USD","bids":[{"price":1873.33,"qty":0.02372454}],"asks":[],"checksum":2734305936,"timestamp":"2026-08-02T05:43:44.146016Z"}]}
{"channel":"book","type":"update","data":[{"symbol":"ETH/USD","bids":[],"asks":[{"price":1873.52,"qty":0.00000000},{"price":1873.64,"qty":6.13208319},{"price":1873.50,"qty":1.60630847}],"checksum":1465928278,"timestamp":"2026-08-02T05:43:44.298949Z"}]}
{"channel":"book","type":"update","data":[{"symbol":"ETH/USD","bids":[],"asks":[{"price":1873.51,"qty":0.00000000},{"price":1873.64,"qty":6.13208319},{"price":1873.49,"qty":0.01439800}],"checksum":651041071,"timestamp":"2026-08-02T05:43:44.300131Z"}]}
{"channel":"book","type":"update","data":[{"symbol":"ETH/USD","bids":[],"asks":[{"price":1873.50,"qty":0.00000000},{"price":1873.64,"qty":6.13208319},{"price":1873.54,"qty":1.60630847}],"checksum":134335197,"timestamp":"2026-08-02T05:43:44.301264Z"}]}
{"channel":"book","type":"update","data":[{"symbol":"ETH/USD","bids":[],"asks":[{"price":1873.49,"qty":0.00000000},{"price":1873.64,"qty":6.13208319},{"price":1873.53,"qty":0.01439800}],"checksum":1878555571,"timestamp":"2026-08-02T05:43:44.302811Z"}]}
{"channel":"book","type":"update","data":[{"symbol":"ETH/USD","bids":[],"asks":[{"price":1873.54,"qty":0.00000000},{"price":1873.64,"qty":6.13208319},{"price":1873.52,"qty":1.60630847}],"checksum":2489733275,"timestamp":"2026-08-02T05:43:44.633171Z"}]}
{"channel":"book","type":"update","data":[{"symbol":"ETH/USD","bids":[],"asks":[{"price":1873.53,"qty":0.00000000},{"price":1873.64,"qty":6.13208319},{"price":1873.51,"qty":0.01439800}],"checksum":2734305936,"timestamp":"2026-08-02T05:43:44.634762Z"}]}
{"channel":"heartbeat"}
{"channel":"book","type":"update","data":[{"symbol":"ETH/USD","bids":[],"asks":[{"price":1873.52,"qty":0.00000000},{"price":1873.64,"qty":6.13208319},{"price":1873.50,"qty":1.60630847}],"checksum":1465928278,"timestamp":"2026-08-02T05:43:45.065804Z"}]}
{"channel":"book","type":"update","data":[{"symbol":"ETH/USD","bids":[],"asks":[{"price":1873.51,"qty":0.00000000},{"price":1873.64,"qty":6.13208319},{"price":1873.49,"qty":0.01439800}],"checksum":651041071,"timestamp":"2026-08-02T05:43:45.066960Z"}]}
{"channel":"book","type":"update","data":[{"symbol":"ETH/USD","bids":[],"asks":[{"price":1873.50,"qty":0.00000000},{"price":1873.64,"qty":6.13208319},{"price":1873.54,"qty":1.60630847}],"checksum":134335197,"timestamp":"2026-08-02T05:43:45.068109Z"}]}
{"channel":"book","type":"update","data":[{"symbol":"ETH/USD","bids":[],"asks":[{"price":1873.49,"qty":0.00000000},{"price":1873.64,"qty":6.13208319},{"price":1873.53,"qty":0.01439800}],"checksum":1878555571,"timestamp":"2026-08-02T05:43:45.069333Z"}]}
{"channel":"book","type":"update","data":[{"symbol":"ETH/USD","bids":[],"asks":[{"price":1873.60,"qty":2.85800239}],"checksum":160774798,"timestamp":"2026-08-02T05:43:45.216870Z"}]}
{"channel":"book","type":"update","data":[{"symbol":"ETH/USD","bids":[{"price":1873.28,"qty":0.00000000},{"price":1873.00,"qty":9.06780566}],"asks":[],"checksum":3978914222,"timestamp":"2026-08-02T05:43:45.217161Z"}]}
{"channel":"book","type":"update","data":[{"symbol":"ETH/USD","bids":[{"price":1873.12,"qty":0.00000000},{"price":1872.99,"qty":5.48997900}],"asks":[],"checksum":1730009831,"timestamp":"2026-08-02T05:43:45.218390Z"}]}
{"channel":"book","type":"update","data":[{"symbol":"ETH/USD","bids":[],"asks":[{"price":1873.55,"qty":0.97828999}],"checksum":1375292662,"timestamp":"2026-08-02T05:43:45.218807Z"}]}
{"channel":"book","type":"update","data":[{"symbol":"ETH/USD","bids":[{"price":1873.32,"qty":2.66905305}],"asks":[],"checksum":333202099,"timestamp":"2026-08-02T05:43:45.219158Z"}]}
{"channel":"book","type":"update","data":[{"symbol":"ETH/USD","bids":[{"price":1873.06,"qty":26.69415985}],"asks":[],"checksum":174613775,"timestamp":"2026-08-02T05:43:45.219431Z"}]}
{"channel":"book","type":"update","data":[{"symbol":"ETH/USD","bids":[{"price":1873.14,"qty":1.07648308}],"asks":[],"checksum":2194404580,"timestamp":"2026-08-02T05:43:45.220094Z"}]}
{"channel":"book","type":"update","data":[{"symbol":"ETH/USD","bids":[{"price":1873.05,"qty":4.78246993},{"price":1873.06,"qty":26.70748615}],"asks":[],"checksum":196899322,"timestamp":"2026-08-02T05:43:45.221367Z"}]}
{"channel":"book","type":"update","data":[{"symbol":"ETH/USD","bids":[{"price":1873.13,"qty":0.00000000},{"price":1873.04,"qty":14.94574237},{"price":1873.11,"qty":1.60630847}],"asks":[],"checksum":815158868,"timestamp":"2026-08-02T05:43:45.221604Z"}]}
{"channel":"book","type":"update","data":[{"symbol":"ETH/USD","bids":[],"asks":[{"price":1873.34,"qty":4.64404303}],"checksum":274115891,"timestamp":"2026-08-02T05:43:45.222006Z"}]}
{"channel":"book","type":"update","data":[{"symbol":"ETH/USD","bids":[{"price":1873.11,"qty":0.00000000},{"price":1873.04,"qty":14.94574237},{"price":1873.14,"qty":2.68279155}],"asks":[],"checksum":2482558193,"timestamp":"2026-08-02T05:43:45.223246Z"}]}
{"channel":"book","type":"update","data":[{"symbol":"ETH/USD","bids":[{"price":1873.06,"qty":26.69415985},{"price":1873.07,"qty":0.01332630}],"asks":[],"checksum":872465970,"timestamp":"2026-08-02T05:43:45.223573Z"}]}
{"channel":"book","type":"update","data":[{"symbol":"ETH/USD","bids":[{"price":1873.14,"qty":1.60630847}],"asks":[],"checksum":198598923,"timestamp":"2026-08-02T05:43:45.224501Z"}]}
{"channel":"book","type":"update","data":[{"symbol":"ETH/USD","bids":[{"price":1873.15,"qty":1.07648308}],"asks":[],"checksum":812109456,"timestamp":"2026-08-02T05:43:45.224603Z"}]}
{"channel":"book","type":"update","data":[{"symbol":"ETH/USD","bids":[],"asks":[{"price":1873.54,"qty":0.00000000},{"price":1873.64,"qty":8.80068654},{"price":1873.52,"qty":1.60630847}],"checksum":2291126516,"timestamp":"2026-08-02T05:43:45.225934Z"}]}
{"channel":"book","type":"update","data":[{"symbol":"ETH/USD","bids":[],"asks":[{"price":1873.53,"qty":0.00000000},{"price":1873.64,"qty":8.80068654},{"price":1873.51,"qty":0.01439800}],"checksum":529981362,"timestamp":"2026-08-02T05:43:45.227530Z"}]}
{"channel":"book","type":"update","data":[{"symbol":"ETH/USD","bids":[],"asks":[{"price":1873.51,"qty":0.01266813}],"checksum":35753002,"timestamp":"2026-08-02T05:43:45.255218Z"}]}
{"channel":"book","type":"update","data":[{"symbol":"ETH/USD","bids":[{"price":1873.33,"qty":0.43502454}],"asks":[],"checksum":1055766723,"timestamp":"2026-08-02T05:43:45.277802Z"}]}
{"channel":"book","type":"update","data":[{"symbol":"ETH/USD","bids":[{"price":1873.14,"qty":0.00000000},{"price":1873.05,"qty":4.78246993},{"price":1873.11,"qty":1.60630847}],"asks":[],"checksum":970897325,"timestamp":"2026-08-02T05:43:45.388347Z"}]}
{"channel":"book","type":"update","data":[{"symbol":"ETH/USD","bids":[],"asks":[{"price":1873.52,"qty":0.00000000},{"price":1873.64,"qty":6.13208319},{"price":1873.50,"qty":1.60630847}],"checksum":2917532993,"timestamp":"2026-08-02T05:43:45.388430Z"}]}
{"channel":"book","type":"update","data":[{"symbol":"BTC/USD","bids":[],"asks":[{"price":63355.6,"qty":0.23557490}],"checksum":3763554005,"timestamp":"2026-08-02T05:43:45.389665Z"}]}
{"channel":"book","type":"update","data":[{"symbol":"ETH/USD","bids":[],"asks":[{"price":1873.51,"qty":0.00000000},{"price":1873.64,"qty":6.13208319},{"price":1873.49,"qty":0.01266813}],"checksum":3014973118,"timestamp":"2026-08-02T05:43:45.390725Z"}]}
{"channel":"book","type":"update","data":[{"symbol":"ETH/USD","bids":[],"asks":[{"price":1873.50,"qty":0.00000000},{"price":1873.64,"qty":6.13208319},{"price":1873.54,"qty":1.60630847}],"checksum":3362432451,"timestamp":"2026-08-02T05:43:45.392107Z"}]}
{"channel":"book","type":"update","data":[{"symbol":"ETH/USD","bids":[],"asks":[{"price":1873.49,"qty":0.00000000},{"price":1873.64,"qty":6.13208319},{"price":1873.53,"qty":0.01266813}],"checksum":3968927576,"timestamp":"2026-08-02T05:43:45.394705Z"}]}
{"channel":"book","type":"update","data":[{"symbol":"ETH/USD","bids":[],"asks":[{"price":1873.38,"qty":0.00000000},{"price":1873.64,"qty":6.13208319}],"checksum":777012446,"timestamp":"2026-08-02T05:43:45.548121Z"}]}
{"channel":"book","type":"update","data":[{"symbol":"ETH/USD","bids":[],"asks":[{"price":1873.54,"qty":0.00000000},{"price":1873.71,"qty":25.63329697},{"price":1873.52,"qty":1.60630847}],"checksum":3178352181,"timestamp":"2026-08-02T05:43:45.549256Z"}]}
{"channel":"book","type":"update","data":[{"symbol":"ETH/USD","bids":[],"asks":[{"price":1873.53,"qty":0.00000000},{"price":1873.71,"qty":25.63329697},{"price":1873.51,"qty":0.01266813}],"checksum":592149878,"timestamp":"2026-08-02T05:43:45.550493Z"}]}
{"channel":"book","type":"update","data":[{"symbol":"ETH/USD","bids":[],"asks":[{"price":1873.40,"qty":0.00000000},{"price":1873.71,"qty":25.63329697},{"price":1873.44,"qty":0.80079672}],"checksum":2916276828,"timestamp":"2026-08-02T05:43:45.551272Z"}]}
{"channel":"book","type":"update","data":[{"symbol":"ETH/USD","bids":[],"asks":[{"price":1873.46,"qty":1.60159344}],"checksum":883980538,"timestamp":"2026-08-02T05:43:45.554642Z"}]}
{"channel":"book","type":"update","data":[{"symbol":"ETH/USD","bids":[],"asks":[{"price":1873.51,"qty":0.00000000},{"price":1873.64,"qty":6.13208319},{"price":1873.43,"qty":0.01266813}],"checksum":1641764029,"timestamp":"2026-08-02T05:43:45.555849Z"}]}
{"channel":"book","type":"update","data":[{"symbol":"ETH/USD","bids":[],"asks":[{"price":1873.52,"qty":0.00000000},{"price":1873.64,"qty":6.13208319},{"price":1873.54,"qty":1.60630847}],"checksum":3394411870,"timestamp":"2026-08-02T05:43:45.557140Z"}]}
{"channel":"book","type":"update","data":[{"symbol":"ETH/USD","bids":[{"price":1873.17,"qty":0.10677088}],"asks":[],"checksum":256786144,"timestamp":"2026-08-02T05:43:45.626801Z"}]}
{"channel":"book","type":"update","data":[{"symbol":"ETH/USD","bids":[{"price":1873.30,"qty":0.25000000}],"asks":[],"checksum":1868842325,"timestamp":"2026-08-02T05:43:45.696335Z"}]}
{"channel":"heartbeat"}
{"channel":"book","type":"update","data":[{"symbol":"ETH/USD","bids":[{"price":1873.08,"qty":0.10677601}],"asks":[],"checksum":1354317960,"timestamp":"2026-08-02T05:43:45.763499Z"}]}
{"channel":"book","type":"update","data":[{"symbol":"BTC/USD","bids":[{"price":63342.5,"qty":0.00000000},{"price":63342.1,"qty":0.06224631}],"asks":[],"checksum":2113412025,"timestamp":"2026-08-02T05:43:45.916626Z"}]}
{"channel":"book","type":"update","data":[{"symbol":"ETH/USD","bids":[{"price":1873.23,"qty":0.00000000},{"price":1873.07,"qty":0.01332630},{"price":1873.21,"qty":0.00320200}],"asks":[],"checksum":2625455056,"timestamp":"2026-08-02T05:43:45.916713Z"}]}
{"channel":"heartbeat"}
{"channel":"book","type":"update","data":[{"symbol":"ETH/USD","bids":[{"price":1873.08,"qty":0.12010231}],"asks":[],"checksum":3808987106,"timestamp":"2026-08-02T05:43:46.724701Z"}]}
{"channel":"book","type":"update","data":[{"symbol":"ETH/USD","bids":[{"price":1873.20,"qty":16.01343403}],"asks":[],"checksum":2181823816,"timestamp":"2026-08-02T05:43:47.068983Z"}]}
{"channel":"book","type":"update","data":[{"symbol":"ETH/USD","bids":[],"asks":[{"price":1873.55,"qty":0.00000000},{"price":1873.64,"qty":6.13208319}],"checksum":3877199774,"timestamp":"2026-08-02T05:43:47.262252Z"}]}
{"channel":"book","type":"update","data":[{"symbol":"ETH/USD","bids":[],"asks":[{"price":1873.54,"qty":0.00000000},{"price":1873.71,"qty":25.63329697},{"price":1873.58,"qty":1.60630847}],"checksum":2487823240,"timestamp":"2026-08-02T05:43:47.263555Z"}]}
{"channel":"book","type":"update","data":[{"symbol":"ETH/USD","bids":[{"price":1873.21,"qty":4.81508317}],"asks":[],"checksum":3130731772,"timestamp":"2026-08-02T05:43:47.263805Z"}]}
{"channel":"book","type":"update","data":[{"symbol":"ETH/USD","bids":[],"asks":[{"price":1873.43,"qty":0.00000000},{"price":1873.71,"qty":25.63329697},{"price":1873.57,"qty":0.01266813}],"checksum":483818842,"timestamp":"2026-08-02T05:43:47.264778Z"}]}
{"channel":"book","type":"update","data":[{"symbol":"ETH/USD","bids":[],"asks":[{"price":1873.57,"qty":1.35958993}],"checksum":2340358148,"timestamp":"2026-08-02T05:43:47.264926Z"}]}
{"channel":"book","type":"update","data":[{"symbol":"ETH/USD","bids":[],"asks":[{"price":1873.58,"qty":0.00000000},{"price":1873.71,"qty":25.63329697},{"price":1873.56,"qty":1.60630847}],"checksum":2849204418,"timestamp":"2026-08-02T05:43:47.265863Z"}]}
{"channel":"book","type":"update","data":[{"symbol":"ETH/USD","bids":[],"asks":[{"price":1873.57,"qty":1.34692180},{"price":1873.56,"qty":1.61897660}],"checksum":108637294,"timestamp":"2026-08-02T05:43:47.266179Z"}]}
{"channel":"book","type":"update","data":[{"symbol":"ETH/USD","bids":[],"asks":[{"price":1873.57,"qty":0.00000000},{"price":1873.71,"qty":25.63329697}],"checksum":3617580187,"timestamp":"2026-08-02T05:43:47.267058Z"}]}
{"channel":"book","type":"update","data":[{"symbol":"ETH/USD","bids":[],"asks":[{"price":1873.56,"qty":1.60630847},{"price":1873.55,"qty":0.01266813}],"checksum":3329608852,"timestamp":"2026-08-02T05:43:47.267301Z"}]}
{"channel":"book","type":"update","data":[{"symbol":"ETH/USD","bids":[],"asks":[{"price":1873.56,"qty":0.00000000},{"price":1873.71,"qty":25.63329697},{"price":1873.54,"qty":1.60630847}],"checksum":954745154,"timestamp":"2026-08-02T05:43:47.479728Z"}]}
{"channel":"book","type":"update","data":[{"symbol":"ETH/USD","bids":[],"asks":[{"price":1873.55,"qty":0.00000000},{"price":1873.71,"qty":25.63329697},{"price":1873.43,"qty":0.01266813}],"checksum":2181570123,"timestamp":"2026-08-02T05:43:47.480873Z"}]}
{"channel":"book","type":"update","data":[{"symbol":"ETH/USD","bids":[],"asks":[{"price":1873.53,"qty":1.35070324}],"checksum":3356102968,"timestamp":"2026-08-02T05:43:47.481035Z"}]}
{"channel":"book","type":"update","data":[{"symbol":"ETH/USD","bids":[],"asks":[{"price":1873.54,"qty":0.00000000},{"price":1873.64,"qty":6.13208319},{"price":1873.58,"qty":1.60630847}],"checksum":2311297696,"timestamp":"2026-08-02T05:43:47.481937Z"}]}
{"channel":"book","type":"update","data":[{"symbol":"ETH/USD","bids":[{"price":1873.08,"qty":0.10677601}],"asks":[],"checksum":4139146898,"timestamp":"2026-08-02T05:43:47.591039Z"}]}
{"channel":"book","type":"update","data":[{"symbol":"ETH/USD","bids":[],"asks":[{"price":1873.62,"qty":0.00000000},{"price":1873.64,"qty":6.13208319},{"price":1873.60,"qty":2.86605339}],"checksum":3247402551,"timestamp":"2026-08-02T05:43:47.613425Z"}]}
{"channel":"book","type":"update","data":[{"symbol":"ETH/USD","bids":[],"asks":[{"price":1873.58,"qty":0.00000000},{"price":1873.71,"qty":25.63329697},{"price":1873.52,"qty":1.60630847}],"checksum":4015760180,"timestamp":"2026-08-02T05:43:47.702477Z"}]}
{"channel":"book","type":"update","data":[{"symbol":"ETH/USD","bids":[],"asks":[{"price":1873.53,"qty":0.00000000},{"price":1873.71,"qty":25.63329697}],"checksum":1091650700,"timestamp":"2026-08-02T05:43:47.703888Z"}]}
{"channel":"book","type":"update","data":[{"symbol":"ETH/USD","bids":[],"asks":[{"price":1873.52,"qty":0.00000000},{"price":1873.73,"qty":17.61507310},{"price":1873.58,"qty":1.60630847}],"checksum":4272386395,"timestamp":"2026-08-02T05:43:47.704880Z"}]}
{"channel":"book","type":"update","data":[{"symbol":"ETH/USD","bids":[],"asks":[{"price":1873.59,"qty":0.89545593}],"checksum":1183601826,"timestamp":"2026-08-02T05:43:47.705218Z"}]}
{"channel":"book","type":"update","data":[{"symbol":"ETH/USD","bids":[],"asks":[{"price":1873.43,"qty":0.00000000},{"price":1873.73,"qty":17.61507310},{"price":1873.57,"qty":0.01266813}],"checksum":1246057391,"timestamp":"2026-08-02T05:43:47.705978Z"}]}
{"channel":"book","type":"update","data":[{"symbol":"ETH/USD","bids":[],"asks":[{"price":1873.59,"qty":0.03993899}],"checksum":2176533648,"timestamp":"2026-08-02T05:43:47.706140Z"}]}
{"channel":"heartbeat"}
{"channel":"book","type":"update","data":[{"symbol":"ETH/USD","bids":[],"asks":[{"price":1873.57,"qty":1.35958993}],"checksum":3925710845,"timestamp":"2026-08-02T05:43:47.707264Z"}]}
{"channel":"book","type":"update","data":[{"symbol":"ETH/USD","bids":[],"asks":[{"price":1873.57,"qty":1.34692180},{"price":1873.56,"qty":0.01266813}],"checksum":313071488,"timestamp":"2026-08-02T05:43:47.708472Z"}]}
{"channel":"book","type":"update","data":[{"symbol":"ETH/USD","bids":[{"price":1873.30,"qty":0.50000000}],"asks":[],"checksum":647438312,"timestamp":"2026-08-02T05:43:47.828102Z"}]}
{"channel":"book","type":"update","data":[{"symbol":"ETH/USD","bids":[],"asks":[{"price":1873.58,"qty":0.00000000},{"price":1873.71,"qty":25.63329697},{"price":1873.55,"qty":1.60630847}],"checksum":3174569820,"timestamp":"2026-08-02T05:43:47.870023Z"}]}
{"channel":"book","type":"update","data":[{"symbol":"ETH/USD","bids":[],"asks":[{"price":1873.57,"qty":0.00000000},{"price":1873.71,"qty":25.63329697}],"checksum":2764570754,"timestamp":"2026-08-02T05:43:47.871153Z"}]}
{"channel":"book","type":"update","data":[{"symbol":"ETH/USD","bids":[],"asks":[{"price":1873.56,"qty":0.00000000},{"price":1873.73,"qty":17.61507310},{"price":1873.54,"qty":0.01266813}],"checksum":282401669,"timestamp":"2026-08-02T05:43:47.871200Z"}]}
{"channel":"book","type":"update","data":[{"symbol":"ETH/USD","bids":[],"asks":[{"price":1873.54,"qty":1.36337137}],"checksum":549084221,"timestamp":"2026-08-02T05:43:47.872430Z"}]}
{"channel":"book","type":"update","data":[{"symbol":"ETH/USD","bids":[],"asks":[{"price":1873.54,"qty":1.35070324},{"price":1873.43,"qty":0.01266813}],"checksum":1984474278,"timestamp":"2026-08-02T05:43:47.873669Z"}]}
{"channel":"book","type":"update","data":[{"symbol":"ETH/USD","bids":[],"asks":[{"price":1873.55,"qty":0.00000000},{"price":1873.71,"qty":25.63329697},{"price":1873.53,"qty":1.60630847}],"checksum":977233479,"timestamp":"2026-08-02T05:43:48.231700Z"}]}
{"channel":"book","type":"update","data":[{"symbol":"ETH/USD","bids":[],"asks":[{"price":1873.54,"qty":0.00000000},{"price":1873.71,"qty":25.63329697}],"checksum":2343515993,"timestamp":"2026-08-02T05:43:48.233036Z"}]}
{"channel":"book","type":"update","data":[{"symbol":"ETH/USD","bids":[],"asks":[{"price":1873.59,"qty":0.89545593}],"checksum":3751076546,"timestamp":"2026-08-02T05:43:48.234305Z"}]}
{"channel":"book","type":"update","data":[{"symbol":"ETH/USD","bids":[],"asks":[{"price":1873.53,"qty":0.00000000},{"price":1873.72,"qty":2.66849990},{"price":1873.58,"qty":1.60630847}],"checksum":1924291786,"timestamp":"2026-08-02T05:43:48.234339Z"}]}
{"channel":"book","type":"update","data":[{"symbol":"ETH/USD","bids":[],"asks":[{"price":1873.59,"qty":0.03993899}],"checksum":3399055667,"timestamp":"2026-08-02T05:43:48.235518Z"}]}
{"channel":"book","type":"update","data":[{"symbol":"ETH/USD","bids":[],"asks":[{"price":1873.43,"qty":0.00000000},{"price":1873.72,"qty":2.66849990},{"price":1873.57,"qty":0.01266813}],"checksum":3045412088,"timestamp":"2026-08-02T05:43:48.235843Z"}]}
{"channel":"book","type":"update","data":[{"symbol":"ETH/USD","bids":[],"asks":[{"price":1873.57,"qty":1.35958993}],"checksum":3720585109,"timestamp":"2026-08-02T05:43:48.236783Z"}]}
{"channel":"book","type":"update","data":[{"symbol":"ETH/USD","bids":[],"asks":[{"price":1873.57,"qty":1.34692180},{"price":1873.56,"qty":0.01266813}],"checksum":647438312,"timestamp":"2026-08-02T05:43:48.237982Z"}]}
{"channel":"book","type":"update","data":[{"symbol":"ETH/USD","bids":[],"asks":[{"price":1873.58,"qty":0.00000000},{"price":1873.71,"qty":25.63329697},{"price":1873.55,"qty":1.60630847}],"checksum":3174569820,"timestamp":"2026-08-02T05:43:48.537902Z"}]}
{"channel":"book","type":"update","data":[{"symbol":"ETH/USD","bids":[],"asks":[{"price":1873.56,"qty":0.00000000},{"price":1873.71,"qty":25.63329697},{"price":1873.54,"qty":0.01266813}],"checksum":2879203232,"timestamp":"2026-08-02T05:43:48.539480Z"}]}
{"channel":"book","type":"update","data":[{"symbol":"ETH/USD","bids":[],"asks":[{"price":1873.57,"qty":0.00000000},{"price":1873.71,"qty":25.63329697}],"checksum":282401669,"timestamp":"2026-08-02T05:43:48.539520Z"}]}
{"channel":"book","type":"update","data":[{"symbol":"ETH/USD","bids":[{"price":1873.11,"qty":1.65969562}],"asks":[],"checksum":722324131,"timestamp":"2026-08-02T05:43:48.540688Z"}]}
{"channel":"book","type":"update","data":[{"symbol":"ETH/USD","bids":[],"asks":[{"price":1873.54,"qty":1.35958993}],"checksum":1832829344,"timestamp":"2026-08-02T05:43:48.540932Z"}]}
{"channel":"book","type":"update","data":[{"symbol":"ETH/USD","bids":[{"price":1873.11,"qty":0.05338715},{"price":1873.12,"qty":1.60630847}],"asks":[],"checksum":1787446428,"timestamp":"2026-08-02T05:43:48.541801Z"}]}
{"channel":"book","type":"update","data":[{"symbol":"ETH/USD","bids":[],"asks":[{"price":1873.54,"qty":1.34692180},{"price":1873.43,"qty":0.01266813}],"checksum":1055703305,"timestamp":"2026-08-02T05:43:48.542202Z"}]}
{"channel":"heartbeat"}
{"channel":"book","type":"update","data":[{"symbol":"ETH/USD","bids":[],"asks":[{"price":1873.55,"qty":0.00000000},{"price":1873.71,"qty":25.63329697},{"price":1873.53,"qty":1.60630847}],"checksum":927134840,"timestamp":"2026-08-02T05:43:48.804515Z"}]}
{"channel":"book","type":"update","data":[{"symbol":"ETH/USD","bids":[],"asks":[{"price":1873.54,"qty":0.00000000},{"price":1873.71,"qty":25.63329697}],"checksum":785470195,"timestamp":"2026-08-02T05:43:48.806224Z"}]}
{"channel":"book","type":"update","data":[{"symbol":"ETH/USD","bids":[],"asks":[{"price":1873.53,"qty":0.00000000},{"price":1873.73,"qty":14.94658584},{"price":1873.58,"qty":1.60630847}],"checksum":484792408,"timestamp":"2026-08-02T05:43:48.807891Z"}]}
{"channel":"book","type":"update","data":[{"symbol":"ETH/USD","bids":[],"asks":[{"price":1873.59,"qty":0.89545593}],"checksum":2321919599,"timestamp":"2026-08-02T05:43:48.807996Z"}]}
{"channel":"book","type":"update","data":[{"symbol":"ETH/USD","bids":[],"asks":[{"price":1873.59,"qty":0.03993899}],"checksum":484792408,"timestamp":"2026-08-02T05:43:48.809068Z"}]}
{"channel":"book","type":"update","data":[{"symbol":"ETH/USD","bids":[],"asks":[{"price":1873.43,"qty":0.00000000},{"price":1873.73,"qty":14.94658584},{"price":1873.57,"qty":0.01266813}],"checksum":1792878612,"timestamp":"2026-08-02T05:43:48.809107Z"}]}
{"channel":"book","type":"update","data":[{"symbol":"ETH/USD","bids":[],"asks":[{"price":1873.57,"qty":1.35958993}],"checksum":4055743942,"timestamp":"2026-08-02T05:43:48.810667Z"}]}
{"channel":"book","type":"update","data":[{"symbol":"ETH/USD","bids":[],"asks":[{"price":1873.57,"qty":1.34692180},{"price":1873.56,"qty":0.01266813}],"checksum":1903273369,"timestamp":"2026-08-02T05:43:48.811798Z"}]}
{"channel":"book","type":"update","data":[{"symbol":"ETH/USD","bids":[],"asks":[{"price":1873.58,"qty":0.00000000},{"price":1873.71,"qty":25.63329697},{"price":1873.55,"qty":1.60630847}],"checksum":3132858713,"timestamp":"2026-08-02T05:43:49.131574Z"}]}
{"channel":"book","type":"update","data":[{"symbol":"ETH/USD","bids":[],"asks":[{"price":1873.56,"qty":0.00000000},{"price":1873.71,"qty":25.63329697},{"price":1873.54,"qty":0.01266813}],"checksum":1933842566,"timestamp":"2026-08-02T05:43:49.132738Z"}]}
{"channel":"book","type":"update","data":[{"symbol":"ETH/USD","bids":[],"asks":[{"price":1873.57,"qty":0.00000000},{"price":1873.71,"qty":25.63329697}],"checksum":809451059,"timestamp":"2026-08-02T05:43:49.132756Z"}]}
{"channel":"book","type":"update","data":[{"symbol":"ETH/USD","bids":[],"asks":[{"price":1873.54,"qty":1.35958993}],"checksum":1787446428,"timestamp":"2026-08-02T05:43:49.134293Z"}]}
{"channel":"book","type":"update","data":[{"symbol":"ETH/USD","bids":[],"asks":[{"price":1873.54,"qty":1.34692180},{"price":1873.43,"qty":0.01266813}],"checksum":1055703305,"timestamp":"2026-08-02T05:43:49.135617Z"}]}
{"channel":"book","type":"update","data":[{"symbol":"ETH/USD","bids":[],"asks":[{"price":1873.55,"qty":0.00000000},{"price":1873.65,"qty":2.66859455},{"price":1873.53,"qty":1.60630847}],"checksum":927134840,"timestamp":"2026-08-02T05:43:49.309548Z"}]}
{"channel":"book","type":"update","data":[{"symbol":"ETH/USD","bids":[],"asks":[{"price":1873.54,"qty":0.00000000},{"price":1873.65,"qty":2.66859455}],"checksum":580488909,"timestamp":"2026-08-02T05:43:49.310827Z"}]}
{"channel":"book","type":"update","data":[{"symbol":"ETH/USD","bids":[],"asks":[{"price":1873.53,"qty":0.00000000},{"price":1873.71,"qty":25.63329697},{"price":1873.58,"qty":1.60630847}],"checksum":3472869089,"timestamp":"2026-08-02T05:43:49.311869Z"}]}
{"channel":"book","type":"update","data":[{"symbol":"ETH/USD","bids":[],"asks":[{"price":1873.59,"qty":0.89545593}],"checksum":1201766315,"timestamp":"2026-08-02T05:43:49.312282Z"}]}
{"channel":"book","type":"update","data":[{"symbol":"ETH/USD","bids":[],"asks":[{"price":1873.59,"qty":0.03993899}],"checksum":3472869089,"timestamp":"2026-08-02T05:43:49.313009Z"}]}
{"channel":"book","type":"update","data":[{"symbol":"ETH/USD","bids":[],"asks":[{"price":1873.43,"qty":0.00000000},{"price":1873.71,"qty":25.63329697},{"price":1873.57,"qty":0.01266813}],"checksum":718150305,"timestamp":"2026-08-02T05:43:49.313143Z"}]}
{"channel":"book","type":"update","data":[{"symbol":"ETH/USD","bids":[],"asks":[{"price":1873.57,"qty":1.35958993}],"checksum":781809761,"timestamp":"2026-08-02T05:43:49.314145Z"}]}
{"channel":"book","type":"update","data":[{"symbol":"ETH/USD","bids":[],"asks":[{"price":1873.57,"qty":1.34692180},{"price":1873.56,"qty":0.01266813}],"checksum":1903273369,"timestamp":"2026-08-02T05:43:49.315303Z"}]}
{"channel":"book","type":"update","data":[{"symbol":"ETH/USD","bids":[],"asks":[{"price":1873.59,"qty":0.00000000},{"price":1873.65,"qty":2.66859455},{"price":1873.56,"qty":0.05260712}],"checksum":1763081421,"timestamp":"2026-08-02T05:43:49.399412Z"}]}
{"channel":"book","type":"update","data":[{"symbol":"BTC/USD","bids":[],"asks":[{"price":63350.9,"qty":0.74258967},{"price":63352.6,"qty":0.05019216}],"checksum":3079499756,"timestamp":"2026-08-02T05:43:49.409932Z"}]}
{"channel":"heartbeat"}
{"channel":"book","type":"update","data":[{"symbol":"ETH/USD","bids":[{"price":1873.33,"qty":0.02372454}],"asks":[],"checksum":1218090804,"timestamp":"2026-08-02T05:43:49.818374Z"}]}
{"channel":"book","type":"update","data":[{"symbol":"ETH/USD","bids":[],"asks":[{"price":1873.58,"qty":0.00000000},{"price":1873.71,"qty":25.63329697},{"price":1873.55,"qty":1.60630847}],"checksum":1672193422,"timestamp":"2026-08-02T05:43:49.819641Z"}]}
{"channel":"book","type":"update","data":[{"symbol":"ETH/USD","bids":[],"asks":[{"price":1873.56,"qty":0.03993899},{"price":1873.54,"qty":0.01266813}],"checksum":2241141970,"timestamp":"2026-08-02T05:43:49.821065Z"}]}
{"channel":"book","type":"update","data":[{"symbol":"ETH/USD","bids":[],"asks":[{"price":1873.57,"qty":0.00000000},{"price":1873.65,"qty":2.66859455}],"checksum":1072205696,"timestamp":"2026-08-02T05:43:49.821078Z"}]}
{"channel":"book","type":"update","data":[{"symbol":"ETH/USD","bids":[],"asks":[{"price":1873.54,"qty":1.35958993}],"checksum":1254380538,"timestamp":"2026-08-02T05:43:49.824411Z"}]}
{"channel":"book","type":"update","data":[{"symbol":"ETH/USD","bids":[],"asks":[{"price":1873.54,"qty":1.34692180},{"price":1873.43,"qty":0.01266813}],"checksum":276416666,"timestamp":"2026-08-02T05:43:49.825887Z"}]}
{"channel":"book","type":"update","data":[{"symbol":"ETH/USD","bids":[],"asks":[{"price":1873.55,"qty":0.00000000},{"price":1873.65,"qty":2.66859455},{"price":1873.53,"qty":1.60630847}],"checksum":134255254,"timestamp":"2026-08-02T05:43:49.993382Z"}]}
{"channel":"book","type":"update","data":[{"symbol":"ETH/USD","bids":[],"asks":[{"price":1873.54,"qty":0.00000000},{"price":1873.65,"qty":2.66859455}],"checksum":1951414211,"timestamp":"2026-08-02T05:43:49.994649Z"}]}
{"channel":"book","type":"update","data":[{"symbol":"ETH/USD","bids":[],"asks":[{"price":1873.53,"qty":0.00000000},{"price":1873.71,"qty":25.63329697},{"price":1873.55,"qty":1.60630847}],"checksum":3010883181,"timestamp":"2026-08-02T05:43:49.995744Z"}]}
{"channel":"book","type":"update","data":[{"symbol":"ETH/USD","bids":[],"asks":[{"price":1873.59,"qty":0.85551694}],"checksum":1111609833,"timestamp":"2026-08-02T05:43:49.996166Z"}]}
{"channel":"book","type":"update","data":[{"symbol":"ETH/USD","bids":[],"asks":[{"price":1873.43,"qty":0.00000000},{"price":1873.65,"qty":2.66859455},{"price":1873.54,"qty":0.01266813}],"checksum":266129335,"timestamp":"2026-08-02T05:43:49.996825Z"}]}
{"channel":"book","type":"update","data":[{"symbol":"ETH/USD","bids":[],"asks":[{"price":1873.59,"qty":0.00000000},{"price":1873.65,"qty":2.66859455}],"checksum":1072205696,"timestamp":"2026-08-02T05:43:49.996947Z"}]}
{"channel":"book","type":"update","data":[{"symbol":"BTC/USD","bids":[{"price":63345.7,"qty":0.00000000},{"price":63342.0,"qty":0.83830565}],"asks":[],"checksum":1672288388,"timestamp":"2026-08-02T05:43:50.032929Z"}]}
{"channel":"book","type":"update","data":[{"symbol":"BTC/USD","bids":[{"price":63346.6,"qty":0.01523524}],"asks":[],"checksum":2245076990,"timestamp":"2026-08-02T05:43:50.033789Z"}]}
{"channel":"book","type":"update","data":[{"symbol":"BTC/USD","bids":[],"asks":[{"price":63348.5,"qty":0.14310673}],"checksum":4115687806,"timestamp":"2026-08-02T05:43:50.034871Z"}]}
{"channel":"book","type":"update","data":[{"symbol":"BTC/USD","bids":[],"asks":[{"price":63348.5,"qty":0.27420075}],"checksum":520862881,"timestamp":"2026-08-02T05:43:50.035247Z"}]}
{"channel":"book","type":"update","data":[{"symbol":"BTC/USD","bids":[],"asks":[{"price":63348.5,"qty":0.30520075}],"checksum":4015627438,"timestamp":"2026-08-02T05:43:50.037284Z"}]}
{"channel":"book","type":"update","data":[{"symbol":"BTC/USD","bids":[],"asks":[{"price":63348.5,"qty":0.33680075}],"checksum":6261629,"timestamp":"2026-08-02T05:43:50.037441Z"}]}
{"channel":"book","type":"update","data":[{"symbol":"BTC/USD","bids":[{"price":63348.4,"qty":0.09048930}],"asks":[],"checksum":1139086763,"timestamp":"2026-08-02T05:43:50.037855Z"}]}
{"channel":"book","type":"update","data":[{"symbol":"BTC/USD","bids":[{"price":63342.5,"qty":0.00009400}],"asks":[],"checksum":897755890,"timestamp":"2026-08-02T05:43:50.039726Z"}]}
{"channel":"book","type":"update","data":[{"symbol":"ETH/USD","bids":[{"price":1873.21,"qty":4.81188117},{"price":1873.23,"qty":0.00320200}],"asks":[],"checksum":1711266650,"timestamp":"2026-08-02T05:43:50.039904Z"}]}
{"channel":"book","type":"update","data":[{"symbol":"BTC/USD","bids":[{"price":63348.4,"qty":0.05888930}],"asks":[],"checksum":994253544,"timestamp":"2026-08-02T05:43:50.044301Z"}]}
{"channel":"book","type":"update","data":[{"symbol":"BTC/USD","bids":[],"asks":[{"price":63350.4,"qty":0.00000000},{"price":63355.6,"qty":0.23557490}],"checksum":3428475585,"timestamp":"2026-08-02T05:43:50.135865Z"}]}
{"channel":"book","type":"update","data":[{"symbol":"BTC/USD","bids":[],"asks":[{"price":63350.3,"qty":0.00000000},{"price":63355.7,"qty":0.78919566}],"checksum":3535569482,"timestamp":"2026-08-02T05:43:50.137065Z"}]}
{"channel":"book","type":"update","data":[{"symbol":"BTC/USD","bids":[],"asks":[{"price":63350.2,"qty":0.00000000},{"price":63357.0,"qty":0.00157836},{"price":63350.7,"qty":0.00126056}],"checksum":1327924540,"timestamp":"2026-08-02T05:43:50.208222Z"}]}
{"channel":"book","type":"update","data":[{"symbol":"ETH/USD","bids":[],"asks":[{"price":1873.55,"qty":0.00000000},{"price":1873.71,"qty":25.63329697},{"price":1873.53,"qty":1.60630847}],"checksum":3859115185,"timestamp":"2026-08-02T05:43:50.288229Z"}]}
{"channel":"book","type":"update","data":[{"symbol":"ETH/USD","bids":[],"asks":[{"price":1873.54,"qty":0.00000000},{"price":1873.71,"qty":25.63329697},{"price":1873.43,"qty":0.01266813}],"checksum":3798879700,"timestamp":"2026-08-02T05:43:50.289484Z"}]}
{"channel":"book","type":"update","data":[{"symbol":"ETH/USD","bids":[],"asks":[{"price":1873.53,"qty":0.00000000},{"price":1873.71,"qty":25.63329697},{"price":1873.55,"qty":1.60630847}],"checksum":1971666022,"timestamp":"2026-08-02T05:43:50.290874Z"}]}
{"channel":"book","type":"update","data":[{"symbol":"ETH/USD","bids":[],"asks":[{"price":1873.43,"qty":0.00000000},{"price":1873.71,"qty":25.63329697},{"price":1873.54,"qty":0.01266813}],"checksum":1711266650,"timestamp":"2026-08-02T05:43:50.292085Z"}]}
{"channel":"book","type":"update","data":[{"symbol":"ETH/USD","bids":[],"asks":[{"price":1873.55,"qty":0.00000000},{"price":1873.71,"qty":25.63329697},{"price":1873.53,"qty":1.60630847}],"checksum":3859115185,"timestamp":"2026-08-02T05:43:50.617571Z"}]}
{"channel":"book","type":"update","data":[{"symbol":"ETH/USD","bids":[],"asks":[{"price":1873.54,"qty":0.00000000},{"price":1873.71,"qty":25.63329697},{"price":1873.43,"qty":0.01266813}],"checksum":3798879700,"timestamp":"2026-08-02T05:43:50.618912Z"}]}
{"channel":"book","type":"update","data":[{"symbol":"ETH/USD","bids":[],"asks":[{"price":1873.53,"qty":0.00000000},{"price":1873.71,"qty":25.63329697},{"price":1873.55,"qty":1.60630847}],"checksum":1971666022,"timestamp":"2026-08-02T05:43:50.620156Z"}]}
{"channel":"book","type":"update","data":[{"symbol":"ETH/USD","bids":[],"asks":[{"price":1873.43,"qty":0.00000000},{"price":1873.71,"qty":25.63329697},{"price":1873.54,"qty":0.01266813}],"checksum":1711266650,"timestamp":"2026-08-02T05:43:50.621409Z"}]}
{"channel":"heartbeat"}
{"channel":"book","type":"update","data":[{"symbol":"ETH/USD","bids":[],"asks":[{"price":1873.55,"qty":0.00000000},{"price":1873.71,"qty":25.63329697},{"price":1873.53,"qty":1.60630847}],"checksum":3859115185,"timestamp":"2026-08-02T05:43:51.019311Z"}]}
{"channel":"book","type":"update","data":[{"symbol":"ETH/USD","bids":[],"asks":[{"price":1873.54,"qty":1.35958993}],"checksum":3399392424,"timestamp":"2026-08-02T05:43:51.019465Z"}]}
{"channel":"book","type":"update","data":[{"symbol":"ETH/USD","bids":[],"asks":[{"price":1873.54,"qty":0.01266813}],"checksum":3859115185,"timestamp":"2026-08-02T05:43:51.020641Z"}]}
{"channel":"book","type":"update","data":[{"symbol":"ETH/USD","bids":[],"asks":[{"price":1873.54,"qty":0.00000000},{"price":1873.71,"qty":25.63329697},{"price":1873.43,"qty":0.01266813}],"checksum":3798879700,"timestamp":"2026-08-02T05:43:51.021217Z"}]}
{"channel":"book","type":"update","data":[{"symbol":"ETH/USD","bids":[],"asks":[{"price":1873.59,"qty":0.85551694}],"checksum":4019803530,"timestamp":"2026-08-02T05:43:51.022001Z"}]}
{"channel":"book","type":"update","data":[{"symbol":"ETH/USD","bids":[],"asks":[{"price":1873.53,"qty":0.00000000},{"price":1873.65,"qty":2.66859455},{"price":1873.55,"qty":1.60630847}],"checksum":3593564033,"timestamp":"2026-08-02T05:43:51.022541Z"}]}
{"channel":"book","type":"update","data":[{"symbol":"ETH/USD","bids":[],"asks":[{"price":1873.59,"qty":0.00000000},{"price":1873.65,"qty":2.66859455}],"checksum":1971666022,"timestamp":"2026-08-02T05:43:51.023991Z"}]}
{"channel":"book","type":"update","data":[{"symbol":"ETH/USD","bids":[],"asks":[{"price":1873.43,"qty":0.00000000},{"price":1873.71,"qty":25.63329697},{"price":1873.54,"qty":0.01266813}],"checksum":1711266650,"timestamp":"2026-08-02T05:43:51.024247Z"}]}
{"channel":"book","type":"update","data":[{"symbol":"ETH/USD","bids":[],"asks":[{"price":1873.54,"qty":1.35958993}],"checksum":1368076677,"timestamp":"2026-08-02T05:43:51.025546Z"}]}
{"channel":"book","type":"update","data":[{"symbol":"ETH/USD","bids":[],"asks":[{"price":1873.54,"qty":1.34692180},{"price":1873.43,"qty":0.01266813}],"checksum":916810009,"timestamp":"2026-08-02T05:43:51.026849Z"}]}
{"channel":"book","type":"update","data":[{"symbol":"ETH/USD","bids":[],"asks":[{"price":1873.55,"qty":0.00000000},{"price":1873.65,"qty":2.66859455},{"price":1873.53,"qty":1.60630847}],"checksum":1963108823,"timestamp":"2026-08-02T05:43:51.276239Z"}]}
{"channel":"book","type":"update","data":[{"symbol":"ETH/USD","bids":[],"asks":[{"price":1873.54,"qty":0.00000000},{"price":1873.65,"qty":2.66859455}],"checksum":3798879700,"timestamp":"2026-08-02T05:43:51.277809Z"}]}
{"channel":"book","type":"update","data":[{"symbol":"ETH/USD","bids":[],"asks":[{"price":1873.53,"qty":0.00000000},{"price":1873.71,"qty":25.63329697},{"price":1873.55,"qty":1.60630847}],"checksum":1971666022,"timestamp":"2026-08-02T05:43:51.278983Z"}]}
{"channel":"book","type":"update","data":[{"symbol":"ETH/USD","bids":[],"asks":[{"price":1873.59,"qty":0.85551694}],"checksum":3593564033,"timestamp":"2026-08-02T05:43:51.279585Z"}]}
{"channel":"book","type":"update","data":[{"symbol":"ETH/USD","bids":[],"asks":[{"price":1873.43,"qty":0.00000000},{"price":1873.65,"qty":2.66859455},{"price":1873.54,"qty":0.01266813}],"checksum":1990986011,"timestamp":"2026-08-02T05:43:51.280053Z"}]}
{"channel":"book","type":"update","data":[{"symbol":"ETH/USD","bids":[],"asks":[{"price":1873.59,"qty":0.00000000},{"price":1873.65,"qty":2.66859455}],"checksum":1711266650,"timestamp":"2026-08-02T05:43:51.280274Z"}]}
{"channel":"book","type":"update","data":[{"symbol":"ETH/USD","bids":[],"asks":[{"price":1873.54,"qty":1.35958993}],"checksum":1368076677,"timestamp":"2026-08-02T05:43:51.281638Z"}]}
{"channel":"book","type":"update","data":[{"symbol":"ETH/USD","bids":[],"asks":[{"price":1873.54,"qty":1.34692180},{"price":1873.43,"qty":0.01266813}],"checksum":916810009,"timestamp":"2026-08-02T05:43:51.282998Z"}]}
{"channel":"book","type":"update","data":[{"symbol":"ETH/USD","bids":[],"asks":[{"price":1873.56,"qty":0.00000000},{"price":1873.65,"qty":2.66859455},{"price":1873.59,"qty":0.03993899}],"checksum":18819642,"timestamp":"2026-08-02T05:43:51.382153Z"}]}
{"channel":"book","type":"update","data":[{"symbol":"ETH/USD","bids":[],"asks":[{"price":1873.55,"qty":0.00000000},{"price":1873.65,"qty":2.66859455},{"price":1873.53,"qty":1.60630847}],"checksum":1119415028,"timestamp":"2026-08-02T05:43:51.598993Z"}]}
{"channel":"book","type":"update","data":[{"symbol":"ETH/USD","bids":[],"asks":[{"price":1873.54,"qty":0.00000000},{"price":1873.65,"qty":2.66859455}],"checksum":3153312396,"timestamp":"2026-08-02T05:43:51.600201Z"}]}
{"channel":"book","type":"update","data":[{"symbol":"ETH/USD","bids":[],"asks":[{"price":1873.53,"qty":0.00000000},{"price":1873.71,"qty":25.63329697},{"price":1873.58,"qty":1.60630847}],"checksum":1463597971,"timestamp":"2026-08-02T05:43:51.601423Z"}]}
{"channel":"book","type":"update","data":[{"symbol":"ETH/USD","bids":[],"asks":[{"price":1873.59,"qty":0.89545593}],"checksum":1070746948,"timestamp":"2026-08-02T05:43:51.601489Z"}]}
{"channel":"book","type":"update","data":[{"symbol":"ETH/USD","bids":[],"asks":[{"price":1873.43,"qty":0.00000000},{"price":1873.71,"qty":25.63329697},{"price":1873.57,"qty":0.01266813}],"checksum":3470036193,"timestamp":"2026-08-02T05:43:51.603778Z"}]}
{"channel":"book","type":"update","data":[{"symbol":"ETH/USD","bids":[],"asks":[{"price":1873.59,"qty":0.03993899}],"checksum":2233424962,"timestamp":"2026-08-02T05:43:51.603792Z"}]}
{"channel":"book","type":"update","data":[{"symbol":"ETH/USD","bids":[],"asks":[{"price":1873.57,"qty":1.35958993}],"checksum":2565011848,"timestamp":"2026-08-02T05:43:51.605537Z"}]}
